Workbook

Sheet stata
A1: label | B1: idstudy | C1: pubyear | D1: reviewed | E1: dollaryear | F1: emissionyear | G1: tolweight | H1: scc | I1: sccmean | J1: sccbg | K1: sccmed | L1: stdev | M1: stdlow | N1: stdup | O1: iie | P1: mmi | Q1: dim | R1: sce | S1: fund | T1: dicerice | U1: page | V1: cdr | W1: prtp | X1: rra | Y1: growth | Z1: ies | AA1: eweight | AB1: climatesens | AC1: hope | AD1: nordhaus | AE1: tol | AF1: pigou | AG1: dataset | AH1: citations | AI1: sjr | AJ1: perstudy
A2: =+VLOOKUP(B2,studies!$A$2:$C$102,3) -> Nordhaus (1982) | B2: 1 | C2: 1982 | D2: 1 | E2: 1980 | F2: 1980 | G2: 0.5 | H2: 1984.9987 | I2: 0 | J2: 1 | K2: 0 | O2: 1 | P2: 0 | Q2: 0 | R2: 0 | S2: 0 | T2: 0 | U2: 0 | W2: 1 | Y2: 4 | AA2: 0 | AC2: 0 | AD2: 1 | AE2: 0 | AF2: 0 | AG2: 0 | AH2: 132 | AI2: 6.46 | AJ2: 2
A3: =+VLOOKUP(B3,studies!$A$2:$C$102,3) -> Nordhaus (1982) | B3: 1 | C3: 1982 | D3: 1 | E3: 1980 | F3: 1980 | G3: 0.5 | H3: 283.57124 | I3: 0 | J3: 1 | K3: 0 | O3: 1 | P3: 0 | Q3: 0 | R3: 0 | S3: 0 | T3: 0 | U3: 0 | W3: 1 | Y3: 1 | AA3: 0 | AC3: 0 | AD3: 1 | AE3: 0 | AF3: 0 | AG3: 0 | AH3: 132 | AI3: 6.46 | AJ3: 2
A4: =+VLOOKUP(B4,studies!$A$2:$C$102,3) -> Ayres & Walter (1991) | B4: 2 | C4: 1991 | D4: 1 | E4: 1989 | F4: 1990 | G4: 1 | H4: 450.7956 | I4: 0 | J4: 1 | K4: 0 | O4: 1 | P4: 0 | Q4: 0 | R4: 0 | S4: 0 | T4: 0 | U4: 0 | V4: 3 | W4: 1 | Y4: 0 | AA4: 0 | AC4: 0 | AD4: 0 | AE4: 0 | AF4: 0 | AG4: 0 | AH4: 220 | AI4: 1.65 | AJ4: 1
A5: =+VLOOKUP(B5,studies!$A$2:$C$102,3) -> Nordhaus (1991) | B5: 3 | C5: 1991 | D5: 1 | E5: 1989 | F5: 1990 | G5: 0.0625 | H5: 914.62959 | I5: 0 | J5: 1 | K5: 0 | O5: 1 | P5: 0 | Q5: 0 | R5: 0 | S5: 0 | T5: 1 | U5: 0 | V5: 1 | W5: 0 | X5: 1 | Y5: 1 | AA5: 0 | AC5: 0 | AD5: 1 | AE5: 0 | AF5: 0 | AG5: 0 | AH5: 1166 | AI5: 3.46 | AJ5: 9
A6: =+VLOOKUP(B6,studies!$A$2:$C$102,3) -> Nordhaus (1991) | B6: 3 | C6: 1991 | D6: 1 | E6: 1989 | F6: 1990 | G6: 0.125 | H6: 457.31479 | I6: 0 | J6: 1 | K6: 0 | O6: 1 | P6: 0 | Q6: 0 | R6: 0 | S6: 0 | T6: 1 | U6: 0 | V6: 1 | W6: 0 | X6: 1 | Y6: 1 | AA6: 0 | AC6: 0 | AD6: 1 | AE6: 0 | AF6: 0 | AG6: 0 | AH6: 1166 | AI6: 3.46 | AJ6: 9
A7: =+VLOOKUP(B7,studies!$A$2:$C$102,3) -> Nordhaus (1991) | B7: 3 | C7: 1991 | D7: 1 | E7: 1989 | F7: 1990 | G7: 0.0625 | H7: 114.29402 | I7: 0 | J7: 1 | K7: 0 | O7: 1 | P7: 0 | Q7: 0 | R7: 0 | S7: 0 | T7: 1 | U7: 0 | V7: 1 | W7: 0 | X7: 1 | Y7: 1 | AA7: 0 | AC7: 0 | AD7: 1 | AE7: 0 | AF7: 0 | AG7: 0 | AH7: 1166 | AI7: 3.46 | AJ7: 9
A8: =+VLOOKUP(B8,studies!$A$2:$C$102,3) -> Nordhaus (1991) | B8: 3 | C8: 1991 | D8: 1 | E8: 1989 | F8: 1990 | G8: 0.125 | H8: 203.20478 | I8: 0 | J8: 1 | K8: 0 | O8: 1 | P8: 0 | Q8: 0 | R8: 0 | S8: 0 | T8: 1 | U8: 0 | V8: 3 | W8: 1 | X8: 1 | Y8: 2 | AA8: 0 | AC8: 0 | AD8: 1 | AE8: 0 | AF8: 0 | AG8: 0 | AH8: 1166 | AI8: 3.46 | AJ8: 9
A9: =+VLOOKUP(B9,studies!$A$2:$C$102,3) -> Nordhaus (1991) | B9: 3 | C9: 1991 | D9: 1 | E9: 1989 | F9: 1990 | G9: 0.25 | H9: 101.67175 | I9: 0 | J9: 1 | K9: 0 | O9: 1 | P9: 0 | Q9: 0 | R9: 0 | S9: 0 | T9: 1 | U9: 0 | V9: 3 | W9: 1 | X9: 1 | Y9: 2 | AA9: 0 | AC9: 0 | AD9: 1 | AE9: 0 | AF9: 0 | AG9: 0 | AH9: 1166 | AI9: 3.46 | AJ9: 9
A10: =+VLOOKUP(B10,studies!$A$2:$C$102,3) -> Nordhaus (1991) | B10: 3 | C10: 1991 | D10: 1 | E10: 1989 | F10: 1990 | G10: 0.125 | H10: 25.38326 | I10: 0 | J10: 1 | K10: 0 | O10: 1 | P10: 0 | Q10: 0 | R10: 0 | S10: 0 | T10: 1 | U10: 0 | V10: 3 | W10: 1 | X10: 1 | Y10: 2 | AA10: 0 | AC10: 0 | AD10: 1 | AE10: 0 | AF10: 0 | AG10: 0 | AH10: 1166 | AI10: 3.46 | AJ10: 9
A11: =+VLOOKUP(B11,studies!$A$2:$C$102,3) -> Nordhaus (1991) | B11: 3 | C11: 1991 | D11: 1 | E11: 1989 | F11: 1990 | G11: 0.0625 | H11: 33.844346 | I11: 0 | J11: 1 | K11: 0 | O11: 1 | P11: 0 | Q11: 0 | R11: 0 | S11: 0 | T11: 1 | U11: 0 | V11: 7 | W11: 4 | X11: 1 | Y11: 3 | AA11: 0 | AC11: 0 | AD11: 1 | AE11: 0 | AF11: 0 | AG11: 0 | AH11: 1166 | AI11: 3.46 | AJ11: 9
A12: =+VLOOKUP(B12,studies!$A$2:$C$102,3) -> Nordhaus (1991) | B12: 3 | C12: 1991 | D12: 1 | E12: 1989 | F12: 1990 | G12: 0.125 | H12: 16.922173 | I12: 0 | J12: 1 | K12: 0 | O12: 1 | P12: 0 | Q12: 0 | R12: 0 | S12: 0 | T12: 1 | U12: 0 | V12: 7 | W12: 4 | X12: 1 | Y12: 3 | AA12: 0 | AC12: 0 | AD12: 1 | AE12: 0 | AF12: 0 | AG12: 0 | AH12: 1166 | AI12: 3.46 | AJ12: 9
A13: =+VLOOKUP(B13,studies!$A$2:$C$102,3) -> Nordhaus (1991) | B13: 3 | C13: 1991 | D13: 1 | E13: 1989 | F13: 1990 | G13: 0.0625 | H13: 4.2998965 | I13: 0 | J13: 1 | K13: 0 | O13: 1 | P13: 0 | Q13: 0 | R13: 0 | S13: 0 | T13: 1 | U13: 0 | V13: 7 | W13: 4 | X13: 1 | Y13: 3 | AA13: 0 | AC13: 0 | AD13: 1 | AE13: 0 | AF13: 0 | AG13: 0 | AH13: 1166 | AI13: 3.46 | AJ13: 9
A14: =+VLOOKUP(B14,studies!$A$2:$C$102,3) -> Cline (1992) | B14: 4 | C14: 1992 | D14: 0 | E14: 1989 | F14: 1990 | G14: 1 | H14: 245.51022 | I14: 0 | J14: 1 | K14: 0 | L14: 111.7847 | M14: 114.06602 | N14: 114.06602 | O14: 1 | P14: 1 | Q14: 0 | R14: 1 | S14: 0 | T14: 0 | U14: 0 | V14: 1.5 | W14: 0 | X14: 1.5 | Y14: 1 | AA14: 0 | AC14: 0 | AD14: 0 | AE14: 0 | AF14: 0 | AG14: 0 | AH14: 39 | AI14: 0 | AJ14: 1
A15: =+VLOOKUP(B15,studies!$A$2:$C$102,3) -> Haraden (1992) | B15: 5 | C15: 1992 | D15: 1 | E15: 1984 | F15: 1987 | G15: 1 | H15: 72.59118 | I15: 0 | J15: 1 | K15: 0 | O15: 1 | P15: 0 | Q15: 0 | R15: 0 | S15: 0 | T15: 0 | U15: 0 | V15: 4 | W15: 2 | X15: 1 | Y15: 2 | AA15: 0 | AC15: 0 | AD15: 0 | AE15: 0 | AF15: 0 | AG15: 0 | AH15: 12 | AI15: 1.85 | AJ15: 1
A16: =+VLOOKUP(B16,studies!$A$2:$C$102,3) -> Hohmeyer & Gaertner (1992) | B16: 6 | C16: 1992 | D16: 0 | E16: 1990 | F16: 1990 | G16: 1 | H16: 6383.0401 | I16: 0 | J16: 1 | K16: 0 | O16: 1 | P16: 0 | Q16: 0 | R16: 1 | S16: 0 | T16: 0 | U16: 0 | V16: 0 | W16: 2 | AA16: 0 | AC16: 0 | AD16: 0 | AE16: 0 | AF16: 0 | AG16: 0 | AH16: 37 | AI16: 0 | AJ16: 1
A17: =+VLOOKUP(B17,studies!$A$2:$C$102,3) -> Penner et al. (1992) | B17: 7 | C17: 1992 | D17: 1 | E17: 1989 | F17: 1989 | G17: 0.25 | H17: 65.023092 | I17: 0 | J17: 1 | K17: 0 | O17: 0 | P17: 0 | Q17: 0 | R17: 0 | S17: 0 | T17: 1 | U17: 0 | V17: 4 | W17: 2 | AA17: 0 | AC17: 0 | AD17: 0 | AE17: 0 | AF17: 0 | AG17: 0 | AH17: 7 | AI17: 1.85 | AJ17: 1
A18: =+VLOOKUP(B18,studies!$A$2:$C$102,3) -> Haraden (1993) | B18: 8 | C18: 1993 | D18: 1 | E18: 1989 | F18: 1989 | G18: 0.25 | H18: 7.2161199 | I18: 0 | J18: 1 | K18: 0 | O18: 0 | P18: 0 | Q18: 0 | R18: 0 | S18: 0 | T18: 0 | U18: 0 | V18: 4 | W18: 2 | X18: 1.25 | Y18: 1.6 | AA18: 0 | AC18: 0 | AD18: 0 | AE18: 0 | AF18: 0 | AG18: 0 | AH18: 9 | AI18: 1.85 | AJ18: 3
A19: =+VLOOKUP(B19,studies!$A$2:$C$102,3) -> Haraden (1993) | B19: 8 | C19: 1993 | D19: 1 | E19: 1989 | F19: 1989 | G19: 0.5 | H19: 11.623804 | I19: 0 | J19: 1 | K19: 0 | O19: 0 | P19: 0 | Q19: 0 | R19: 0 | S19: 0 | T19: 0 | U19: 0 | V19: 4 | W19: 2 | X19: 0.86956522 | Y19: 2.3 | AA19: 0 | AC19: 0 | AD19: 0 | AE19: 0 | AF19: 0 | AG19: 0 | AH19: 9 | AI19: 1.85 | AJ19: 3
A20: =+VLOOKUP(B20,studies!$A$2:$C$102,3) -> Haraden (1993) | B20: 8 | C20: 1993 | D20: 1 | E20: 1989 | F20: 1989 | G20: 0.25 | H20: 34.247315 | I20: 0 | J20: 1 | K20: 0 | O20: 0 | P20: 0 | Q20: 0 | R20: 0 | S20: 0 | T20: 0 | U20: 0 | V20: 4 | W20: 2 | X20: 0.5 | Y20: 4 | AA20: 0 | AC20: 0 | AD20: 0 | AE20: 0 | AF20: 0 | AG20: 0 | AH20: 9 | AI20: 1.85 | AJ20: 3
A21: =+VLOOKUP(B21,studies!$A$2:$C$102,3) -> Nordhaus (1993) | B21: 9 | C21: 1993 | D21: 1 | E21: 1989 | F21: 1990 | G21: 1 | H21: 18.914501 | I21: 0 | J21: 1 | K21: 0 | O21: 0 | P21: 1 | Q21: 0 | R21: 1 | S21: 0 | T21: 1 | U21: 0 | V21: 5 | W21: 3 | AA21: 0 | AC21: 0 | AD21: 1 | AE21: 0 | AF21: 1 | AG21: 0 | AH21: 386 | AI21: 1.13 | AJ21: 1
A22: =+VLOOKUP(B22,studies!$A$2:$C$102,3) -> Parry (1993) | B22: 10 | C22: 1993 | D22: 1 | E22: 1991 | F22: 1990 | G22: 0.0089285714 | H22: 0.025256367 | I22: 0 | J22: 1 | K22: 0 | O22: 0 | P22: 1 | Q22: 0 | R22: 0 | S22: 0 | T22: 1 | U22: 0 | W22: 0 | AA22: 0 | AC22: 0 | AD22: 0 | AE22: 0 | AF22: 0 | AG22: 0 | AH22: 23 | AI22: 1.13 | AJ22: 60
A23: =+VLOOKUP(B23,studies!$A$2:$C$102,3) -> Parry (1993) | B23: 10 | C23: 1993 | D23: 1 | E23: 1991 | F23: 1990 | G23: 0.0089285714 | H23: 0.1515382 | I23: 0 | J23: 1 | K23: 0 | O23: 0 | P23: 1 | Q23: 0 | R23: 0 | S23: 0 | T23: 1 | U23: 0 | W23: 0 | AA23: 0 | AC23: 0 | AD23: 0 | AE23: 0 | AF23: 0 | AG23: 0 | AH23: 23 | AI23: 1.13 | AJ23: 60
A24: =+VLOOKUP(B24,studies!$A$2:$C$102,3) -> Parry (1993) | B24: 10 | C24: 1993 | D24: 1 | E24: 1991 | F24: 1990 | G24: 0.017857143 | H24: 0.03788455 | I24: 0 | J24: 1 | K24: 0 | O24: 0 | P24: 1 | Q24: 0 | R24: 0 | S24: 0 | T24: 1 | U24: 0 | W24: 0 | AA24: 0 | AC24: 0 | AD24: 0 | AE24: 0 | AF24: 0 | AG24: 0 | AH24: 23 | AI24: 1.13 | AJ24: 60
A25: =+VLOOKUP(B25,studies!$A$2:$C$102,3) -> Parry (1993) | B25: 10 | C25: 1993 | D25: 1 | E25: 1991 | F25: 1990 | G25: 0.017857143 | H25: 0.2273073 | I25: 0 | J25: 1 | K25: 0 | O25: 0 | P25: 1 | Q25: 0 | R25: 0 | S25: 0 | T25: 1 | U25: 0 | W25: 0 | AA25: 0 | AC25: 0 | AD25: 0 | AE25: 0 | AF25: 0 | AG25: 0 | AH25: 23 | AI25: 1.13 | AJ25: 60
A26: =+VLOOKUP(B26,studies!$A$2:$C$102,3) -> Parry (1993) | B26: 10 | C26: 1993 | D26: 1 | E26: 1991 | F26: 1990 | G26: 0.017857143 | H26: 0.075769101 | I26: 0 | J26: 1 | K26: 0 | O26: 0 | P26: 1 | Q26: 0 | R26: 0 | S26: 0 | T26: 1 | U26: 0 | W26: 0 | AA26: 0 | AC26: 0 | AD26: 0 | AE26: 0 | AF26: 0 | AG26: 0 | AH26: 23 | AI26: 1.13 | AJ26: 60
A27: =+VLOOKUP(B27,studies!$A$2:$C$102,3) -> Parry (1993) | B27: 10 | C27: 1993 | D27: 1 | E27: 1991 | F27: 1990 | G27: 0.017857143 | H27: 0.4546146 | I27: 0 | J27: 1 | K27: 0 | O27: 0 | P27: 1 | Q27: 0 | R27: 0 | S27: 0 | T27: 1 | U27: 0 | W27: 0 | AA27: 0 | AC27: 0 | AD27: 0 | AE27: 0 | AF27: 0 | AG27: 0 | AH27: 23 | AI27: 1.13 | AJ27: 60
A28: =+VLOOKUP(B28,studies!$A$2:$C$102,3) -> Parry (1993) | B28: 10 | C28: 1993 | D28: 1 | E28: 1991 | F28: 1990 | G28: 0.0089285714 | H28: 0.13891002 | I28: 0 | J28: 1 | K28: 0 | O28: 0 | P28: 1 | Q28: 0 | R28: 0 | S28: 0 | T28: 1 | U28: 0 | W28: 0 | AA28: 0 | AC28: 0 | AD28: 0 | AE28: 0 | AF28: 0 | AG28: 0 | AH28: 23 | AI28: 1.13 | AJ28: 60
A29: =+VLOOKUP(B29,studies!$A$2:$C$102,3) -> Parry (1993) | B29: 10 | C29: 1993 | D29: 1 | E29: 1991 | F29: 1990 | G29: 0.0089285714 | H29: 0.83346011 | I29: 0 | J29: 1 | K29: 0 | O29: 0 | P29: 1 | Q29: 0 | R29: 0 | S29: 0 | T29: 1 | U29: 0 | W29: 0 | AA29: 0 | AC29: 0 | AD29: 0 | AE29: 0 | AF29: 0 | AG29: 0 | AH29: 23 | AI29: 1.13 | AJ29: 60
A30: =+VLOOKUP(B30,studies!$A$2:$C$102,3) -> Parry (1993) | B30: 10 | C30: 1993 | D30: 1 | E30: 1991 | F30: 1990 | G30: 0.0089285714 | H30: 0.34096095 | I30: 0 | J30: 1 | K30: 0 | O30: 0 | P30: 1 | Q30: 0 | R30: 0 | S30: 0 | T30: 1 | U30: 0 | W30: 0 | AA30: 0 | AC30: 0 | AD30: 0 | AE30: 0 | AF30: 0 | AG30: 0 | AH30: 23 | AI30: 1.13 | AJ30: 60
A31: =+VLOOKUP(B31,studies!$A$2:$C$102,3) -> Parry (1993) | B31: 10 | C31: 1993 | D31: 1 | E31: 1991 | F31: 1990 | G31: 0.0089285714 | H31: 2.0457657 | I31: 0 | J31: 1 | K31: 0 | O31: 0 | P31: 1 | Q31: 0 | R31: 0 | S31: 0 | T31: 1 | U31: 0 | W31: 0 | AA31: 0 | AC31: 0 | AD31: 0 | AE31: 0 | AF31: 0 | AG31: 0 | AH31: 23 | AI31: 1.13 | AJ31: 60
A32: =+VLOOKUP(B32,studies!$A$2:$C$102,3) -> Parry (1993) | B32: 10 | C32: 1993 | D32: 1 | E32: 1991 | F32: 1990 | G32: 0.0089285714 | H32: 0.050512734 | I32: 0 | J32: 1 | K32: 0 | O32: 0 | P32: 1 | Q32: 0 | R32: 0 | S32: 0 | T32: 1 | U32: 0 | W32: 0 | AA32: 0 | AC32: 0 | AD32: 0 | AE32: 0 | AF32: 0 | AG32: 0 | AH32: 23 | AI32: 1.13 | AJ32: 60
A33: =+VLOOKUP(B33,studies!$A$2:$C$102,3) -> Parry (1993) | B33: 10 | C33: 1993 | D33: 1 | E33: 1991 | F33: 1990 | G33: 0.0089285714 | H33: 0.3030764 | I33: 0 | J33: 1 | K33: 0 | O33: 0 | P33: 1 | Q33: 0 | R33: 0 | S33: 0 | T33: 1 | U33: 0 | W33: 0 | AA33: 0 | AC33: 0 | AD33: 0 | AE33: 0 | AF33: 0 | AG33: 0 | AH33: 23 | AI33: 1.13 | AJ33: 60
... A81: =+VLOOKUP(B81,studies!$A$2:$C$102,3) -> Parry (1993) | B81: 10 | C81: 1993 | D81: 1 | E81: 1991 | F81: 1990 | G81: 0.0089285714 | H81: 10396.657 | I81: 0 | J81: 1 | K81: 0 | O81: 0 | P81: 1 | Q81: 0 | R81: 0 | S81: 0 | T81: 1 | U81: 0 | W81: 0 | AA81: 0 | AC81: 0 | AD81: 0 | AE81: 0 | AF81: 0 | AG81: 0 | AH81: 23 | AI81: 1.13 | AJ81: 60
A82: =+VLOOKUP(B82,studies!$A$2:$C$102,3) -> Peck & Teisberg (1993) | B82: 11 | C82: 1993 | D82: 1 | E82: 1989 | F82: 2030 | G82: 0.5 | H82: 11.105529 | I82: 0 | J82: 1 | K82: 0 | O82: 0 | P82: 1 | Q82: 0 | R82: 1 | S82: 0 | T82: 0 | U82: 0 | V82: 5 | W82: 3 | AA82: 0 | AC82: 0 | AD82: 0 | AE82: 0 | AF82: 1 | AG82: 0 | AH82: 198 | AI82: 1.13 | AJ82: 27
A83: =+VLOOKUP(B83,studies!$A$2:$C$102,3) -> Peck & Teisberg (1993) | B83: 11 | C83: 1993 | D83: 1 | E83: 1989 | F83: 2030 | G83: 0.019230769 | H83: 24.210053 | I83: 0 | J83: 1 | K83: 0 | O83: 0 | P83: 1 | Q83: 0 | R83: 1 | S83: 0 | T83: 0 | U83: 0 | V83: 5 | W83: 3 | AA83: 0 | AC83: 0 | AD83: 0 | AE83: 0 | AF83: 1 | AG83: 0 | AH83: 198 | AI83: 1.13 | AJ83: 27
A84: =+VLOOKUP(B84,studies!$A$2:$C$102,3) -> Peck & Teisberg (1993) | B84: 11 | C84: 1993 | D84: 1 | E84: 1989 | F84: 2030 | G84: 0.019230769 | H84: 24.543219 | I84: 0 | J84: 1 | K84: 0 | O84: 0 | P84: 1 | Q84: 0 | R84: 1 | S84: 0 | T84: 0 | U84: 0 | V84: 5 | W84: 3 | AA84: 0 | AC84: 0 | AD84: 0 | AE84: 0 | AF84: 1 | AG84: 0 | AH84: 198 | AI84: 1.13 | AJ84: 27
A85: =+VLOOKUP(B85,studies!$A$2:$C$102,3) -> Peck & Teisberg (1993) | B85: 11 | C85: 1993 | D85: 1 | E85: 1989 | F85: 2030 | G85: 0.019230769 | H85: 25.431661 | I85: 0 | J85: 1 | K85: 0 | O85: 0 | P85: 1 | Q85: 0 | R85: 1 | S85: 0 | T85: 0 | U85: 0 | V85: 5 | W85: 3 | AA85: 0 | AC85: 0 | AD85: 0 | AE85: 0 | AF85: 1 | AG85: 0 | AH85: 198 | AI85: 1.13 | AJ85: 27
A86: =+VLOOKUP(B86,studies!$A$2:$C$102,3) -> Peck & Teisberg (1993) | B86: 11 | C86: 1993 | D86: 1 | E86: 1989 | F86: 2030 | G86: 0.019230769 | H86: 24.210053 | I86: 0 | J86: 1 | K86: 0 | O86: 0 | P86: 1 | Q86: 0 | R86: 1 | S86: 0 | T86: 0 | U86: 0 | V86: 5 | W86: 3 | AA86: 0 | AC86: 0 | AD86: 0 | AE86: 0 | AF86: 1 | AG86: 0 | AH86: 198 | AI86: 1.13 | AJ86: 27
A87: =+VLOOKUP(B87,studies!$A$2:$C$102,3) -> Peck & Teisberg (1993) | B87: 11 | C87: 1993 | D87: 1 | E87: 1989 | F87: 2030 | G87: 0.019230769 | H87: 24.543219 | I87: 0 | J87: 1 | K87: 0 | O87: 0 | P87: 1 | Q87: 0 | R87: 1 | S87: 0 | T87: 0 | U87: 0 | V87: 5 | W87: 3 | AA87: 0 | AC87: 0 | AD87: 0 | AE87: 0 | AF87: 1 | AG87: 0 | AH87: 198 | AI87: 1.13 | AJ87: 27
...

Sheet notes
A1: Dataset 0
A2: base dataset used from Richard Tols web: https://sites.google.com/site/climateconomics/data/06-economic-impacts, file marginaldamagecosts.xlsx as of March 5, 2013
A3: more studies picked using this query from Google scholar, additionally papers references checked for more papers, search finished on August 1, 2014 | O3: query
A4: keyword: integrated assessment, social cost of carbon, climate damages, marginal damage costs, climate change, emissions, greenhouse, carbon dioxide, marginal impacts
A5: dataset 0 is a whole dataset without curvature (future emissions not included), future SCC are on sheet SCC (with average growth rate of SCC estimation)
A6: SCC recalculated to 2010 USD/tC using consumer price index (CPI) from here (http://research.stlouisfed.org/fred2/series/CPIAUCNS/downloaddata)
A7: SCC recalculated for the 2015 year of emission using SCC growth rate of 3.11% per year (calculated from the literature, see sheet SCC: yearly growth rate between the closest two time points reported in the article)
A8: our preference for SCC reporting: median>best guess>mean; mean and median usually reported when Monte Carlo simulations
A9: standard deviations and confidence intervals also recalculated to 2010/2015 USD/emission
A10: confidence intervals recalculated to upper and lower standard deviation (preferentially for 5% and 95% CI)
A13: Dataset 1
A14: only studies reporting standard deviation or confidence intervals
A15: if study includes both estimates with stdev or CI and without stdev or CI, we delete estimates that do not have stdev or CI
A16: sometimes only upper interval present (then we assume upper = lower), sometimes only stdev reported (then we assume stdev = upper = lower)
A19: Dataset 2
... A31: Variables
A32: idstudy | B32: = identification number of a study
A33: reviewed | B33: = 1 if study was published in a peer-reviewed outlet.
A34: pubyear | B34: The year of publication of the study.
A35: dollaryear | B35: SCC are reported in US dollar of a particular year per ton of CO2 (or C)
A36: emissionyear | B36: SCC are associated with a one-ton increase in CO2 emissions in a particular year
A37: tolweight | B37: Tol put weights across different estimates within each study
A38: scc | B38: estimate of the social cost of carbon in USD per ton of carbon
A39: sccmean | B39: = 1 if SCC estimate is a mean value
A40: sccbg | B40: = 1 if SCC estimate is a best guess value
A41: sccmed | B41: = 1 if SCC estimate is a median value
A42: stdev | B42: standard deviation of a SCC estimate
A43: stdlow | B43: standard deviation from confidence interval, lower limit of 5%
... A64: sjr | B64: = SciMago journal rank based on impact factor from Scopus

Sheet studies
A1: idstudy | B1: label bib | C1: label | D1: citation | E1: pubyear | F1: citations | G1: sjr
A2: 1 | B2: Nordhaus1982 | C2: Nordhaus (1982) | D2: Nordhaus, W. (1982): "How Fast Should We Graze the Global Commons?," American Economic Review, American Economic Association 72(2), 242-46. | E2: 1982 | F2: 132 | G2: 6.46
A3: 2 | B3: Ayres1991 | C3: Ayres & Walter (1991) | D3: Ayres, R.U. and J. Walter (1991): "The Greenhouse Effect: Damages, Costs and Abatement," Environmental and Resource Economics 1(3), 237-270. | E3: 1991 | F3: 220 | G3: 1.65
A4: 3 | B4: Nordhaus1991 | C4: Nordhaus (1991) | D4: Nordhaus, W.D. (1991): "To Slow or Not to Slow: The Economics of the Greenhouse Effect," Economic Journal 101(407), 920-937. | E4: 1991 | F4: 1166 | G4: 3.46
A5: 4 | B5: Cline1992 | C5: Cline (1992) | D5: Cline, W.R. (1992): The Economics of Global Warming, Institute for International Economics, Washington, D.C. | E5: 1992 | F5: 39 | G5: 0
A6: 5 | B6: Haraden1992 | C6: Haraden (1992) | D6: Haraden, J. (1992): "An improved shadow price for CO2," Energy 17(5), 419-426. | E6: 1992 | F6: 12 | G6: 1.85
A7: 6 | B7: Hohmeyer1992 | C7: Hohmeyer & Gaertner (1992) | D7: Hohmeyer, O. and M.Gaertner (1992), The Costs of Climate Change - A Rough Estimate of Orders of Magnitude, Fraunhofer-Institut fur Systemtechnik und Innovationsforschung, Karlsruhe. | E7: 1992 | F7: 37 | G7: 0
A8: 7 | B8: Penner1992 | C8: Penner et al. (1992) | D8: Penner, S.S., J.Haraden, and S.Mates (1992), 'Long-term global energy supplies with acceptable environmental impacts', Energy, 17, (10), pp. 883-899. | E8: 1992 | F8: 7 | G8: 1.85
A9: 8 | B9: Haraden1993 | C9: Haraden (1993) | D9: Haraden, J. 1993. ʻAn updated shadow price for CO2ʼ. Energy 18(3): 303–307 | E9: 1993 | F9: 9 | G9: 1.85
A10: 9 | B10: Nordhaus1993 | C10: Nordhaus (1993) | D10: Nordhaus, W.D. (1993), 'Rolling the 'DICE': An Optimal Transition Path for Controlling Greenhouse Gases', Resource and Energy Economics, 15, 27-50. | E10: 1993 | F10: 386 | G10: 1.13
A11: 10 | B11: Parry1993 | C11: Parry (1993) | D11: Parry, I.W.H. (1993), 'Some Estimates of the Insurance Value against Climate Change from Reducing Greenhouse Gas Emissions', Resource and Energy Economics, 15, 99-115. | E11: 1993 | F11: 23 | G11: 1.13
A12: 11 | B12: Peck1993 | C12: Peck & Teisberg (1993) | D12: Peck, S.C. and T.J.Teisberg (1993), 'Global Warming Uncertainties and the Value of Information: An Analysis using CETA', Resource and Energy Economics, 15, 71-97. | E12: 1993 | F12: 198 | G12: 1.13
A13: 12 | B13: Reilly1993 | C13: Reilly & Richards (1993) | D13: Reilly, J.M. and K.R.Richards (1993), 'Climate Change Damage and the Trace Gas Index Issue', Environmental and Resource Economics, 3, 41-61. | E13: 1993 | F13: 115 | G13: 1.65
... A102: 102 | B102: Rezai2014 | C102: Rezai & van der Ploeg (2014) | D102: Rezai Armon & Frederick van der Ploeg, 2014. "Abandoning Fossil Fuel; How fast and how much?," OxCarre Working Papers 123, Oxford Centre for the Analysis of Resource Rich Economies, University of Oxford. | E102: 2014 | F102: 3 | G102: 0

Sheet Dataset0
A1: label | B1: idstudy | C1: pubyear | D1: reviewed | E1: dollaryear | F1: emissionyear | G1: tolweight | H1: scc | I1: sccmean | J1: sccbg | K1: sccmed | L1: stdev | M1: stdlow | N1: stdup | O1: iie | P1: mmi | Q1: dim | R1: sce | S1: fund | T1: dicerice | U1: page | V1: cdr | W1: prtp | X1: rra | Y1: growth | Z1: ies | AA1: eweight | AB1: climatesens | AC1: hope | AD1: nordhaus | AE1: tol | AF1: pigou
A2: =+VLOOKUP(B2,studies!$A$2:$C$102,3) -> Nordhaus (1982) | B2: 1 | C2: 1982 | D2: 1 | E2: 1980 | F2: 1980 | G2: 0.5 | H2: 1984.9987 | I2: 0 | J2: 1 | K2: 0 | O2: 1 | P2: 0 | Q2: 0 | R2: 0 | S2: 0 | T2: 0 | U2: 0 | W2: 1 | Y2: 4 | AA2: 0 | AC2: 0 | AD2: 1 | AE2: 0 | AF2: 0
A3: =+VLOOKUP(B3,studies!$A$2:$C$102,3) -> Nordhaus (1982) | B3: 1 | C3: 1982 | D3: 1 | E3: 1980 | F3: 1980 | G3: 0.5 | H3: 283.57124 | I3: 0 | J3: 1 | K3: 0 | O3: 1 | P3: 0 | Q3: 0 | R3: 0 | S3: 0 | T3: 0 | U3: 0 | W3: 1 | Y3: 1 | AA3: 0 | AC3: 0 | AD3: 1 | AE3: 0 | AF3: 0
A4: =+VLOOKUP(B4,studies!$A$2:$C$102,3) -> Ayres & Walter (1991) | B4: 2 | C4: 1991 | D4: 1 | E4: 1989 | F4: 1990 | G4: 1 | H4: 450.7956 | I4: 0 | J4: 1 | K4: 0 | O4: 1 | P4: 0 | Q4: 0 | R4: 0 | S4: 0 | T4: 0 | U4: 0 | V4: 3 | W4: 1 | Y4: 0 | AA4: 0 | AC4: 0 | AD4: 0 | AE4: 0 | AF4: 0
A5: =+VLOOKUP(B5,studies!$A$2:$C$102,3) -> Nordhaus (1991) | B5: 3 | C5: 1991 | D5: 1 | E5: 1989 | F5: 1990 | G5: 0.0625 | H5: 914.62959 | I5: 0 | J5: 1 | K5: 0 | O5: 1 | P5: 0 | Q5: 0 | R5: 0 | S5: 0 | T5: 1 | U5: 0 | V5: 1 | W5: 0 | X5: 1 | Y5: 1 | AA5: 0 | AC5: 0 | AD5: 1 | AE5: 0 | AF5: 0
A6: =+VLOOKUP(B6,studies!$A$2:$C$102,3) -> Nordhaus (1991) | B6: 3 | C6: 1991 | D6: 1 | E6: 1989 | F6: 1990 | G6: 0.125 | H6: 457.31479 | I6: 0 | J6: 1 | K6: 0 | O6: 1 | P6: 0 | Q6: 0 | R6: 0 | S6: 0 | T6: 1 | U6: 0 | V6: 1 | W6: 0 | X6: 1 | Y6: 1 | AA6: 0 | AC6: 0 | AD6: 1 | AE6: 0 | AF6: 0
A7: =+VLOOKUP(B7,studies!$A$2:$C$102,3) -> Nordhaus (1991) | B7: 3 | C7: 1991 | D7: 1 | E7: 1989 | F7: 1990 | G7: 0.0625 | H7: 114.29402 | I7: 0 | J7: 1 | K7: 0 | O7: 1 | P7: 0 | Q7: 0 | R7: 0 | S7: 0 | T7: 1 | U7: 0 | V7: 1 | W7: 0 | X7: 1 | Y7: 1 | AA7: 0 | AC7: 0 | AD7: 1 | AE7: 0 | AF7: 0
A8: =+VLOOKUP(B8,studies!$A$2:$C$102,3) -> Nordhaus (1991) | B8: 3 | C8: 1991 | D8: 1 | E8: 1989 | F8: 1990 | G8: 0.125 | H8: 203.20478 | I8: 0 | J8: 1 | K8: 0 | O8: 1 | P8: 0 | Q8: 0 | R8: 0 | S8: 0 | T8: 1 | U8: 0 | V8: 3 | W8: 1 | X8: 1 | Y8: 2 | AA8: 0 | AC8: 0 | AD8: 1 | AE8: 0 | AF8: 0
A9: =+VLOOKUP(B9,studies!$A$2:$C$102,3) -> Nordhaus (1991) | B9: 3 | C9: 1991 | D9: 1 | E9: 1989 | F9: 1990 | G9: 0.25 | H9: 101.67175 | I9: 0 | J9: 1 | K9: 0 | O9: 1 | P9: 0 | Q9: 0 | R9: 0 | S9: 0 | T9: 1 | U9: 0 | V9: 3 | W9: 1 | X9: 1 | Y9: 2 | AA9: 0 | AC9: 0 | AD9: 1 | AE9: 0 | AF9: 0
A10: =+VLOOKUP(B10,studies!$A$2:$C$102,3) -> Nordhaus (1991) | B10: 3 | C10: 1991 | D10: 1 | E10: 1989 | F10: 1990 | G10: 0.125 | H10: 25.38326 | I10: 0 | J10: 1 | K10: 0 | O10: 1 | P10: 0 | Q10: 0 | R10: 0 | S10: 0 | T10: 1 | U10: 0 | V10: 3 | W10: 1 | X10: 1 | Y10: 2 | AA10: 0 | AC10: 0 | AD10: 1 | AE10: 0 | AF10: 0
A11: =+VLOOKUP(B11,studies!$A$2:$C$102,3) -> Nordhaus (1991) | B11: 3 | C11: 1991 | D11: 1 | E11: 1989 | F11: 1990 | G11: 0.0625 | H11: 33.844346 | I11: 0 | J11: 1 | K11: 0 | O11: 1 | P11: 0 | Q11: 0 | R11: 0 | S11: 0 | T11: 1 | U11: 0 | V11: 7 | W11: 4 | X11: 1 | Y11: 3 | AA11: 0 | AC11: 0 | AD11: 1 | AE11: 0 | AF11: 0
A12: =+VLOOKUP(B12,studies!$A$2:$C$102,3) -> Nordhaus (1991) | B12: 3 | C12: 1991 | D12: 1 | E12: 1989 | F12: 1990 | G12: 0.125 | H12: 16.922173 | I12: 0 | J12: 1 | K12: 0 | O12: 1 | P12: 0 | Q12: 0 | R12: 0 | S12: 0 | T12: 1 | U12: 0 | V12: 7 | W12: 4 | X12: 1 | Y12: 3 | AA12: 0 | AC12: 0 | AD12: 1 | AE12: 0 | AF12: 0
A13: =+VLOOKUP(B13,studies!$A$2:$C$102,3) -> Nordhaus (1991) | B13: 3 | C13: 1991 | D13: 1 | E13: 1989 | F13: 1990 | G13: 0.0625 | H13: 4.2998965 | I13: 0 | J13: 1 | K13: 0 | O13: 1 | P13: 0 | Q13: 0 | R13: 0 | S13: 0 | T13: 1 | U13: 0 | V13: 7 | W13: 4 | X13: 1 | Y13: 3 | AA13: 0 | AC13: 0 | AD13: 1 | AE13: 0 | AF13: 0
A14: =+VLOOKUP(B14,studies!$A$2:$C$102,3) -> Cline (1992) | B14: 4 | C14: 1992 | D14: 0 | E14: 1989 | F14: 1990 | G14: 1 | H14: 245.51022 | I14: 0 | J14: 1 | K14: 0 | L14: 111.7847 | M14: 114.06602 | N14: 114.06602 | O14: 1 | P14: 1 | Q14: 0 | R14: 1 | S14: 0 | T14: 0 | U14: 0 | V14: 1.5 | W14: 0 | X14: 1.5 | Y14: 1 | AA14: 0 | AC14: 0 | AD14: 0 | AE14: 0 | AF14: 0
A15: =+VLOOKUP(B15,studies!$A$2:$C$102,3) -> Haraden (1992) | B15: 5 | C15: 1992 | D15: 1 | E15: 1984 | F15: 1987 | G15: 1 | H15: 72.59118 | I15: 0 | J15: 1 | K15: 0 | O15: 1 | P15: 0 | Q15: 0 | R15: 0 | S15: 0 | T15: 0 | U15: 0 | V15: 4 | W15: 2 | X15: 1 | Y15: 2 | AA15: 0 | AC15: 0 | AD15: 0 | AE15: 0 | AF15: 0
A16: =+VLOOKUP(B16,studies!$A$2:$C$102,3) -> Hohmeyer & Gaertner (1992) | B16: 6 | C16: 1992 | D16: 0 | E16: 1990 | F16: 1990 | G16: 1 | H16: 6383.0401 | I16: 0 | J16: 1 | K16: 0 | O16: 1 | P16: 0 | Q16: 0 | R16: 1 | S16: 0 | T16: 0 | U16: 0 | V16: 0 | W16: 2 | AA16: 0 | AC16: 0 | AD16: 0 | AE16: 0 | AF16: 0
A17: =+VLOOKUP(B17,studies!$A$2:$C$102,3) -> Penner et al. (1992) | B17: 7 | C17: 1992 | D17: 1 | E17: 1989 | F17: 1989 | G17: 0.25 | H17: 65.023092 | I17: 0 | J17: 1 | K17: 0 | O17: 0 | P17: 0 | Q17: 0 | R17: 0 | S17: 0 | T17: 1 | U17: 0 | V17: 4 | W17: 2 | AA17: 0 | AC17: 0 | AD17: 0 | AE17: 0 | AF17: 0
A18: =+VLOOKUP(B18,studies!$A$2:$C$102,3) -> Haraden (1993) | B18: 8 | C18: 1993 | D18: 1 | E18: 1989 | F18: 1989 | G18: 0.25 | H18: 7.2161199 | I18: 0 | J18: 1 | K18: 0 | O18: 0 | P18: 0 | Q18: 0 | R18: 0 | S18: 0 | T18: 0 | U18: 0 | V18: 4 | W18: 2 | X18: 1.25 | Y18: 1.6 | AA18: 0 | AC18: 0 | AD18: 0 | AE18: 0 | AF18: 0
A19: =+VLOOKUP(B19,studies!$A$2:$C$102,3) -> Haraden (1993) | B19: 8 | C19: 1993 | D19: 1 | E19: 1989 | F19: 1989 | G19: 0.5 | H19: 11.623804 | I19: 0 | J19: 1 | K19: 0 | O19: 0 | P19: 0 | Q19: 0 | R19: 0 | S19: 0 | T19: 0 | U19: 0 | V19: 4 | W19: 2 | X19: 0.86956522 | Y19: 2.3 | AA19: 0 | AC19: 0 | AD19: 0 | AE19: 0 | AF19: 0
A20: =+VLOOKUP(B20,studies!$A$2:$C$102,3) -> Haraden (1993) | B20: 8 | C20: 1993 | D20: 1 | E20: 1989 | F20: 1989 | G20: 0.25 | H20: 34.247315 | I20: 0 | J20: 1 | K20: 0 | O20: 0 | P20: 0 | Q20: 0 | R20: 0 | S20: 0 | T20: 0 | U20: 0 | V20: 4 | W20: 2 | X20: 0.5 | Y20: 4 | AA20: 0 | AC20: 0 | AD20: 0 | AE20: 0 | AF20: 0
A21: =+VLOOKUP(B21,studies!$A$2:$C$102,3) -> Nordhaus (1993) | B21: 9 | C21: 1993 | D21: 1 | E21: 1989 | F21: 1990 | G21: 1 | H21: 18.914501 | I21: 0 | J21: 1 | K21: 0 | O21: 0 | P21: 1 | Q21: 0 | R21: 1 | S21: 0 | T21: 1 | U21: 0 | V21: 5 | W21: 3 | AA21: 0 | AC21: 0 | AD21: 1 | AE21: 0 | AF21: 1
A22: =+VLOOKUP(B22,studies!$A$2:$C$102,3) -> Parry (1993) | B22: 10 | C22: 1993 | D22: 1 | E22: 1991 | F22: 1990 | G22: 0.0089285714 | H22: 0.025256367 | I22: 0 | J22: 1 | K22: 0 | O22: 0 | P22: 1 | Q22: 0 | R22: 0 | S22: 0 | T22: 1 | U22: 0 | W22: 0 | AA22: 0 | AC22: 0 | AD22: 0 | AE22: 0 | AF22: 0
A23: =+VLOOKUP(B23,studies!$A$2:$C$102,3) -> Parry (1993) | B23: 10 | C23: 1993 | D23: 1 | E23: 1991 | F23: 1990 | G23: 0.0089285714 | H23: 0.1515382 | I23: 0 | J23: 1 | K23: 0 | O23: 0 | P23: 1 | Q23: 0 | R23: 0 | S23: 0 | T23: 1 | U23: 0 | W23: 0 | AA23: 0 | AC23: 0 | AD23: 0 | AE23: 0 | AF23: 0
A24: =+VLOOKUP(B24,studies!$A$2:$C$102,3) -> Parry (1993) | B24: 10 | C24: 1993 | D24: 1 | E24: 1991 | F24: 1990 | G24: 0.017857143 | H24: 0.03788455 | I24: 0 | J24: 1 | K24: 0 | O24: 0 | P24: 1 | Q24: 0 | R24: 0 | S24: 0 | T24: 1 | U24: 0 | W24: 0 | AA24: 0 | AC24: 0 | AD24: 0 | AE24: 0 | AF24: 0
A25: =+VLOOKUP(B25,studies!$A$2:$C$102,3) -> Parry (1993) | B25: 10 | C25: 1993 | D25: 1 | E25: 1991 | F25: 1990 | G25: 0.017857143 | H25: 0.2273073 | I25: 0 | J25: 1 | K25: 0 | O25: 0 | P25: 1 | Q25: 0 | R25: 0 | S25: 0 | T25: 1 | U25: 0 | W25: 0 | AA25: 0 | AC25: 0 | AD25: 0 | AE25: 0 | AF25: 0
A26: =+VLOOKUP(B26,studies!$A$2:$C$102,3) -> Parry (1993) | B26: 10 | C26: 1993 | D26: 1 | E26: 1991 | F26: 1990 | G26: 0.017857143 | H26: 0.075769101 | I26: 0 | J26: 1 | K26: 0 | O26: 0 | P26: 1 | Q26: 0 | R26: 0 | S26: 0 | T26: 1 | U26: 0 | W26: 0 | AA26: 0 | AC26: 0 | AD26: 0 | AE26: 0 | AF26: 0
A27: =+VLOOKUP(B27,studies!$A$2:$C$102,3) -> Parry (1993) | B27: 10 | C27: 1993 | D27: 1 | E27: 1991 | F27: 1990 | G27: 0.017857143 | H27: 0.4546146 | I27: 0 | J27: 1 | K27: 0 | O27: 0 | P27: 1 | Q27: 0 | R27: 0 | S27: 0 | T27: 1 | U27: 0 | W27: 0 | AA27: 0 | AC27: 0 | AD27: 0 | AE27: 0 | AF27: 0
A28: =+VLOOKUP(B28,studies!$A$2:$C$102,3) -> Parry (1993) | B28: 10 | C28: 1993 | D28: 1 | E28: 1991 | F28: 1990 | G28: 0.0089285714 | H28: 0.13891002 | I28: 0 | J28: 1 | K28: 0 | O28: 0 | P28: 1 | Q28: 0 | R28: 0 | S28: 0 | T28: 1 | U28: 0 | W28: 0 | AA28: 0 | AC28: 0 | AD28: 0 | AE28: 0 | AF28: 0
A29: =+VLOOKUP(B29,studies!$A$2:$C$102,3) -> Parry (1993) | B29: 10 | C29: 1993 | D29: 1 | E29: 1991 | F29: 1990 | G29: 0.0089285714 | H29: 0.83346011 | I29: 0 | J29: 1 | K29: 0 | O29: 0 | P29: 1 | Q29: 0 | R29: 0 | S29: 0 | T29: 1 | U29: 0 | W29: 0 | AA29: 0 | AC29: 0 | AD29: 0 | AE29: 0 | AF29: 0
A30: =+VLOOKUP(B30,studies!$A$2:$C$102,3) -> Parry (1993) | B30: 10 | C30: 1993 | D30: 1 | E30: 1991 | F30: 1990 | G30: 0.0089285714 | H30: 0.34096095 | I30: 0 | J30: 1 | K30: 0 | O30: 0 | P30: 1 | Q30: 0 | R30: 0 | S30: 0 | T30: 1 | U30: 0 | W30: 0 | AA30: 0 | AC30: 0 | AD30: 0 | AE30: 0 | AF30: 0
A31: =+VLOOKUP(B31,studies!$A$2:$C$102,3) -> Parry (1993) | B31: 10 | C31: 1993 | D31: 1 | E31: 1991 | F31: 1990 | G31: 0.0089285714 | H31: 2.0457657 | I31: 0 | J31: 1 | K31: 0 | O31: 0 | P31: 1 | Q31: 0 | R31: 0 | S31: 0 | T31: 1 | U31: 0 | W31: 0 | AA31: 0 | AC31: 0 | AD31: 0 | AE31: 0 | AF31: 0
A32: =+VLOOKUP(B32,studies!$A$2:$C$102,3) -> Parry (1993) | B32: 10 | C32: 1993 | D32: 1 | E32: 1991 | F32: 1990 | G32: 0.0089285714 | H32: 0.050512734 | I32: 0 | J32: 1 | K32: 0 | O32: 0 | P32: 1 | Q32: 0 | R32: 0 | S32: 0 | T32: 1 | U32: 0 | W32: 0 | AA32: 0 | AC32: 0 | AD32: 0 | AE32: 0 | AF32: 0
A33: =+VLOOKUP(B33,studies!$A$2:$C$102,3) -> Parry (1993) | B33: 10 | C33: 1993 | D33: 1 | E33: 1991 | F33: 1990 | G33: 0.0089285714 | H33: 0.3030764 | I33: 0 | J33: 1 | K33: 0 | O33: 0 | P33: 1 | Q33: 0 | R33: 0 | S33: 0 | T33: 1 | U33: 0 | W33: 0 | AA33: 0 | AC33: 0 | AD33: 0 | AE33: 0 | AF33: 0
... A81: =+VLOOKUP(B81,studies!$A$2:$C$102,3) -> Parry (1993) | B81: 10 | C81: 1993 | D81: 1 | E81: 1991 | F81: 1990 | G81: 0.0089285714 | H81: 10396.657 | I81: 0 | J81: 1 | K81: 0 | O81: 0 | P81: 1 | Q81: 0 | R81: 0 | S81: 0 | T81: 1 | U81: 0 | W81: 0 | AA81: 0 | AC81: 0 | AD81: 0 | AE81: 0 | AF81: 0
A82: =+VLOOKUP(B82,studies!$A$2:$C$102,3) -> Peck & Teisberg (1993) | B82: 11 | C82: 1993 | D82: 1 | E82: 1989 | F82: 2030 | G82: 0.5 | H82: 11.105529 | I82: 0 | J82: 1 | K82: 0 | O82: 0 | P82: 1 | Q82: 0 | R82: 1 | S82: 0 | T82: 0 | U82: 0 | V82: 5 | W82: 3 | AA82: 0 | AC82: 0 | AD82: 0 | AE82: 0 | AF82: 1
A83: =+VLOOKUP(B83,studies!$A$2:$C$102,3) -> Peck & Teisberg (1993) | B83: 11 | C83: 1993 | D83: 1 | E83: 1989 | F83: 2030 | G83: 0.019230769 | H83: 24.210053 | I83: 0 | J83: 1 | K83: 0 | O83: 0 | P83: 1 | Q83: 0 | R83: 1 | S83: 0 | T83: 0 | U83: 0 | V83: 5 | W83: 3 | AA83: 0 | AC83: 0 | AD83: 0 | AE83: 0 | AF83: 1
A84: =+VLOOKUP(B84,studies!$A$2:$C$102,3) -> Peck & Teisberg (1993) | B84: 11 | C84: 1993 | D84: 1 | E84: 1989 | F84: 2030 | G84: 0.019230769 | H84: 24.543219 | I84: 0 | J84: 1 | K84: 0 | O84: 0 | P84: 1 | Q84: 0 | R84: 1 | S84: 0 | T84: 0 | U84: 0 | V84: 5 | W84: 3 | AA84: 0 | AC84: 0 | AD84: 0 | AE84: 0 | AF84: 1
A85: =+VLOOKUP(B85,studies!$A$2:$C$102,3) -> Peck & Teisberg (1993) | B85: 11 | C85: 1993 | D85: 1 | E85: 1989 | F85: 2030 | G85: 0.019230769 | H85: 25.431661 | I85: 0 | J85: 1 | K85: 0 | O85: 0 | P85: 1 | Q85: 0 | R85: 1 | S85: 0 | T85: 0 | U85: 0 | V85: 5 | W85: 3 | AA85: 0 | AC85: 0 | AD85: 0 | AE85: 0 | AF85: 1
A86: =+VLOOKUP(B86,studies!$A$2:$C$102,3) -> Peck & Teisberg (1993) | B86: 11 | C86: 1993 | D86: 1 | E86: 1989 | F86: 2030 | G86: 0.019230769 | H86: 24.210053 | I86: 0 | J86: 1 | K86: 0 | O86: 0 | P86: 1 | Q86: 0 | R86: 1 | S86: 0 | T86: 0 | U86: 0 | V86: 5 | W86: 3 | AA86: 0 | AC86: 0 | AD86: 0 | AE86: 0 | AF86: 1
A87: =+VLOOKUP(B87,studies!$A$2:$C$102,3) -> Peck & Teisberg (1993) | B87: 11 | C87: 1993 | D87: 1 | E87: 1989 | F87: 2030 | G87: 0.019230769 | H87: 24.543219 | I87: 0 | J87: 1 | K87: 0 | O87: 0 | P87: 1 | Q87: 0 | R87: 1 | S87: 0 | T87: 0 | U87: 0 | V87: 5 | W87: 3 | AA87: 0 | AC87: 0 | AD87: 0 | AE87: 0 | AF87: 1
...

Sheet Dataset1
A1: label | B1: idstudy | C1: pubyear | D1: reviewed | E1: dollaryear | F1: emissionyear | G1: tolweight | H1: scc | I1: sccmean | J1: sccbg | K1: sccmed | L1: stdev | M1: stdlow | N1: stdup | O1: iie | P1: mmi | Q1: dim | R1: sce | S1: fund | T1: dicerice | U1: page | V1: cdr | W1: prtp | X1: rra | Y1: growth | Z1: ies | AA1: eweight | AB1: climatesens | AC1: hope | AD1: nordhaus | AE1: tol | AF1: pigou
A2: =+VLOOKUP(B2,studies!$A$2:$C$102,3) -> Cline (1992) | B2: 4 | C2: 1992 | D2: 0 | E2: 1989 | F2: 1990 | G2: 1 | H2: 245.51022 | I2: 0 | J2: 1 | K2: 0 | L2: 111.7847 | M2: 114.06602 | N2: 114.06602 | O2: 1 | P2: 1 | Q2: 0 | R2: 1 | S2: 0 | T2: 0 | U2: 0 | V2: 1.5 | W2: 0 | X2: 1.5 | Y2: 1 | Z2: =1/X2 -> 0.66666667 | AA2: 0 | AC2: 0 | AD2: 0 | AE2: 0 | AF2: 0
A3: =+VLOOKUP(B3,studies!$A$2:$C$102,3) -> Fankhauser (1994) | B3: 14 | C3: 1994 | D3: 1 | E3: 1988 | F3: 2015 | G3: 1 | H3: 46.634123 | I3: 1 | J3: 0 | K3: 0 | L3: 32.256805 | M3: 15.987338 | N3: 29.247424 | O3: 1 | P3: 1 | Q3: 0 | R3: 1 | S3: 0 | T3: 0 | U3: 0 | V3: NA | W3: NA | X3: 1 | AA3: 0 | AB3: 6 | AC3: 0 | AD3: 0 | AE3: 0 | AF3: 0
A4: =+VLOOKUP(B4,studies!$A$2:$C$102,3) -> Schauer (1995) | B4: 17 | C4: 1995 | D4: 1 | E4: 1990 | F4: 1990 | G4: 0.5 | H4: 6.3273708 | I4: 0 | J4: 0 | K4: 1 | L4: 75.942805 | M4: 75.942805 | N4: 75.942805 | O4: 1 | P4: 1 | Q4: 0 | R4: 1 | S4: 0 | T4: 0 | U4: 0 | V4: 4.91 | W4: 2.3 | AA4: 0 | AC4: 0 | AD4: 0 | AE4: 0 | AF4: 0
A5: =+VLOOKUP(B5,studies!$A$2:$C$102,3) -> Schauer (1995) | B5: 17 | C5: 1995 | D5: 1 | E5: 1990 | F5: 1990 | G5: 0.5 | H5: 192.08218 | I5: 0 | J5: 0 | K5: 1 | L5: 537.62912 | M5: 537.62912 | N5: 537.62912 | O5: 1 | P5: 1 | Q5: 0 | R5: 1 | S5: 0 | T5: 0 | U5: 0 | V5: 4.91 | W5: 2.3 | AA5: 0 | AC5: 0 | AD5: 0 | AE5: 0 | AF5: 0
A6: =+VLOOKUP(B6,studies!$A$2:$C$102,3) -> Hope & Maul (1996) | B6: 21 | C6: 1996 | D6: 1 | E6: 1990 | F6: 1990 | G6: 0.1 | H6: 25.122856 | I6: 1 | J6: 0 | K6: 0 | M6: 7.3244479 | N6: 7.3244479 | O6: 1 | P6: 1 | Q6: 0 | R6: 0 | S6: 0 | T6: 0 | U6: 1 | V6: 4 | W6: 2 | AA6: 0 | AC6: 1 | AD6: 0 | AE6: 0 | AF6: 0
A7: =+VLOOKUP(B7,studies!$A$2:$C$102,3) -> Hope & Maul (1996) | B7: 21 | C7: 1996 | D7: 1 | E7: 1990 | F7: 1990 | G7: 1 | H7: 86.135507 | I7: 1 | J7: 0 | K7: 0 | M7: 43.946687 | N7: 450.45354 | O7: 1 | P7: 1 | Q7: 0 | R7: 0 | S7: 0 | T7: 0 | U7: 1 | V7: 4 | W7: 2 | AA7: 0 | AC7: 1 | AD7: 0 | AE7: 0 | AF7: 0
A8: =+VLOOKUP(B8,studies!$A$2:$C$102,3) -> Hope & Maul (1996) | B8: 21 | C8: 1996 | D8: 1 | E8: 1990 | F8: 1990 | G8: 0.1 | H8: 32.300815 | I8: 1 | J8: 0 | K8: 0 | M8: 9.1555598 | N8: 9.1555598 | O8: 1 | P8: 1 | Q8: 0 | R8: 0 | S8: 0 | T8: 0 | U8: 1 | V8: 4 | W8: 2 | AA8: 0 | AC8: 1 | AD8: 0 | AE8: 0 | AF8: 0
A9: =+VLOOKUP(B9,studies!$A$2:$C$102,3) -> Hope & Maul (1996) | B9: 21 | C9: 1996 | D9: 1 | E9: 1990 | F9: 1990 | G9: 0.1 | H9: 68.19061 | I9: 1 | J9: 0 | K9: 0 | M9: 20.142232 | N9: 23.804456 | O9: 1 | P9: 1 | Q9: 0 | R9: 0 | S9: 0 | T9: 0 | U9: 1 | V9: 4 | W9: 2 | AA9: 0 | AC9: 1 | AD9: 0 | AE9: 0 | AF9: 0
A10: =+VLOOKUP(B10,studies!$A$2:$C$102,3) -> Hope & Maul (1996) | B10: 21 | C10: 1996 | D10: 1 | E10: 1990 | F10: 1990 | G10: 0.6 | H10: 17.944897 | I10: 1 | J10: 0 | K10: 0 | M10: 5.4933359 | N10: 3.6622239 | O10: 1 | P10: 1 | Q10: 0 | R10: 1 | S10: 0 | T10: 0 | U10: 1 | V10: 4 | W10: 2 | AA10: 0 | AC10: 1 | AD10: 0 | AE10: 0 | AF10: 0
A11: =+VLOOKUP(B11,studies!$A$2:$C$102,3) -> Hope & Maul (1996) | B11: 21 | C11: 1996 | D11: 1 | E11: 1990 | F11: 1990 | G11: 0.1 | H11: 104.0804 | I11: 1 | J11: 0 | K11: 0 | M11: 31.128903 | N11: 29.297791 | O11: 1 | P11: 1 | Q11: 0 | R11: 0 | S11: 0 | T11: 0 | U11: 1 | V11: 4 | W11: 2 | AA11: 0 | AC11: 1 | AD11: 0 | AE11: 0 | AF11: 0
A12: =+VLOOKUP(B12,studies!$A$2:$C$102,3) -> Plambeck & Hope (1996) | B12: 23 | C12: 1996 | D12: 1 | E12: 1990 | F12: 1990 | G12: 0.125 | H12: 10.766938 | I12: 1 | J12: 0 | K12: 0 | M12: 3.6622239 | N12: 5.4933359 | O12: 1 | P12: 1 | Q12: 0 | R12: 1 | S12: 0 | T12: 0 | U12: 1 | V12: 5 | W12: 3 | AA12: 0 | AC12: 1 | AD12: 0 | AE12: 0 | AF12: 0
A13: =+VLOOKUP(B13,studies!$A$2:$C$102,3) -> Plambeck & Hope (1996) | B13: 23 | C13: 1996 | D13: 1 | E13: 1990 | F13: 1990 | G13: 0.0625 | H13: 17.944897 | I13: 1 | J13: 0 | K13: 0 | M13: 5.4933359 | N13: 12.817784 | O13: 1 | P13: 1 | Q13: 0 | R13: 1 | S13: 0 | T13: 0 | U13: 1 | V13: 5 | W13: 3 | AA13: 0 | AC13: 1 | AD13: 0 | AE13: 0 | AF13: 0
A14: =+VLOOKUP(B14,studies!$A$2:$C$102,3) -> Plambeck & Hope (1996) | B14: 23 | C14: 1996 | D14: 1 | E14: 1990 | F14: 1990 | G14: 0.125 | H14: 28.711836 | I14: 1 | J14: 0 | K14: 0 | M14: 9.1555598 | N14: 7.3244479 | O14: 1 | P14: 1 | Q14: 0 | R14: 1 | S14: 0 | T14: 0 | U14: 1 | V14: 5 | W14: 3 | AA14: 0 | AC14: 1 | AD14: 0 | AE14: 0 | AF14: 0
A15: =+VLOOKUP(B15,studies!$A$2:$C$102,3) -> Plambeck & Hope (1996) | B15: 23 | C15: 1996 | D15: 1 | E15: 1990 | F15: 1990 | G15: 0.125 | H15: 28.711836 | I15: 1 | J15: 0 | K15: 0 | M15: 3.6622239 | N15: 18.31112 | O15: 1 | P15: 1 | Q15: 0 | R15: 1 | S15: 0 | T15: 0 | U15: 1 | V15: 5 | W15: 3 | AA15: 0 | AC15: 1 | AD15: 0 | AE15: 0 | AF15: 0
A16: =+VLOOKUP(B16,studies!$A$2:$C$102,3) -> Plambeck & Hope (1996) | B16: 23 | C16: 1996 | D16: 1 | E16: 1990 | F16: 1990 | G16: 0.25 | H16: 75.368568 | I16: 1 | J16: 0 | K16: 0 | M16: 20.142232 | N16: 49.440023 | O16: 1 | P16: 1 | Q16: 0 | R16: 1 | S16: 0 | T16: 0 | U16: 1 | V16: 5 | W16: 3 | AA16: 0 | AC16: 1 | AD16: 0 | AE16: 0 | AF16: 0
A17: =+VLOOKUP(B17,studies!$A$2:$C$102,3) -> Plambeck & Hope (1996) | B17: 23 | C17: 1996 | D17: 1 | E17: 1990 | F17: 1990 | G17: 0.125 | H17: 165.09305 | I17: 1 | J17: 0 | K17: 0 | M17: 47.608911 | N17: 87.893374 | O17: 1 | P17: 1 | Q17: 0 | R17: 1 | S17: 0 | T17: 0 | U17: 1 | V17: 4 | W17: 2 | AA17: 0 | AC17: 1 | AD17: 0 | AE17: 0 | AF17: 0
... A19: =+VLOOKUP(B19,studies!$A$2:$C$102,3) -> Plambeck & Hope (1996) | B19: 23 | C19: 1996 | D19: 1 | E19: 1990 | F19: 1990 | G19: 0.0625 | H19: 114.84734 | I19: 1 | J19: 0 | K19: 0 | M19: 18.31112 | N19: 43.946687 | O19: 1 | P19: 1 | Q19: 0 | R19: 1 | S19: 0 | T19: 0 | U19: 1 | V19: 5 | W19: 3 | AA19: 0 | AC19: 1 | AD19: 0 | AE19: 0 | AF19: 0
A20: =+VLOOKUP(B20,studies!$A$2:$C$102,3) -> Cline (1997) | B20: 24 | C20: 1997 | D20: 0 | E20: 1995 | F20: 1995 | G20: 1 | H20: 231.72507 | I20: 0 | J20: 1 | K20: 0 | L20: 105.29957 | M20: 107.44854 | N20: 107.44854 | O20: 1 | P20: 1 | Q20: 0 | R20: 1 | S20: 0 | T20: 1 | U20: 0 | V20: NA | W20: NA | AA20: 0 | AC20: 0 | AD20: 0 | AE20: 0 | AF20: 1
A21: =+VLOOKUP(B21,studies!$A$2:$C$102,3) -> Nordhaus & Popp (1997) | B21: 25 | C21: 1997 | D21: 1 | E21: 1990 | F21: 2000 | G21: 0.9 | H21: 30.750526 | I21: 1 | J21: 0 | K21: 0 | L21: 2.063244 | M21: 18.62909 | N21: 35.668284 | O21: 0 | P21: 1 | Q21: 0 | R21: 1 | S21: 0 | T21: 1 | U21: 0 | V21: 5 | W21: 3 | X21: 1 | Y21: 2 | AA21: 0 | AC21: 0 | AD21: 1 | AE21: 0 | AF21: 1
A22: =+VLOOKUP(B22,studies!$A$2:$C$102,3) -> Roughgarden & Schneider (1999) | B22: 27 | C22: 1999 | D22: 1 | E22: 1990 | F22: 1995 | G22: 1 | H22: 70.359294 | I22: 0 | J22: 0 | K22: 1 | M22: 35.897599 | N22: 267.7631 | O22: 1 | P22: 1 | Q22: 0 | R22: 1 | S22: 0 | T22: 1 | U22: 0 | V22: 5 | W22: 3 | AA22: 0 | AC22: 0 | AD22: 0 | AE22: 0 | AF22: 1
A23: =+VLOOKUP(B23,studies!$A$2:$C$102,3) -> Tol (1999) | B23: 28 | C23: 1999 | D23: 1 | E23: 1995 | F23: 2000 | G23: 0.5 | H23: 158.59454 | I23: 0 | J23: 0 | K23: 1 | L23: 115.54745 | M23: 50.861222 | N23: 124.84118 | O23: 1 | P23: 1 | Q23: 1 | R23: 1 | S23: 1 | T23: 0 | U23: 0 | V23: 3 | W23: 1 | AA23: 1 | AC23: 0 | AD23: 0 | AE23: 1 | AF23: 0
A24: =+VLOOKUP(B24,studies!$A$2:$C$102,3) -> Tol (1999) | B24: 28 | C24: 1999 | D24: 1 | E24: 1995 | F24: 2000 | G24: 0.1 | H24: 917.58268 | I24: 0 | J24: 0 | K24: 1 | L24: 604.92488 | M24: 285.51641 | N24: 643.85683 | O24: 1 | P24: 1 | Q24: 1 | R24: 1 | S24: 1 | T24: 0 | U24: 0 | V24: 0 | W24: -2 | AA24: 1 | AC24: 0 | AD24: 0 | AE24: 1 | AF24: 0
A25: =+VLOOKUP(B25,studies!$A$2:$C$102,3) -> Tol (1999) | B25: 28 | C25: 1999 | D25: 1 | E25: 1995 | F25: 2000 | G25: 0.1 | H25: 475.78361 | I25: 0 | J25: 0 | K25: 1 | L25: 323.98598 | M25: 149.11586 | N25: 349.09293 | O25: 1 | P25: 1 | Q25: 1 | R25: 1 | S25: 1 | T25: 0 | U25: 0 | V25: 1 | W25: -1 | AA25: 1 | AC25: 0 | AD25: 0 | AE25: 1 | AF25: 0
A26: =+VLOOKUP(B26,studies!$A$2:$C$102,3) -> Tol (1999) | B26: 28 | C26: 1999 | D26: 1 | E26: 1995 | F26: 2000 | G26: 0.2 | H26: 65.703451 | I26: 0 | J26: 0 | K26: 1 | L26: 49.843998 | M26: 20.806864 | N26: 55.484969 | O26: 1 | P26: 1 | Q26: 1 | R26: 1 | S26: 1 | T26: 0 | U26: 0 | V26: 5 | W26: 3 | AA26: 1 | AC26: 0 | AD26: 0 | AE26: 1 | AF26: 0
A27: =+VLOOKUP(B27,studies!$A$2:$C$102,3) -> Tol (1999) | B27: 28 | C27: 1999 | D27: 1 | E27: 1995 | F27: 2000 | G27: 0.1 | H27: 13.593818 | I27: 0 | J27: 0 | K27: 1 | L27: 11.328181 | M27: 4.6237475 | N27: 12.715305 | O27: 1 | P27: 1 | Q27: 1 | R27: 1 | S27: 1 | T27: 0 | U27: 0 | V27: 10 | W27: 8 | AA27: 1 | AC27: 0 | AD27: 0 | AE27: 1 | AF27: 0
A28: =+VLOOKUP(B28,studies!$A$2:$C$102,3) -> Tol & Downing (2001) | B28: 30 | C28: 2001 | D28: 0 | E28: 1995 | F28: 1995 | G28: 1 | H28: 10.562966 | I28: 0 | J28: 0 | K28: 1 | L28: 8.4503728 | M28: 8.4503728 | N28: 8.4503728 | O28: 0 | P28: 1 | Q28: 1 | R28: 1 | S28: 1 | T28: 0 | U28: 0 | V28: 3 | W28: 1 | AA28: 0 | AC28: 0 | AD28: 0 | AE28: 1 | AF28: 0
A29: =+VLOOKUP(B29,studies!$A$2:$C$102,3) -> Clarkson & Deyes (2002) | B29: 31 | C29: 2002 | D29: 0 | E29: 2000 | F29: 2000 | G29: 1 | H29: 203.52045 | I29: 0 | J29: 1 | K29: 0 | M29: 51.662725 | N29: 103.83696 | O29: 0 | P29: 1 | Q29: 0 | R29: 1 | S29: 1 | T29: 0 | U29: 0 | V29: 3 | W29: 1 | AA29: 1 | AC29: 0 | AD29: 0 | AE29: 0 | AF29: 0
A30: =+VLOOKUP(B30,studies!$A$2:$C$102,3) -> Pearce (2003) | B30: 33 | C30: 2003 | D30: 1 | E30: 2000 | F30: 2000 | G30: 1 | H30: 51.799128 | I30: 0 | J30: 1 | K30: 0 | M30: 19.607965 | N30: 19.607965 | O30: 0 | P30: 1 | Q30: 0 | R30: 1 | S30: 0 | T30: 1 | U30: 0 | V30: 3 | W30: 1 | AA30: 1 | AC30: 0 | AD30: 0 | AE30: 0 | AF30: 0
A31: =+VLOOKUP(B31,studies!$A$2:$C$102,3) -> Mendelsohn (2004) | B31: 39 | C31: 2004 | D31: 0 | E31: 1990 | F31: 2000 | G31: 1 | H31: 3.9626966 | I31: 0 | J31: 1 | K31: 0 | L31: 0.66044944 | M31: 0.673928 | N31: 0.673928 | O31: 1 | P31: 0 | Q31: 0 | R31: 0 | S31: 0 | T31: 0 | U31: 0 | V31: 5 | W31: 3 | AA31: 0 | AC31: 0 | AD31: 0 | AE31: 0 | AF31: 0
A32: =+VLOOKUP(B32,studies!$A$2:$C$102,3) -> Hope (2005b) | B32: 42 | C32: 2005 | D32: 0 | E32: 2000 | F32: 2000 | G32: 0.16666667 | H32: 86.220485 | I32: 1 | J32: 0 | K32: 0 | M32: 33.759801 | N32: 82.864965 | O32: 0 | P32: 1 | Q32: 0 | R32: 1 | S32: 0 | T32: 0 | U32: 1 | W32: 3 | AA32: 1 | AC32: 1 | AD32: 0 | AE32: 0 | AF32: 0
A33: =+VLOOKUP(B33,studies!$A$2:$C$102,3) -> Hope (2005b) | B33: 42 | C33: 2005 | D33: 0 | E33: 2000 | F33: 2000 | G33: 0.16666667 | H33: 70.179464 | I33: 1 | J33: 0 | K33: 0 | M33: 27.621655 | N33: 70.588674 | O33: 0 | P33: 1 | Q33: 0 | R33: 1 | S33: 0 | T33: 0 | U33: 1 | W33: 3 | AA33: 1 | AC33: 1 | AD33: 0 | AE33: 0 | AF33: 0
A34: =+VLOOKUP(B34,studies!$A$2:$C$102,3) -> Hope (2005b) | B34: 42 | C34: 2005 | D34: 0 | E34: 2000 | F34: 2000 | G34: 0.16666667 | H34: 62.158954 | I34: 1 | J34: 0 | K34: 0 | M34: 23.529558 | N34: 62.40448 | O34: 0 | P34: 1 | Q34: 0 | R34: 1 | S34: 0 | T34: 0 | U34: 1 | W34: 3 | AA34: 0 | AC34: 1 | AD34: 0 | AE34: 0 | AF34: 0
A35: =+VLOOKUP(B35,studies!$A$2:$C$102,3) -> Hope (2005b) | B35: 42 | C35: 2005 | D35: 0 | E35: 2000 | F35: 2000 | G35: 0.16666667 | H35: 92.235867 | I35: 1 | J35: 0 | K35: 0 | M35: 36.828873 | N35: 73.657747 | O35: 0 | P35: 1 | Q35: 0 | R35: 1 | S35: 0 | T35: 0 | U35: 1 | W35: 3 | AA35: 1 | AC35: 1 | AD35: 0 | AE35: 0 | AF35: 0
A36: =+VLOOKUP(B36,studies!$A$2:$C$102,3) -> Hope (2005b) | B36: 42 | C36: 2005 | D36: 0 | E36: 2000 | F36: 2000 | G36: 0.16666667 | H36: 74.189719 | I36: 1 | J36: 0 | K36: 0 | M36: 28.644679 | N36: 68.542626 | O36: 0 | P36: 1 | Q36: 0 | R36: 1 | S36: 0 | T36: 0 | U36: 1 | W36: 3 | AA36: 1 | AC36: 1 | AD36: 0 | AE36: 0 | AF36: 0
A37: =+VLOOKUP(B37,studies!$A$2:$C$102,3) -> Hope (2005b) | B37: 42 | C37: 2005 | D37: 0 | E37: 2000 | F37: 2000 | G37: 0.16666667 | H37: 64.164082 | I37: 1 | J37: 0 | K37: 0 | M37: 24.552582 | N37: 59.335407 | O37: 0 | P37: 1 | Q37: 0 | R37: 1 | S37: 0 | T37: 0 | U37: 1 | W37: 3 | AA37: 0 | AC37: 1 | AD37: 0 | AE37: 0 | AF37: 0
A38: =+VLOOKUP(B38,studies!$A$2:$C$102,3) -> Hope (2005a) | B38: 43 | C38: 2005 | D38: 1 | E38: 2000 | F38: 2000 | G38: 1 | H38: 42.107679 | I38: 1 | J38: 0 | K38: 0 | M38: 11.253267 | N38: 27.621655 | O38: 0 | P38: 1 | Q38: 0 | R38: 1 | S38: 0 | T38: 0 | U38: 1 | W38: 3 | AA38: 0 | AC38: 1 | AD38: 0 | AE38: 0 | AF38: 0
A39: =+VLOOKUP(B39,studies!$A$2:$C$102,3) -> Hope (2006) | B39: 46 | C39: 2006 | D39: 1 | E39: 2000 | F39: 2000 | G39: 1 | H39: 38.097424 | I39: 1 | J39: 0 | K39: 0 | M39: 15.345364 | N39: 32.736776 | O39: 0 | P39: 1 | Q39: 0 | R39: 1 | S39: 0 | T39: 0 | U39: 1 | W39: 3 | AA39: 0 | AC39: 1 | AD39: 0 | AE39: 0 | AF39: 0
A40: =+VLOOKUP(B40,studies!$A$2:$C$102,3) -> Wahba & Hope (2006) | B40: 48 | C40: 2006 | D40: 1 | E40: 2000 | F40: 2000 | G40: 0.5 | H40: 38.097424 | I40: 1 | J40: 0 | K40: 0 | M40: 14.32234 | N40: 30.690728 | O40: 0 | P40: 1 | Q40: 0 | R40: 1 | S40: 0 | T40: 0 | U40: 1 | W40: 3 | X40: 1 | AA40: 0 | AC40: 1 | AD40: 0 | AE40: 0 | AF40: 0
A41: =+VLOOKUP(B41,studies!$A$2:$C$102,3) -> Wahba & Hope (2006) | B41: 48 | C41: 2006 | D41: 1 | E41: 2000 | F41: 2000 | G41: 0.5 | H41: 28.071786 | I41: 1 | J41: 0 | K41: 0 | M41: 11.253267 | N41: 27.621655 | O41: 0 | P41: 1 | Q41: 0 | R41: 1 | S41: 0 | T41: 0 | U41: 1 | W41: 3 | X41: 1 | AA41: 0 | AC41: 1 | AD41: 0 | AE41: 0 | AF41: 0
...

Sheet Dataset2
A1: label | B1: idstudy | C1: pubyear | D1: reviewed | E1: dollaryear | F1: emissionyear | G1: tolweight | H1: scc | I1: sccmean | J1: sccbg | K1: sccmed | L1: stdev | M1: stdlow | N1: stdup | O1: iie | P1: mmi | Q1: dim | R1: sce | S1: fund | T1: dicerice | U1: page | V1: cdr | W1: prtp | X1: rra | Y1: growth | Z1: ies | AA1: eweight | AB1: climatesens | AC1: hope | AD1: nordhaus | AE1: tol | AF1: pigou
A2: =+VLOOKUP(B2,studies!$A$2:$C$102,3) -> Nordhaus (1982) | B2: 1 | C2: 1982 | D2: 1 | E2: 1980 | F2: 1980 | H2: =+IF(VLOOKUP($A2,'Dataset2 ad'!$D$3:$L$855,4,FALSE)="","",VLOOKUP($A2,'Dataset2 ad'!$D$3:$L$855,4,FALSE)) -> 1134.285 | I2: 0 | J2: 1 | K2: 0 | M2: =+IF(VLOOKUP($A2,'Dataset2 ad'!$D$3:$L$855,8,FALSE)="","",VLOOKUP($A2,'Dataset2 ad'!$D$3:$L$855,8,FALSE)) -> 887.80844 | N2: =+IF(VLOOKUP($A2,'Dataset2 ad'!$D$3:$L$855,9,FALSE)="","",VLOOKUP($A2,'Dataset2 ad'!$D$3:$L$855,9,FALSE)) -> 999.09259 | O2: 1 | P2: 0 | Q2: 0 | R2: 0 | S2: 0 | T2: 0 | U2: 0 | W2: 1 | Y2: =+AVERAGE(Dataset0!Y2:Y3) -> 2.5 | AA2: 0 | AC2: 0 | AD2: 1 | AE2: 0 | AF2: 0
A3: =+VLOOKUP(B3,studies!$A$2:$C$102,3) -> Nordhaus (1991) | B3: 3 | C3: 1991 | D3: 1 | E3: 1989 | F3: 1990 | H3: =+IF(VLOOKUP($A3,'Dataset2 ad'!$D$3:$L$855,4,FALSE)="","",VLOOKUP($A3,'Dataset2 ad'!$D$3:$L$855,4,FALSE)) -> 101.67175 | I3: 0 | J3: 1 | K3: 0 | M3: =+IF(VLOOKUP($A3,'Dataset2 ad'!$D$3:$L$855,8,FALSE)="","",VLOOKUP($A3,'Dataset2 ad'!$D$3:$L$855,8,FALSE)) -> 47.10354 | N3: =+IF(VLOOKUP($A3,'Dataset2 ad'!$D$3:$L$855,9,FALSE)="","",VLOOKUP($A3,'Dataset2 ad'!$D$3:$L$855,9,FALSE)) -> 321.44486 | O3: 1 | P3: 0 | Q3: 0 | R3: 0 | S3: 0 | T3: 1 | U3: 0 | V3: =+AVERAGE(Dataset0!V5:V13) -> 3.6666667 | W3: =+AVERAGE(Dataset0!W5:W13) -> 1.6666667 | X3: =+AVERAGE(Dataset0!X5:X13) -> 1 | Y3: =+AVERAGE(Dataset0!Y5:Y13) -> 2 | Z3: =1/X3 -> 1 | AA3: 0 | AC3: 0 | AD3: 1 | AE3: 0 | AF3: 0
A4: =+VLOOKUP(B4,studies!$A$2:$C$102,3) -> Haraden (1993) | B4: 8 | C4: 1993 | D4: 1 | E4: 1989 | F4: 1989 | H4: =+IF(VLOOKUP($A4,'Dataset2 ad'!$D$3:$L$855,4,FALSE)="","",VLOOKUP($A4,'Dataset2 ad'!$D$3:$L$855,4,FALSE)) -> 11.623804 | I4: 0 | J4: 1 | K4: 0 | M4: =+IF(VLOOKUP($A4,'Dataset2 ad'!$D$3:$L$855,8,FALSE)="","",VLOOKUP($A4,'Dataset2 ad'!$D$3:$L$855,8,FALSE)) -> 2.0239366 | N4: =+IF(VLOOKUP($A4,'Dataset2 ad'!$D$3:$L$855,9,FALSE)="","",VLOOKUP($A4,'Dataset2 ad'!$D$3:$L$855,9,FALSE)) -> 10.388347 | O4: 0 | P4: 0 | Q4: 0 | R4: 0 | S4: 0 | T4: 0 | U4: 0 | V4: 4 | W4: 2 | X4: 1.25 | Y4: =+AVERAGE(Dataset0!Y18:Y20) -> 2.6333333 | Z4: =1/X4 -> 0.8 | AA4: 0 | AC4: 0 | AD4: 0 | AE4: 0 | AF4: 0
A5: =+VLOOKUP(B5,studies!$A$2:$C$102,3) -> Parry (1993) | B5: 10 | C5: 1993 | D5: 1 | E5: 1991 | F5: 1990 | H5: =+IF(VLOOKUP($A5,'Dataset2 ad'!$D$3:$L$855,4,FALSE)="","",VLOOKUP($A5,'Dataset2 ad'!$D$3:$L$855,4,FALSE)) -> 1.5406384 | I5: 0 | J5: 1 | K5: 0 | M5: =+IF(VLOOKUP($A5,'Dataset2 ad'!$D$3:$L$855,8,FALSE)="","",VLOOKUP($A5,'Dataset2 ad'!$D$3:$L$855,8,FALSE)) -> 0.75414738 | N5: =+IF(VLOOKUP($A5,'Dataset2 ad'!$D$3:$L$855,9,FALSE)="","",VLOOKUP($A5,'Dataset2 ad'!$D$3:$L$855,9,FALSE)) -> 892.40989 | O5: 0 | P5: 1 | Q5: 0 | R5: 0 | S5: 0 | T5: 1 | U5: 0 | W5: 0 | AA5: 0 | AC5: 0 | AD5: 0 | AE5: 0 | AF5: 0
A6: =+VLOOKUP(B6,studies!$A$2:$C$102,3) -> Peck & Teisberg (1993) | B6: 11 | C6: 1993 | D6: 1 | E6: 1989 | F6: 2030 | H6: =+IF(VLOOKUP($A6,'Dataset2 ad'!$D$3:$L$855,4,FALSE)="","",VLOOKUP($A6,'Dataset2 ad'!$D$3:$L$855,4,FALSE)) -> 24.543219 | I6: 0 | J6: 1 | K6: 0 | M6: =+IF(VLOOKUP($A6,'Dataset2 ad'!$D$3:$L$855,8,FALSE)="","",VLOOKUP($A6,'Dataset2 ad'!$D$3:$L$855,8,FALSE)) -> 8.6407814 | N6: =+IF(VLOOKUP($A6,'Dataset2 ad'!$D$3:$L$855,9,FALSE)="","",VLOOKUP($A6,'Dataset2 ad'!$D$3:$L$855,9,FALSE)) -> 15.695059 | O6: 0 | P6: 1 | Q6: 0 | R6: 1 | S6: 0 | T6: 0 | U6: 0 | V6: 5 | W6: 3 | AA6: 0 | AC6: 0 | AD6: 0 | AE6: 0 | AF6: 1
A7: =+VLOOKUP(B7,studies!$A$2:$C$102,3) -> Reilly & Richards (1993) | B7: 12 | C7: 1993 | D7: 1 | E7: 1990 | F7: 1990 | H7: =+IF(VLOOKUP($A7,'Dataset2 ad'!$D$3:$L$855,4,FALSE)="","",VLOOKUP($A7,'Dataset2 ad'!$D$3:$L$855,4,FALSE)) -> 71.719773 | I7: 0 | J7: 1 | K7: 0 | M7: =+IF(VLOOKUP($A7,'Dataset2 ad'!$D$3:$L$855,8,FALSE)="","",VLOOKUP($A7,'Dataset2 ad'!$D$3:$L$855,8,FALSE)) -> 18.060868 | N7: =+IF(VLOOKUP($A7,'Dataset2 ad'!$D$3:$L$855,9,FALSE)="","",VLOOKUP($A7,'Dataset2 ad'!$D$3:$L$855,9,FALSE)) -> 52.705506 | O7: 0 | P7: 1 | Q7: 0 | R7: 0 | S7: 0 | T7: 0 | U7: 0 | V7: =+AVERAGE(Dataset0!V109:V116) -> 5 | W7: =+AVERAGE(Dataset0!W109:W116) -> 3 | AA7: 0 | AC7: 0 | AD7: 0 | AE7: 0 | AF7: 0
A8: =+VLOOKUP(B8,studies!$A$2:$C$102,3) -> Azar (1994) | B8: 13 | C8: 1994 | D8: 1 | E8: 1990 | F8: 1990 | H8: =+IF(VLOOKUP($A8,'Dataset2 ad'!$D$3:$L$855,4,FALSE)="","",VLOOKUP($A8,'Dataset2 ad'!$D$3:$L$855,4,FALSE)) -> 717.79589 | I8: 0 | J8: 1 | K8: 0 | M8: =+IF(VLOOKUP($A8,'Dataset2 ad'!$D$3:$L$855,8,FALSE)="","",VLOOKUP($A8,'Dataset2 ad'!$D$3:$L$855,8,FALSE)) -> 247.20012 | N8: =+IF(VLOOKUP($A8,'Dataset2 ad'!$D$3:$L$855,9,FALSE)="","",VLOOKUP($A8,'Dataset2 ad'!$D$3:$L$855,9,FALSE)) -> 494.40023 | O8: 0 | P8: 0 | Q8: 0 | R8: 0 | S8: 0 | T8: 0 | U8: 0 | W8: 0 | AA8: 0 | AC8: 0 | AD8: 0 | AE8: 0 | AF8: 0
A9: =+VLOOKUP(B9,studies!$A$2:$C$102,3) -> Schauer (1995) | B9: 17 | C9: 1995 | D9: 1 | E9: 1990 | F9: 1990 | H9: =+IF(VLOOKUP($A9,'Dataset2 ad'!$D$3:$L$855,4,FALSE)="","",VLOOKUP($A9,'Dataset2 ad'!$D$3:$L$855,4,FALSE)) -> 99.204776 | I9: 0 | J9: 0 | K9: 1 | M9: =+IF(VLOOKUP($A9,'Dataset2 ad'!$D$3:$L$855,8,FALSE)="","",VLOOKUP($A9,'Dataset2 ad'!$D$3:$L$855,8,FALSE)) -> 93.705105 | N9: =+IF(VLOOKUP($A9,'Dataset2 ad'!$D$3:$L$855,9,FALSE)="","",VLOOKUP($A9,'Dataset2 ad'!$D$3:$L$855,9,FALSE)) -> 105.85465 | O9: 1 | P9: 1 | Q9: 0 | R9: 1 | S9: 0 | T9: 0 | U9: 0 | V9: 4.91 | W9: 2.3 | AA9: 0 | AC9: 0 | AD9: 0 | AE9: 0 | AF9: 0
A10: =+VLOOKUP(B10,studies!$A$2:$C$102,3) -> Azar & Sterner (1996) | B10: 18 | C10: 1996 | D10: 1 | E10: 1990 | F10: 1990 | H10: =+IF(VLOOKUP($A10,'Dataset2 ad'!$D$3:$L$855,4,FALSE)="","",VLOOKUP($A10,'Dataset2 ad'!$D$3:$L$855,4,FALSE)) -> 323.00815 | I10: 0 | J10: 1 | K10: 0 | M10: =+IF(VLOOKUP($A10,'Dataset2 ad'!$D$3:$L$855,8,FALSE)="","",VLOOKUP($A10,'Dataset2 ad'!$D$3:$L$855,8,FALSE)) -> 140.99562 | N10: =+IF(VLOOKUP($A10,'Dataset2 ad'!$D$3:$L$855,9,FALSE)="","",VLOOKUP($A10,'Dataset2 ad'!$D$3:$L$855,9,FALSE)) -> 668.35587 | O10: 0 | P10: 1 | Q10: 0 | R10: 1 | S10: 0 | T10: 0 | U10: 0 | V10: =+AVERAGE(Dataset0!V125:V140) -> 3.025 | W10: =+AVERAGE(Dataset0!W125:W140) -> 1.025 | AA10: 0 | AC10: 0 | AD10: 0 | AE10: 0 | AF10: 0
A11: =+VLOOKUP(B11,studies!$A$2:$C$102,3) -> Downing et al. (1996) | B11: 19 | C11: 1996 | D11: 0 | E11: 1990 | F11: 1995 | H11: =+IF(VLOOKUP($A11,'Dataset2 ad'!$D$3:$L$855,4,FALSE)="","",VLOOKUP($A11,'Dataset2 ad'!$D$3:$L$855,4,FALSE)) -> 110.47179 | I11: 0 | J11: 1 | K11: 0 | M11: =+IF(VLOOKUP($A11,'Dataset2 ad'!$D$3:$L$855,8,FALSE)="","",VLOOKUP($A11,'Dataset2 ad'!$D$3:$L$855,8,FALSE)) -> 61.493937 | N11: =+IF(VLOOKUP($A11,'Dataset2 ad'!$D$3:$L$855,9,FALSE)="","",VLOOKUP($A11,'Dataset2 ad'!$D$3:$L$855,9,FALSE)) -> 68.573883 | O11: 1 | P11: 0 | Q11: 1 | R11: 1 | S11: 0 | T11: 0 | U11: 0 | V11: 0 | W11: -2 | AA11: 0 | AC11: 0 | AD11: 0 | AE11: 0 | AF11: 0
A12: =+VLOOKUP(B12,studies!$A$2:$C$102,3) -> Hope & Maul (1996) | B12: 21 | C12: 1996 | D12: 1 | E12: 1990 | F12: 1990 | H12: =+IF(VLOOKUP($A12,'Dataset2 ad'!$D$3:$L$855,4,FALSE)="","",VLOOKUP($A12,'Dataset2 ad'!$D$3:$L$855,4,FALSE)) -> 50.245712 | I12: 1 | J12: 0 | K12: 0 | M12: =+IF(VLOOKUP($A12,'Dataset2 ad'!$D$3:$L$855,8,FALSE)="","",VLOOKUP($A12,'Dataset2 ad'!$D$3:$L$855,8,FALSE)) -> 15.564452 | N12: =+IF(VLOOKUP($A12,'Dataset2 ad'!$D$3:$L$855,9,FALSE)="","",VLOOKUP($A12,'Dataset2 ad'!$D$3:$L$855,9,FALSE)) -> 25.17779 | O12: 1 | P12: 1 | Q12: 0 | R12: 0 | S12: 0 | T12: 0 | U12: 1 | V12: 4 | W12: 2 | AA12: 0 | AC12: 1 | AD12: 0 | AE12: 0 | AF12: 0
A13: =+VLOOKUP(B13,studies!$A$2:$C$102,3) -> Plambeck & Hope (1996) | B13: 23 | C13: 1996 | D13: 1 | E13: 1990 | F13: 1990 | H13: =+IF(VLOOKUP($A13,'Dataset2 ad'!$D$3:$L$855,4,FALSE)="","",VLOOKUP($A13,'Dataset2 ad'!$D$3:$L$855,4,FALSE)) -> 52.040202 | I13: 1 | J13: 0 | K13: 0 | M13: =+IF(VLOOKUP($A13,'Dataset2 ad'!$D$3:$L$855,8,FALSE)="","",VLOOKUP($A13,'Dataset2 ad'!$D$3:$L$855,8,FALSE)) -> 19.776009 | N13: =+IF(VLOOKUP($A13,'Dataset2 ad'!$D$3:$L$855,9,FALSE)="","",VLOOKUP($A13,'Dataset2 ad'!$D$3:$L$855,9,FALSE)) -> 526.6278 | O13: 1 | P13: 1 | Q13: 0 | R13: 1 | S13: 0 | T13: 0 | U13: 1 | V13: =+AVERAGE(Dataset0!V151:V158) -> 4.5 | W13: =+AVERAGE(Dataset0!W151:W158) -> 2.5 | AA13: 0 | AC13: 1 | AD13: 0 | AE13: 0 | AF13: 0
A14: =+VLOOKUP(B14,studies!$A$2:$C$102,3) -> Nordhaus & Popp (1997) | B14: 25 | C14: 1997 | D14: 1 | E14: 1990 | F14: 2000 | H14: =+IF(VLOOKUP($A14,'Dataset2 ad'!$D$3:$L$855,4,FALSE)="","",VLOOKUP($A14,'Dataset2 ad'!$D$3:$L$855,4,FALSE)) -> 21.879918 | I14: 1 | J14: 0 | K14: 0 | M14: =+IF(VLOOKUP($A14,'Dataset2 ad'!$D$3:$L$855,8,FALSE)="","",VLOOKUP($A14,'Dataset2 ad'!$D$3:$L$855,8,FALSE)) -> 10.572391 | N14: =+IF(VLOOKUP($A14,'Dataset2 ad'!$D$3:$L$855,9,FALSE)="","",VLOOKUP($A14,'Dataset2 ad'!$D$3:$L$855,9,FALSE)) -> 11.732779 | O14: 0 | P14: 1 | Q14: 0 | R14: 1 | S14: 0 | T14: 1 | U14: 0 | V14: 5 | W14: 3 | X14: 1 | Y14: 2 | Z14: =1/X14 -> 1 | AA14: 0 | AC14: 0 | AD14: 1 | AE14: 0 | AF14: 1
A15: =+VLOOKUP(B15,studies!$A$2:$C$102,3) -> Eyre et al. (1999) | B15: 26 | C15: 1999 | D15: 0 | E15: 1995 | F15: 1995 | H15: =+IF(VLOOKUP($A15,'Dataset2 ad'!$D$3:$L$855,4,FALSE)="","",VLOOKUP($A15,'Dataset2 ad'!$D$3:$L$855,4,FALSE)) -> 308.96675 | I15: 0 | J15: 1 | K15: 0 | M15: =+IF(VLOOKUP($A15,'Dataset2 ad'!$D$3:$L$855,8,FALSE)="","",VLOOKUP($A15,'Dataset2 ad'!$D$3:$L$855,8,FALSE)) -> 62.515513 | N15: =+IF(VLOOKUP($A15,'Dataset2 ad'!$D$3:$L$855,9,FALSE)="","",VLOOKUP($A15,'Dataset2 ad'!$D$3:$L$855,9,FALSE)) -> 69.38683 | O15: 0 | P15: 1 | Q15: 1 | R15: 1 | S15: 1 | T15: 0 | U15: 0 | V15: =+AVERAGE(Dataset0!V162:V165) -> 2 | W15: =+AVERAGE(Dataset0!W162:W165) -> 0 | AA15: 1 | AC15: 0 | AD15: 0 | AE15: 0 | AF15: 0
A16: =+VLOOKUP(B16,studies!$A$2:$C$102,3) -> Tol (1999) | B16: 28 | C16: 1999 | D16: 1 | E16: 1995 | F16: 2000 | H16: =+IF(VLOOKUP($A16,'Dataset2 ad'!$D$3:$L$855,4,FALSE)="","",VLOOKUP($A16,'Dataset2 ad'!$D$3:$L$855,4,FALSE)) -> 143.8679 | I16: 0 | J16: 0 | K16: 1 | M16: =+IF(VLOOKUP($A16,'Dataset2 ad'!$D$3:$L$855,8,FALSE)="","",VLOOKUP($A16,'Dataset2 ad'!$D$3:$L$855,8,FALSE)) -> 66.46637 | N16: =+IF(VLOOKUP($A16,'Dataset2 ad'!$D$3:$L$855,9,FALSE)="","",VLOOKUP($A16,'Dataset2 ad'!$D$3:$L$855,9,FALSE)) -> 336.49322 | O16: 1 | P16: 1 | Q16: 1 | R16: 1 | S16: 1 | T16: 0 | U16: 0 | V16: =+AVERAGE(Dataset0!V167:V196) -> 3.8 | W16: =+AVERAGE(Dataset0!W167:W196) -> 1.8 | AA16: 1 | AC16: 0 | AD16: 0 | AE16: 1 | AF16: 0
A17: =+VLOOKUP(B17,studies!$A$2:$C$102,3) -> Tol & Downing (2001) | B17: 30 | C17: 2001 | D17: 0 | E17: 1995 | F17: 1995 | H17: =+IF(VLOOKUP($A17,'Dataset2 ad'!$D$3:$L$855,4,FALSE)="","",VLOOKUP($A17,'Dataset2 ad'!$D$3:$L$855,4,FALSE)) -> 39.743159 | I17: 0 | J17: 1 | K17: 0 | M17: =+IF(VLOOKUP($A17,'Dataset2 ad'!$D$3:$L$855,8,FALSE)="","",VLOOKUP($A17,'Dataset2 ad'!$D$3:$L$855,8,FALSE)) -> 15.460464 | N17: =+IF(VLOOKUP($A17,'Dataset2 ad'!$D$3:$L$855,9,FALSE)="","",VLOOKUP($A17,'Dataset2 ad'!$D$3:$L$855,9,FALSE)) -> 37.448678 | O17: 0 | P17: 1 | Q17: 1 | R17: 1 | S17: 1 | T17: 0 | U17: 0 | V17: 3 | W17: 1 | AA17: 1 | AC17: 0 | AD17: 0 | AE17: 1 | AF17: 0
A18: =+VLOOKUP(B18,studies!$A$2:$C$102,3) -> Newell & Pizer (2003) | B18: 32 | C18: 2003 | D18: 1 | E18: 1989 | F18: 2000 | H18: =+IF(VLOOKUP($A18,'Dataset2 ad'!$D$3:$L$855,4,FALSE)="","",VLOOKUP($A18,'Dataset2 ad'!$D$3:$L$855,4,FALSE)) -> 18.155201 | I18: 0 | J18: 1 | K18: 0 | M18: =+IF(VLOOKUP($A18,'Dataset2 ad'!$D$3:$L$855,8,FALSE)="","",VLOOKUP($A18,'Dataset2 ad'!$D$3:$L$855,8,FALSE)) -> 6.984081 | N18: =+IF(VLOOKUP($A18,'Dataset2 ad'!$D$3:$L$855,9,FALSE)="","",VLOOKUP($A18,'Dataset2 ad'!$D$3:$L$855,9,FALSE)) -> 32.834842 | O18: 0 | P18: 1 | Q18: 0 | R18: 1 | S18: 0 | T18: 0 | U18: 0 | V18: =+AVERAGE(Dataset0!V203:V211) -> 4.3333333 | W18: =+AVERAGE(Dataset0!W203:W211) -> 2.3333333 | AA18: 0 | AC18: 0 | AD18: 0 | AE18: 0 | AF18: 0
A19: =+VLOOKUP(B19,studies!$A$2:$C$102,3) -> Cline (2004) | B19: 35 | C19: 2004 | D19: 0 | E19: 1990 | F19: 1995 | H19: =+IF(VLOOKUP($A19,'Dataset2 ad'!$D$3:$L$855,4,FALSE)="","",VLOOKUP($A19,'Dataset2 ad'!$D$3:$L$855,4,FALSE)) -> 110.52577 | I19: 0 | J19: 1 | K19: 0 | M19: =+IF(VLOOKUP($A19,'Dataset2 ad'!$D$3:$L$855,8,FALSE)="","",VLOOKUP($A19,'Dataset2 ad'!$D$3:$L$855,8,FALSE)) -> 35.338172 | N19: =+IF(VLOOKUP($A19,'Dataset2 ad'!$D$3:$L$855,9,FALSE)="","",VLOOKUP($A19,'Dataset2 ad'!$D$3:$L$855,9,FALSE)) -> 340.79908 | O19: 0 | P19: 1 | Q19: 0 | R19: 1 | S19: 0 | T19: 1 | U19: 0 | W19: =+AVERAGE(Dataset0!W214:W222) -> 1.3333333 | AA19: 0 | AC19: 0 | AD19: 0 | AE19: 0 | AF19: 0
A20: =+VLOOKUP(B20,studies!$A$2:$C$102,3) -> Hohmeyer (2004) | B20: 36 | C20: 2004 | D20: 0 | E20: 1990 | F20: 1990 | H20: =+IF(VLOOKUP($A20,'Dataset2 ad'!$D$3:$L$855,4,FALSE)="","",VLOOKUP($A20,'Dataset2 ad'!$D$3:$L$855,4,FALSE)) -> 1116.1726 | I20: 0 | J20: 1 | K20: 0 | M20: =+IF(VLOOKUP($A20,'Dataset2 ad'!$D$3:$L$855,8,FALSE)="","",VLOOKUP($A20,'Dataset2 ad'!$D$3:$L$855,8,FALSE)) -> 1016.3488 | N20: =+IF(VLOOKUP($A20,'Dataset2 ad'!$D$3:$L$855,9,FALSE)="","",VLOOKUP($A20,'Dataset2 ad'!$D$3:$L$855,9,FALSE)) -> 1147.3348 | O20: 0 | P20: 1 | Q20: 0 | R20: 1 | S20: 0 | T20: 0 | U20: 0 | W20: =+AVERAGE(Dataset0!W223:W224) -> 0.5 | AA20: 1 | AC20: 0 | AD20: 0 | AE20: 0 | AF20: 0
