Workbook

Sheet data
A1: author | B1: pub_year | C1: idstudy | D1: dep_var | E1: exp_var | F1: tuition | G1: tuition_se | H1: no_exp_var | I1: no_obs | J1: no_df | K1: est_per_study | L1: startyear | M1: endyear | N1: midyear | O1: timespan | P1: ln_timespan | Q1: cit_google | R1: cit_repec | S1: model | T1: endogeneity | U1: unemployment | V1: income | W1: shortrun | X1: linear | Y1: doublelog | Z1: semilog | AA1: boxcox | AB1: country | AC1: idcountry | AD1: usa | AE1: published | AF1: ln_pub_year | AG1: ln_google | AH1: tstat | AI1: pcc | AJ1: pcc_se | AK1: pcc_precsq | AL1: pcc_prec | AM1: tseries | AN1: panel | AO1: cross | AP1: instrument | AQ1: ols | AR1: fe | AS1: male | AT1: female | AU1: private | AV1: public | AW1: invperst | AX1: invperstsq
A2: Agarwal & Winkler (1985) | B2: 1985 | C2: 1 | D2: enrollment | E2: tuition | F2: 0.123 | G2: 0.352 | H2: 3 | I2: 17 | J2: =+I2-H2 -> 14 | K2: 30 | L2: 1954 | M2: 1973 | N2: =+L2+(M2-L2)/2 -> 1963.5 | O2: =+M2-L2+1 -> 20 | P2: =+LN(O1:O2) -> 2.9957323 | Q2: 105 | R2: 0 | S2: OLS | T2: =IF(S2="OLS",0,IF(S2="FE",0,IF(S2="Probit model",0,IF(S2="3SLS",1,IF(S2="Logit",0,IF(S2="2SLS",1,IF(S2="SUR method",1,IF(S2="Modified LS",0,IF(S2="Zenner estimates",1,IF(S2="MLE",0,IF(S2="GLS",0,0))))))))))) -> 0 | U2: 0 | V2: 0 | W2: 0 | X2: 0 | Y2: 1 | Z2: 0 | AA2: 0 | AB2: USA | AC2: =IF(AB2="USA",1,IF(AB2="UK",2,IF(AB2="Canada",3,IF(AB2="Germany",4,IF(AB2="Netherlands",5,IF(AB2="India",20,IF(AB2="Indonesia",7,IF(AB2="Korea",8,IF(AB2="Philippines",9,IF(AB2="Taiwan",10,IF(AB2="Greece",11,IF(AB2="Iran",12,IF(AB2="Israel",13,IF(AB2="Kuwait",14,IF(AB2="Lebanon",15,IF(AB2="Saudi Arabia",16,IF(AB2="Turkey",17,IF(AB2="Ethiopia",18,IF(AB2="Kenya",19,IF(AB2="Nigeria",20,IF(AB2="Multinational",6,""))))))))))))))))))))) -> 1 | AD2: =IF(AB2="USA",1,0) -> 1 | AE2: 1 | AF2: 7.593374 | AG2: 4.663439 | AH2: =+F2/G2 -> 0.34943182 | AI2: =AH2/SQRT(AH2^2+J2) -> 0.092984972 | AJ2: =+AI2/AH2 -> 0.26610334 | AK2: =1/AJ2^2 -> 14.122103 | AL2: =1/AJ2 -> 3.7579386 | AM2: 1 | AN2: 0 | AO2: 0 | AP2: =1/SQRT(J2) -> 0.26726124 | AQ2: 1 | AR2: 0 | AS2: 0 | AT2: 0 | AU2: 0 | AV2: 0 | AW2: =1/K2 -> 0.033333333 | AX2: =1/(K2*K2) -> 0.0011111111
A3: Agarwal & Winkler (1985) | B3: 1985 | C3: =+IF(A3=A2,C2,C2+1) -> 1 | D3: enrollment | E3: tuition | F3: -0.895 | G3: 0.974 | H3: 3 | I3: 17 | J3: =+I3-H3 -> 14 | K3: 30 | L3: 1954 | M3: 1973 | N3: =+L3+(M3-L3)/2 -> 1963.5 | O3: =+M3-L3+1 -> 20 | P3: =+LN(O2:O3) -> 2.9957323 | Q3: 105 | R3: 0 | S3: OLS | T3: =IF(S3="OLS",0,IF(S3="FE",0,IF(S3="Probit model",0,IF(S3="3SLS",1,IF(S3="Logit",0,IF(S3="2SLS",1,IF(S3="SUR method",1,IF(S3="Modified LS",0,IF(S3="Zenner estimates",1,IF(S3="MLE",0,IF(S3="GLS",0,0))))))))))) -> 0 | U3: 0 | V3: 0 | W3: 0 | X3: 0 | Y3: 1 | Z3: 0 | AA3: 0 | AB3: USA | AC3: =IF(AB3="USA",1,IF(AB3="UK",2,IF(AB3="Canada",3,IF(AB3="Germany",4,IF(AB3="Netherlands",5,IF(AB3="India",20,IF(AB3="Indonesia",7,IF(AB3="Korea",8,IF(AB3="Philippines",9,IF(AB3="Taiwan",10,IF(AB3="Greece",11,IF(AB3="Iran",12,IF(AB3="Israel",13,IF(AB3="Kuwait",14,IF(AB3="Lebanon",15,IF(AB3="Saudi Arabia",16,IF(AB3="Turkey",17,IF(AB3="Ethiopia",18,IF(AB3="Kenya",19,IF(AB3="Nigeria",20,IF(AB3="Multinational",6,""))))))))))))))))))))) -> 1 | AD3: =IF(AB3="USA",1,0) -> 1 | AE3: 1 | AF3: 7.593374 | AG3: 4.663439 | AH3: =+F3/G3 -> -0.91889117 | AI3: =AH3/SQRT(AH3^2+J3) -> -0.23849722 | AJ3: =+AI3/AH3 -> 0.25954893 | AK3: =1/AJ3^2 -> 14.844361 | AL3: =1/AJ3 -> 3.852838 | AM3: 1 | AN3: 0 | AO3: 0 | AP3: =1/SQRT(J3) -> 0.26726124 | AQ3: 1 | AR3: 0 | AS3: 0 | AT3: 0 | AU3: 0 | AV3: 0 | AW3: =1/K3 -> 0.033333333 | AX3: =1/(K3*K3) -> 0.0011111111
A4: Agarwal & Winkler (1985) | B4: 1985 | C4: =+IF(A4=A3,C3,C3+1) -> 1 | D4: enrollment | E4: tuition | F4: -1.21 | G4: 0.298 | H4: 3 | I4: 17 | J4: =+I4-H4 -> 14 | K4: 30 | L4: 1954 | M4: 1973 | N4: =+L4+(M4-L4)/2 -> 1963.5 | O4: =+M4-L4+1 -> 20 | P4: =+LN(O3:O4) -> 2.9957323 | Q4: 105 | R4: 0 | S4: OLS | T4: =IF(S4="OLS",0,IF(S4="FE",0,IF(S4="Probit model",0,IF(S4="3SLS",1,IF(S4="Logit",0,IF(S4="2SLS",1,IF(S4="SUR method",1,IF(S4="Modified LS",0,IF(S4="Zenner estimates",1,IF(S4="MLE",0,IF(S4="GLS",0,0))))))))))) -> 0 | U4: 0 | V4: 0 | W4: 0 | X4: 0 | Y4: 1 | Z4: 0 | AA4: 0 | AB4: USA | AC4: =IF(AB4="USA",1,IF(AB4="UK",2,IF(AB4="Canada",3,IF(AB4="Germany",4,IF(AB4="Netherlands",5,IF(AB4="India",20,IF(AB4="Indonesia",7,IF(AB4="Korea",8,IF(AB4="Philippines",9,IF(AB4="Taiwan",10,IF(AB4="Greece",11,IF(AB4="Iran",12,IF(AB4="Israel",13,IF(AB4="Kuwait",14,IF(AB4="Lebanon",15,IF(AB4="Saudi Arabia",16,IF(AB4="Turkey",17,IF(AB4="Ethiopia",18,IF(AB4="Kenya",19,IF(AB4="Nigeria",20,IF(AB4="Multinational",6,""))))))))))))))))))))) -> 1 | AD4: =IF(AB4="USA",1,0) -> 1 | AE4: 1 | AF4: 7.593374 | AG4: 4.663439 | AH4: =+F4/G4 -> -4.0604027 | AI4: =AH4/SQRT(AH4^2+J4) -> -0.73538148 | AJ4: =+AI4/AH4 -> 0.18111048 | AK4: =1/AJ4^2 -> 30.48687 | AL4: =1/AJ4 -> 5.5214916 | AM4: 1 | AN4: 0 | AO4: 0 | AP4: =1/SQRT(J4) -> 0.26726124 | AQ4: 1 | AR4: 0 | AS4: 0 | AT4: 0 | AU4: 0 | AV4: 0 | AW4: =1/K4 -> 0.033333333 | AX4: =1/(K4*K4) -> 0.0011111111
A5: Agarwal & Winkler (1985) | B5: 1985 | C5: =+IF(A5=A4,C4,C4+1) -> 1 | D5: enrollment | E5: tuition | F5: -0.468 | G5: 0.222 | H5: 3 | I5: 17 | J5: =+I5-H5 -> 14 | K5: 30 | L5: 1954 | M5: 1973 | N5: =+L5+(M5-L5)/2 -> 1963.5 | O5: =+M5-L5+1 -> 20 | P5: =+LN(O4:O5) -> 2.9957323 | Q5: 105 | R5: 0 | S5: OLS | T5: =IF(S5="OLS",0,IF(S5="FE",0,IF(S5="Probit model",0,IF(S5="3SLS",1,IF(S5="Logit",0,IF(S5="2SLS",1,IF(S5="SUR method",1,IF(S5="Modified LS",0,IF(S5="Zenner estimates",1,IF(S5="MLE",0,IF(S5="GLS",0,0))))))))))) -> 0 | U5: 0 | V5: 0 | W5: 0 | X5: 0 | Y5: 1 | Z5: 0 | AA5: 0 | AB5: USA | AC5: =IF(AB5="USA",1,IF(AB5="UK",2,IF(AB5="Canada",3,IF(AB5="Germany",4,IF(AB5="Netherlands",5,IF(AB5="India",20,IF(AB5="Indonesia",7,IF(AB5="Korea",8,IF(AB5="Philippines",9,IF(AB5="Taiwan",10,IF(AB5="Greece",11,IF(AB5="Iran",12,IF(AB5="Israel",13,IF(AB5="Kuwait",14,IF(AB5="Lebanon",15,IF(AB5="Saudi Arabia",16,IF(AB5="Turkey",17,IF(AB5="Ethiopia",18,IF(AB5="Kenya",19,IF(AB5="Nigeria",20,IF(AB5="Multinational",6,""))))))))))))))))))))) -> 1 | AD5: =IF(AB5="USA",1,0) -> 1 | AE5: 1 | AF5: 7.593374 | AG5: 4.663439 | AH5: =+F5/G5 -> -2.1081081 | AI5: =AH5/SQRT(AH5^2+J5) -> -0.49086708 | AJ5: =+AI5/AH5 -> 0.23284721 | AK5: =1/AJ5^2 -> 18.44412 | AL5: =1/AJ5 -> 4.2946618 | AM5: 1 | AN5: 0 | AO5: 0 | AP5: =1/SQRT(J5) -> 0.26726124 | AQ5: 1 | AR5: 0 | AS5: 0 | AT5: 0 | AU5: 0 | AV5: 0 | AW5: =1/K5 -> 0.033333333 | AX5: =1/(K5*K5) -> 0.0011111111
A6: Agarwal & Winkler (1985) | B6: 1985 | C6: =+IF(A6=A5,C5,C5+1) -> 1 | D6: enrollment | E6: tuition | F6: -1.523 | G6: 1.304 | H6: 3 | I6: 17 | J6: =+I6-H6 -> 14 | K6: 30 | L6: 1954 | M6: 1973 | N6: =+L6+(M6-L6)/2 -> 1963.5 | O6: =+M6-L6+1 -> 20 | P6: =+LN(O5:O6) -> 2.9957323 | Q6: 105 | R6: 0 | S6: OLS | T6: =IF(S6="OLS",0,IF(S6="FE",0,IF(S6="Probit model",0,IF(S6="3SLS",1,IF(S6="Logit",0,IF(S6="2SLS",1,IF(S6="SUR method",1,IF(S6="Modified LS",0,IF(S6="Zenner estimates",1,IF(S6="MLE",0,IF(S6="GLS",0,0))))))))))) -> 0 | U6: 0 | V6: 0 | W6: 0 | X6: 0 | Y6: 1 | Z6: 0 | AA6: 0 | AB6: USA | AC6: =IF(AB6="USA",1,IF(AB6="UK",2,IF(AB6="Canada",3,IF(AB6="Germany",4,IF(AB6="Netherlands",5,IF(AB6="India",20,IF(AB6="Indonesia",7,IF(AB6="Korea",8,IF(AB6="Philippines",9,IF(AB6="Taiwan",10,IF(AB6="Greece",11,IF(AB6="Iran",12,IF(AB6="Israel",13,IF(AB6="Kuwait",14,IF(AB6="Lebanon",15,IF(AB6="Saudi Arabia",16,IF(AB6="Turkey",17,IF(AB6="Ethiopia",18,IF(AB6="Kenya",19,IF(AB6="Nigeria",20,IF(AB6="Multinational",6,""))))))))))))))))))))) -> 1 | AD6: =IF(AB6="USA",1,0) -> 1 | AE6: 1 | AF6: 7.593374 | AG6: 4.663439 | AH6: =+F6/G6 -> -1.1679448 | AI6: =AH6/SQRT(AH6^2+J6) -> -0.29796745 | AJ6: =+AI6/AH6 -> 0.25512118 | AK6: =1/AJ6^2 -> 15.364095 | AL6: =1/AJ6 -> 3.919706 | AM6: 1 | AN6: 0 | AO6: 0 | AP6: =1/SQRT(J6) -> 0.26726124 | AQ6: 1 | AR6: 0 | AS6: 0 | AT6: 0 | AU6: 0 | AV6: 0 | AW6: =1/K6 -> 0.033333333 | AX6: =1/(K6*K6) -> 0.0011111111
A7: Agarwal & Winkler (1985) | B7: 1985 | C7: =+IF(A7=A6,C6,C6+1) -> 1 | D7: enrollment | E7: tuition | F7: -0.87 | G7: 0.204 | H7: 3 | I7: 17 | J7: =+I7-H7 -> 14 | K7: 30 | L7: 1954 | M7: 1973 | N7: =+L7+(M7-L7)/2 -> 1963.5 | O7: =+M7-L7+1 -> 20 | P7: =+LN(O6:O7) -> 2.9957323 | Q7: 105 | R7: 0 | S7: OLS | T7: =IF(S7="OLS",0,IF(S7="FE",0,IF(S7="Probit model",0,IF(S7="3SLS",1,IF(S7="Logit",0,IF(S7="2SLS",1,IF(S7="SUR method",1,IF(S7="Modified LS",0,IF(S7="Zenner estimates",1,IF(S7="MLE",0,IF(S7="GLS",0,0))))))))))) -> 0 | U7: 0 | V7: 0 | W7: 0 | X7: 0 | Y7: 1 | Z7: 0 | AA7: 0 | AB7: USA | AC7: =IF(AB7="USA",1,IF(AB7="UK",2,IF(AB7="Canada",3,IF(AB7="Germany",4,IF(AB7="Netherlands",5,IF(AB7="India",20,IF(AB7="Indonesia",7,IF(AB7="Korea",8,IF(AB7="Philippines",9,IF(AB7="Taiwan",10,IF(AB7="Greece",11,IF(AB7="Iran",12,IF(AB7="Israel",13,IF(AB7="Kuwait",14,IF(AB7="Lebanon",15,IF(AB7="Saudi Arabia",16,IF(AB7="Turkey",17,IF(AB7="Ethiopia",18,IF(AB7="Kenya",19,IF(AB7="Nigeria",20,IF(AB7="Multinational",6,""))))))))))))))))))))) -> 1 | AD7: =IF(AB7="USA",1,0) -> 1 | AE7: 1 | AF7: 7.593374 | AG7: 4.663439 | AH7: =+F7/G7 -> -4.2647059 | AI7: =AH7/SQRT(AH7^2+J7) -> -0.75169905 | AJ7: =+AI7/AH7 -> 0.17626047 | AK7: =1/AJ7^2 -> 32.187716 | AL7: =1/AJ7 -> 5.6734219 | AM7: 1 | AN7: 0 | AO7: 0 | AP7: =1/SQRT(J7) -> 0.26726124 | AQ7: 1 | AR7: 0 | AS7: 0 | AT7: 0 | AU7: 0 | AV7: 0 | AW7: =1/K7 -> 0.033333333 | AX7: =1/(K7*K7) -> 0.0011111111
A8: Agarwal & Winkler (1985) | B8: 1985 | C8: =+IF(A8=A7,C7,C7+1) -> 1 | D8: enrollment | E8: tuition | F8: -1.197 | G8: 0.256 | H8: 3 | I8: 17 | J8: =+I8-H8 -> 14 | K8: 30 | L8: 1954 | M8: 1973 | N8: =+L8+(M8-L8)/2 -> 1963.5 | O8: =+M8-L8+1 -> 20 | P8: =+LN(O7:O8) -> 2.9957323 | Q8: 105 | R8: 0 | S8: OLS | T8: =IF(S8="OLS",0,IF(S8="FE",0,IF(S8="Probit model",0,IF(S8="3SLS",1,IF(S8="Logit",0,IF(S8="2SLS",1,IF(S8="SUR method",1,IF(S8="Modified LS",0,IF(S8="Zenner estimates",1,IF(S8="MLE",0,IF(S8="GLS",0,0))))))))))) -> 0 | U8: 0 | V8: 0 | W8: 0 | X8: 0 | Y8: 1 | Z8: 0 | AA8: 0 | AB8: USA | AC8: =IF(AB8="USA",1,IF(AB8="UK",2,IF(AB8="Canada",3,IF(AB8="Germany",4,IF(AB8="Netherlands",5,IF(AB8="India",20,IF(AB8="Indonesia",7,IF(AB8="Korea",8,IF(AB8="Philippines",9,IF(AB8="Taiwan",10,IF(AB8="Greece",11,IF(AB8="Iran",12,IF(AB8="Israel",13,IF(AB8="Kuwait",14,IF(AB8="Lebanon",15,IF(AB8="Saudi Arabia",16,IF(AB8="Turkey",17,IF(AB8="Ethiopia",18,IF(AB8="Kenya",19,IF(AB8="Nigeria",20,IF(AB8="Multinational",6,""))))))))))))))))))))) -> 1 | AD8: =IF(AB8="USA",1,0) -> 1 | AE8: 1 | AF8: 7.593374 | AG8: 4.663439 | AH8: =+F8/G8 -> -4.6757812 | AI8: =AH8/SQRT(AH8^2+J8) -> -0.78078471 | AJ8: =+AI8/AH8 -> 0.16698487 | AK8: =1/AJ8^2 -> 35.86293 | AL8: =1/AJ8 -> 5.9885666 | AM8: 1 | AN8: 0 | AO8: 0 | AP8: =1/SQRT(J8) -> 0.26726124 | AQ8: 1 | AR8: 0 | AS8: 0 | AT8: 0 | AU8: 0 | AV8: 0 | AW8: =1/K8 -> 0.033333333 | AX8: =1/(K8*K8) -> 0.0011111111
A9: Agarwal & Winkler (1985) | B9: 1985 | C9: =+IF(A9=A8,C8,C8+1) -> 1 | D9: enrollment | E9: tuition | F9: -1.357 | G9: 0.601 | H9: 3 | I9: 17 | J9: =+I9-H9 -> 14 | K9: 30 | L9: 1954 | M9: 1973 | N9: =+L9+(M9-L9)/2 -> 1963.5 | O9: =+M9-L9+1 -> 20 | P9: =+LN(O8:O9) -> 2.9957323 | Q9: 105 | R9: 0 | S9: OLS | T9: =IF(S9="OLS",0,IF(S9="FE",0,IF(S9="Probit model",0,IF(S9="3SLS",1,IF(S9="Logit",0,IF(S9="2SLS",1,IF(S9="SUR method",1,IF(S9="Modified LS",0,IF(S9="Zenner estimates",1,IF(S9="MLE",0,IF(S9="GLS",0,0))))))))))) -> 0 | U9: 0 | V9: 0 | W9: 0 | X9: 0 | Y9: 1 | Z9: 0 | AA9: 0 | AB9: USA | AC9: =IF(AB9="USA",1,IF(AB9="UK",2,IF(AB9="Canada",3,IF(AB9="Germany",4,IF(AB9="Netherlands",5,IF(AB9="India",20,IF(AB9="Indonesia",7,IF(AB9="Korea",8,IF(AB9="Philippines",9,IF(AB9="Taiwan",10,IF(AB9="Greece",11,IF(AB9="Iran",12,IF(AB9="Israel",13,IF(AB9="Kuwait",14,IF(AB9="Lebanon",15,IF(AB9="Saudi Arabia",16,IF(AB9="Turkey",17,IF(AB9="Ethiopia",18,IF(AB9="Kenya",19,IF(AB9="Nigeria",20,IF(AB9="Multinational",6,""))))))))))))))))))))) -> 1 | AD9: =IF(AB9="USA",1,0) -> 1 | AE9: 1 | AF9: 7.593374 | AG9: 4.663439 | AH9: =+F9/G9 -> -2.2579035 | AI9: =AH9/SQRT(AH9^2+J9) -> -0.51666611 | AJ9: =+AI9/AH9 -> 0.22882559 | AK9: =1/AJ9^2 -> 19.098128 | AL9: =1/AJ9 -> 4.3701405 | AM9: 1 | AN9: 0 | AO9: 0 | AP9: =1/SQRT(J9) -> 0.26726124 | AQ9: 1 | AR9: 0 | AS9: 0 | AT9: 0 | AU9: 0 | AV9: 0 | AW9: =1/K9 -> 0.033333333 | AX9: =1/(K9*K9) -> 0.0011111111
A10: Agarwal & Winkler (1985) | B10: 1985 | C10: =+IF(A10=A9,C9,C9+1) -> 1 | D10: enrollment | E10: tuition | F10: -0.223 | G10: 1.229 | H10: 3 | I10: 17 | J10: =+I10-H10 -> 14 | K10: 30 | L10: 1954 | M10: 1973 | N10: =+L10+(M10-L10)/2 -> 1963.5 | O10: =+M10-L10+1 -> 20 | P10: =+LN(O9:O10) -> 2.9957323 | Q10: 105 | R10: 0 | S10: OLS | T10: =IF(S10="OLS",0,IF(S10="FE",0,IF(S10="Probit model",0,IF(S10="3SLS",1,IF(S10="Logit",0,IF(S10="2SLS",1,IF(S10="SUR method",1,IF(S10="Modified LS",0,IF(S10="Zenner estimates",1,IF(S10="MLE",0,IF(S10="GLS",0,0))))))))))) -> 0 | U10: 0 | V10: 0 | W10: 0 | X10: 0 | Y10: 1 | Z10: 0 | AA10: 0 | AB10: USA | AC10: =IF(AB10="USA",1,IF(AB10="UK",2,IF(AB10="Canada",3,IF(AB10="Germany",4,IF(AB10="Netherlands",5,IF(AB10="India",20,IF(AB10="Indonesia",7,IF(AB10="Korea",8,IF(AB10="Philippines",9,IF(AB10="Taiwan",10,IF(AB10="Greece",11,IF(AB10="Iran",12,IF(AB10="Israel",13,IF(AB10="Kuwait",14,IF(AB10="Lebanon",15,IF(AB10="Saudi Arabia",16,IF(AB10="Turkey",17,IF(AB10="Ethiopia",18,IF(AB10="Kenya",19,IF(AB10="Nigeria",20,IF(AB10="Multinational",6,""))))))))))))))))))))) -> 1 | AD10: =IF(AB10="USA",1,0) -> 1 | AE10: 1 | AF10: 7.593374 | AG10: 4.663439 | AH10: =+F10/G10 -> -0.18144833 | AI10: =AH10/SQRT(AH10^2+J10) -> -0.048437186 | AJ10: =+AI10/AH10 -> 0.26694754 | AK10: =1/AJ10^2 -> 14.032923 | AL10: =1/AJ10 -> 3.7460544 | AM10: 1 | AN10: 0 | AO10: 0 | AP10: =1/SQRT(J10) -> 0.26726124 | AQ10: 1 | AR10: 0 | AS10: 0 | AT10: 0 | AU10: 0 | AV10: 0 | AW10: =1/K10 -> 0.033333333 | AX10: =1/(K10*K10) -> 0.0011111111
A11: Agarwal & Winkler (1985) | B11: 1985 | C11: =+IF(A11=A10,C10,C10+1) -> 1 | D11: enrollment | E11: tuition | F11: -1.165 | G11: 0.255 | H11: 3 | I11: 17 | J11: =+I11-H11 -> 14 | K11: 30 | L11: 1954 | M11: 1973 | N11: =+L11+(M11-L11)/2 -> 1963.5 | O11: =+M11-L11+1 -> 20 | P11: =+LN(O10:O11) -> 2.9957323 | Q11: 105 | R11: 0 | S11: OLS | T11: =IF(S11="OLS",0,IF(S11="FE",0,IF(S11="Probit model",0,IF(S11="3SLS",1,IF(S11="Logit",0,IF(S11="2SLS",1,IF(S11="SUR method",1,IF(S11="Modified LS",0,IF(S11="Zenner estimates",1,IF(S11="MLE",0,IF(S11="GLS",0,0))))))))))) -> 0 | U11: 0 | V11: 0 | W11: 0 | X11: 0 | Y11: 1 | Z11: 0 | AA11: 0 | AB11: USA | AC11: =IF(AB11="USA",1,IF(AB11="UK",2,IF(AB11="Canada",3,IF(AB11="Germany",4,IF(AB11="Netherlands",5,IF(AB11="India",20,IF(AB11="Indonesia",7,IF(AB11="Korea",8,IF(AB11="Philippines",9,IF(AB11="Taiwan",10,IF(AB11="Greece",11,IF(AB11="Iran",12,IF(AB11="Israel",13,IF(AB11="Kuwait",14,IF(AB11="Lebanon",15,IF(AB11="Saudi Arabia",16,IF(AB11="Turkey",17,IF(AB11="Ethiopia",18,IF(AB11="Kenya",19,IF(AB11="Nigeria",20,IF(AB11="Multinational",6,""))))))))))))))))))))) -> 1 | AD11: =IF(AB11="USA",1,0) -> 1 | AE11: 1 | AF11: 7.593374 | AG11: 4.663439 | AH11: =+F11/G11 -> -4.5686275 | AI11: =AH11/SQRT(AH11^2+J11) -> -0.77365101 | AJ11: =+AI11/AH11 -> 0.16933992 | AK11: =1/AJ11^2 -> 34.872357 | AL11: =1/AJ11 -> 5.9052821 | AM11: 1 | AN11: 0 | AO11: 0 | AP11: =1/SQRT(J11) -> 0.26726124 | AQ11: 1 | AR11: 0 | AS11: 0 | AT11: 0 | AU11: 0 | AV11: 0 | AW11: =1/K11 -> 0.033333333 | AX11: =1/(K11*K11) -> 0.0011111111
A12: Agarwal & Winkler (1985) | B12: 1985 | C12: =+IF(A12=A11,C11,C11+1) -> 1 | D12: enrollment | E12: tuition | F12: -2.836 | G12: 0.352 | H12: 3 | I12: 17 | J12: =+I12-H12 -> 14 | K12: 30 | L12: 1954 | M12: 1973 | N12: =+L12+(M12-L12)/2 -> 1963.5 | O12: =+M12-L12+1 -> 20 | P12: =+LN(O11:O12) -> 2.9957323 | Q12: 105 | R12: 0 | S12: OLS | T12: =IF(S12="OLS",0,IF(S12="FE",0,IF(S12="Probit model",0,IF(S12="3SLS",1,IF(S12="Logit",0,IF(S12="2SLS",1,IF(S12="SUR method",1,IF(S12="Modified LS",0,IF(S12="Zenner estimates",1,IF(S12="MLE",0,IF(S12="GLS",0,0))))))))))) -> 0 | U12: 0 | V12: 0 | W12: 0 | X12: 0 | Y12: 1 | Z12: 0 | AA12: 0 | AB12: USA | AC12: =IF(AB12="USA",1,IF(AB12="UK",2,IF(AB12="Canada",3,IF(AB12="Germany",4,IF(AB12="Netherlands",5,IF(AB12="India",20,IF(AB12="Indonesia",7,IF(AB12="Korea",8,IF(AB12="Philippines",9,IF(AB12="Taiwan",10,IF(AB12="Greece",11,IF(AB12="Iran",12,IF(AB12="Israel",13,IF(AB12="Kuwait",14,IF(AB12="Lebanon",15,IF(AB12="Saudi Arabia",16,IF(AB12="Turkey",17,IF(AB12="Ethiopia",18,IF(AB12="Kenya",19,IF(AB12="Nigeria",20,IF(AB12="Multinational",6,""))))))))))))))))))))) -> 1 | AD12: =IF(AB12="USA",1,0) -> 1 | AE12: 1 | AF12: 7.593374 | AG12: 4.663439 | AH12: =+F12/G12 -> -8.0568182 | AI12: =AH12/SQRT(AH12^2+J12) -> -0.90696632 | AJ12: =+AI12/AH12 -> 0.11257128 | AK12: =1/AJ12^2 -> 78.912319 | AL12: =1/AJ12 -> 8.8832606 | AM12: 1 | AN12: 0 | AO12: 0 | AP12: =1/SQRT(J12) -> 0.26726124 | AQ12: 1 | AR12: 0 | AS12: 0 | AT12: 0 | AU12: 0 | AV12: 0 | AW12: =1/K12 -> 0.033333333 | AX12: =1/(K12*K12) -> 0.0011111111
A13: Agarwal & Winkler (1985) | B13: 1985 | C13: =+IF(A13=A12,C12,C12+1) -> 1 | D13: enrollment | E13: tuition | F13: -2.278 | G13: 0.279 | H13: 3 | I13: 17 | J13: =+I13-H13 -> 14 | K13: 30 | L13: 1954 | M13: 1973 | N13: =+L13+(M13-L13)/2 -> 1963.5 | O13: =+M13-L13+1 -> 20 | P13: =+LN(O12:O13) -> 2.9957323 | Q13: 105 | R13: 0 | S13: OLS | T13: =IF(S13="OLS",0,IF(S13="FE",0,IF(S13="Probit model",0,IF(S13="3SLS",1,IF(S13="Logit",0,IF(S13="2SLS",1,IF(S13="SUR method",1,IF(S13="Modified LS",0,IF(S13="Zenner estimates",1,IF(S13="MLE",0,IF(S13="GLS",0,0))))))))))) -> 0 | U13: 0 | V13: 0 | W13: 0 | X13: 0 | Y13: 1 | Z13: 0 | AA13: 0 | AB13: USA | AC13: =IF(AB13="USA",1,IF(AB13="UK",2,IF(AB13="Canada",3,IF(AB13="Germany",4,IF(AB13="Netherlands",5,IF(AB13="India",20,IF(AB13="Indonesia",7,IF(AB13="Korea",8,IF(AB13="Philippines",9,IF(AB13="Taiwan",10,IF(AB13="Greece",11,IF(AB13="Iran",12,IF(AB13="Israel",13,IF(AB13="Kuwait",14,IF(AB13="Lebanon",15,IF(AB13="Saudi Arabia",16,IF(AB13="Turkey",17,IF(AB13="Ethiopia",18,IF(AB13="Kenya",19,IF(AB13="Nigeria",20,IF(AB13="Multinational",6,""))))))))))))))))))))) -> 1 | AD13: =IF(AB13="USA",1,0) -> 1 | AE13: 1 | AF13: 7.593374 | AG13: 4.663439 | AH13: =+F13/G13 -> -8.1648746 | AI13: =AH13/SQRT(AH13^2+J13) -> -0.90908915 | AJ13: =+AI13/AH13 -> 0.11134147 | AK13: =1/AJ13^2 -> 80.665176 | AL13: =1/AJ13 -> 8.9813794 | AM13: 1 | AN13: 0 | AO13: 0 | AP13: =1/SQRT(J13) -> 0.26726124 | AQ13: 1 | AR13: 0 | AS13: 0 | AT13: 0 | AU13: 0 | AV13: 0 | AW13: =1/K13 -> 0.033333333 | AX13: =1/(K13*K13) -> 0.0011111111
A14: Agarwal & Winkler (1985) | B14: 1985 | C14: =+IF(A14=A13,C13,C13+1) -> 1 | D14: enrollment | E14: tuition | F14: 0.725 | G14: 0.475 | H14: 3 | I14: 17 | J14: =+I14-H14 -> 14 | K14: 30 | L14: 1954 | M14: 1973 | N14: =+L14+(M14-L14)/2 -> 1963.5 | O14: =+M14-L14+1 -> 20 | P14: =+LN(O13:O14) -> 2.9957323 | Q14: 105 | R14: 0 | S14: OLS | T14: =IF(S14="OLS",0,IF(S14="FE",0,IF(S14="Probit model",0,IF(S14="3SLS",1,IF(S14="Logit",0,IF(S14="2SLS",1,IF(S14="SUR method",1,IF(S14="Modified LS",0,IF(S14="Zenner estimates",1,IF(S14="MLE",0,IF(S14="GLS",0,0))))))))))) -> 0 | U14: 0 | V14: 0 | W14: 0 | X14: 0 | Y14: 1 | Z14: 0 | AA14: 0 | AB14: USA | AC14: =IF(AB14="USA",1,IF(AB14="UK",2,IF(AB14="Canada",3,IF(AB14="Germany",4,IF(AB14="Netherlands",5,IF(AB14="India",20,IF(AB14="Indonesia",7,IF(AB14="Korea",8,IF(AB14="Philippines",9,IF(AB14="Taiwan",10,IF(AB14="Greece",11,IF(AB14="Iran",12,IF(AB14="Israel",13,IF(AB14="Kuwait",14,IF(AB14="Lebanon",15,IF(AB14="Saudi Arabia",16,IF(AB14="Turkey",17,IF(AB14="Ethiopia",18,IF(AB14="Kenya",19,IF(AB14="Nigeria",20,IF(AB14="Multinational",6,""))))))))))))))))))))) -> 1 | AD14: =IF(AB14="USA",1,0) -> 1 | AE14: 1 | AF14: 7.593374 | AG14: 4.663439 | AH14: =+F14/G14 -> 1.5263158 | AI14: =AH14/SQRT(AH14^2+J14) -> 0.37770792 | AJ14: =+AI14/AH14 -> 0.24746381 | AK14: =1/AJ14^2 -> 16.32964 | AL14: =1/AJ14 -> 4.0409949 | AM14: 1 | AN14: 0 | AO14: 0 | AP14: =1/SQRT(J14) -> 0.26726124 | AQ14: 1 | AR14: 0 | AS14: 0 | AT14: 0 | AU14: 0 | AV14: 0 | AW14: =1/K14 -> 0.033333333 | AX14: =1/(K14*K14) -> 0.0011111111
... A55: Buss et al. (2004) | B55: 2004 | C55: =+IF(A55=A54,C54,C54+1) -> 7 | D55: enrollment | E55: tuition | F55: -0.069 | G55: 0.0082 | H55: 10 | I55: 356 | J55: =+I55-H55 -> 346 | K55: 6 | L55: 1988 | M55: 1998 | N55: =+L55+(M55-L55)/2 -> 1993 | O55: =+M55-L55+1 -> 11 | P55: =+LN(O54:O55) -> 2.3978953 | Q55: 42 | R55: 3 | S55: OLS | T55: =IF(S55="OLS",0,IF(S55="FE",0,IF(S55="Probit model",0,IF(S55="3SLS",1,IF(S55="Logit",0,IF(S55="2SLS",1,IF(S55="SUR method",1,IF(S55="Modified LS",0,IF(S55="Zenner estimates",1,IF(S55="MLE",0,IF(S55="GLS",0,0))))))))))) -> 0 | U55: 0 | V55: 0 | W55: 0 | X55: 0 | Y55: 0 | Z55: 1 | AA55: 0 | AB55: USA | AC55: =IF(AB55="USA",1,IF(AB55="UK",2,IF(AB55="Canada",3,IF(AB55="Germany",4,IF(AB55="Netherlands",5,IF(AB55="India",20,IF(AB55="Indonesia",7,IF(AB55="Korea",8,IF(AB55="Philippines",9,IF(AB55="Taiwan",10,IF(AB55="Greece",11,IF(AB55="Iran",12,IF(AB55="Israel",13,IF(AB55="Kuwait",14,IF(AB55="Lebanon",15,IF(AB55="Saudi Arabia",16,IF(AB55="Turkey",17,IF(AB55="Ethiopia",18,IF(AB55="Kenya",19,IF(AB55="Nigeria",20,IF(AB55="Multinational",6,""))))))))))))))))))))) -> 1 | AD55: =IF(AB55="USA",1,0) -> 1 | AE55: 1 | AF55: 7.602901 | AG55: 3.7612 | AH55: =+F55/G55 -> -8.4146341 | AI55: =AH55/SQRT(AH55^2+J55) -> -0.41216226 | AJ55: =+AI55/AH55 -> 0.048981602 | AK55: =1/AJ55^2 -> 416.80607 | AL55: =1/AJ55 -> 20.415829 | AM55: 1 | AN55: 0 | AO55: 0 | AP55: =1/SQRT(J55) -> 0.053760333 | AQ55: 1 | AR55: 0 | AS55: 0 | AT55: 0 | AU55: 1 | AV55: 0 | AW55: =1/K55 -> 0.16666667 | AX55: =1/(K55*K55) -> 0.027777778
A56: Campbell & Siegel (1967) | B56: 1967 | C56: =+IF(A56=A55,C55,C55+1) -> 8 | D56: enrollment | E56: tuition | F56: -0.44 | G56: 0.1506 | H56: 2 | I56: 450 | J56: =+I56-H56 -> 448 | K56: 1 | L56: 1927 | M56: 1963 | N56: =(1927+1931+1935+1939+1947+1951+1955+1959+1963)/O56 -> 1945.2222 | O56: 9 | P56: =+LN(O55:O56) -> 2.1972246 | Q56: 293 | R56: 0 | S56: OLS | T56: =IF(S56="OLS",0,IF(S56="FE",0,IF(S56="Probit model",0,IF(S56="3SLS",1,IF(S56="Logit",0,IF(S56="2SLS",1,IF(S56="SUR method",1,IF(S56="Modified LS",0,IF(S56="Zenner estimates",1,IF(S56="MLE",0,IF(S56="GLS",0,0))))))))))) -> 0 | U56: 0 | V56: 1 | W56: 1 | X56: 0 | Y56: 1 | Z56: 0 | AA56: 0 | AB56: USA | AC56: =IF(AB56="USA",1,IF(AB56="UK",2,IF(AB56="Canada",3,IF(AB56="Germany",4,IF(AB56="Netherlands",5,IF(AB56="India",20,IF(AB56="Indonesia",7,IF(AB56="Korea",8,IF(AB56="Philippines",9,IF(AB56="Taiwan",10,IF(AB56="Greece",11,IF(AB56="Iran",12,IF(AB56="Israel",13,IF(AB56="Kuwait",14,IF(AB56="Lebanon",15,IF(AB56="Saudi Arabia",16,IF(AB56="Turkey",17,IF(AB56="Ethiopia",18,IF(AB56="Kenya",19,IF(AB56="Nigeria",20,IF(AB56="Multinational",6,""))))))))))))))))))))) -> 1 | AD56: =IF(AB56="USA",1,0) -> 1 | AE56: 1 | AF56: 7.584265 | AG56: 5.68358 | AH56: =+F56/G56 -> -2.9216467 | AI56: =AH56/SQRT(AH56^2+J56) -> -0.1367383 | AJ56: =+AI56/AH56 -> 0.046801791 | AK56: =1/AJ56^2 -> 456.53602 | AL56: =1/AJ56 -> 21.366704 | AM56: 0 | AN56: 1 | AO56: 0 | AP56: =1/SQRT(J56) -> 0.047245559 | AQ56: 1 | AR56: 0 | AS56: 0 | AT56: 0 | AU56: 0 | AV56: 1 | AW56: =1/K56 -> 1 | AX56: =1/(K56*K56) -> 1
A57: Canton & de Jong (2002) | B57: 2002 | C57: =+IF(A57=A56,C56,C56+1) -> 9 | D57: enrollment | E57: tuition | F57: -0.143 | G57: 0.192 | H57: 6 | I57: 48 | J57: =+I57-H57 -> 42 | K57: 20 | L57: 1950 | M57: 1999 | N57: =+L57+(M57-L57)/2 -> 1974.5 | O57: =+M57-L57+1 -> 50 | P57: =+LN(O56:O57) -> 3.912023 | Q57: 20 | R57: 4 | S57: ECM (OLS) | T57: =IF(S57="OLS",0,IF(S57="FE",0,IF(S57="Probit model",0,IF(S57="3SLS",1,IF(S57="Logit",0,IF(S57="2SLS",1,IF(S57="SUR method",1,IF(S57="Modified LS",0,IF(S57="Zenner estimates",1,IF(S57="MLE",0,IF(S57="GLS",0,0))))))))))) -> 0 | U57: 1 | V57: 1 | W57: 0 | X57: 0 | Y57: 1 | Z57: 0 | AA57: 0 | AB57: Netherlands | AC57: =IF(AB57="USA",1,IF(AB57="UK",2,IF(AB57="Canada",3,IF(AB57="Germany",4,IF(AB57="Netherlands",5,IF(AB57="India",20,IF(AB57="Indonesia",7,IF(AB57="Korea",8,IF(AB57="Philippines",9,IF(AB57="Taiwan",10,IF(AB57="Greece",11,IF(AB57="Iran",12,IF(AB57="Israel",13,IF(AB57="Kuwait",14,IF(AB57="Lebanon",15,IF(AB57="Saudi Arabia",16,IF(AB57="Turkey",17,IF(AB57="Ethiopia",18,IF(AB57="Kenya",19,IF(AB57="Nigeria",20,IF(AB57="Multinational",6,""))))))))))))))))))))) -> 5 | AD57: =IF(AB57="USA",1,0) -> 0 | AE57: 0 | AF57: 7.601902 | AG57: 3.044523 | AH57: =+F57/G57 -> -0.74479167 | AI57: =AH57/SQRT(AH57^2+J57) -> -0.11417236 | AJ57: =+AI57/AH57 -> 0.15329435 | AK57: =1/AJ57^2 -> 42.554715 | AL57: =1/AJ57 -> 6.5233975 | AM57: 0 | AN57: 1 | AO57: 0 | AP57: =1/SQRT(J57) -> 0.15430335 | AQ57: 1 | AR57: 0 | AS57: 1 | AT57: 0 | AU57: 0 | AV57: 0 | AW57: =1/K57 -> 0.05 | AX57: =1/(K57*K57) -> 0.0025
A58: Canton & de Jong (2002) | B58: 2002 | C58: =+IF(A58=A57,C57,C57+1) -> 9 | D58: enrollment | E58: tuition | F58: -0.377 | G58: 0.292 | H58: 6 | I58: 47 | J58: =+I58-H58 -> 41 | K58: 20 | L58: 1950 | M58: 1999 | N58: =+L58+(M58-L58)/2 -> 1974.5 | O58: =+M58-L58+1 -> 50 | P58: =+LN(O57:O58) -> 3.912023 | Q58: 20 | R58: 4 | S58: ECM (OLS) | T58: =IF(S58="OLS",0,IF(S58="FE",0,IF(S58="Probit model",0,IF(S58="3SLS",1,IF(S58="Logit",0,IF(S58="2SLS",1,IF(S58="SUR method",1,IF(S58="Modified LS",0,IF(S58="Zenner estimates",1,IF(S58="MLE",0,IF(S58="GLS",0,0))))))))))) -> 0 | U58: 1 | V58: 1 | W58: 0 | X58: 0 | Y58: 1 | Z58: 0 | AA58: 0 | AB58: Netherlands | AC58: =IF(AB58="USA",1,IF(AB58="UK",2,IF(AB58="Canada",3,IF(AB58="Germany",4,IF(AB58="Netherlands",5,IF(AB58="India",20,IF(AB58="Indonesia",7,IF(AB58="Korea",8,IF(AB58="Philippines",9,IF(AB58="Taiwan",10,IF(AB58="Greece",11,IF(AB58="Iran",12,IF(AB58="Israel",13,IF(AB58="Kuwait",14,IF(AB58="Lebanon",15,IF(AB58="Saudi Arabia",16,IF(AB58="Turkey",17,IF(AB58="Ethiopia",18,IF(AB58="Kenya",19,IF(AB58="Nigeria",20,IF(AB58="Multinational",6,""))))))))))))))))))))) -> 5 | AD58: =IF(AB58="USA",1,0) -> 0 | AE58: 0 | AF58: 7.601902 | AG58: 3.044523 | AH58: =+F58/G58 -> -1.2910959 | AI58: =AH58/SQRT(AH58^2+J58) -> -0.19765728 | AJ58: =+AI58/AH58 -> 0.15309264 | AK58: =1/AJ58^2 -> 42.666929 | AL58: =1/AJ58 -> 6.5319927 | AM58: 0 | AN58: 1 | AO58: 0 | AP58: =1/SQRT(J58) -> 0.15617376 | AQ58: 1 | AR58: 0 | AS58: 1 | AT58: 0 | AU58: 0 | AV58: 0 | AW58: =1/K58 -> 0.05 | AX58: =1/(K58*K58) -> 0.0025
A59: Canton & de Jong (2002) | B59: 2002 | C59: =+IF(A59=A58,C58,C58+1) -> 9 | D59: enrollment | E59: tuition | F59: -0.228 | G59: 0.131 | H59: 7 | I59: 48 | J59: =+I59-H59 -> 41 | K59: 20 | L59: 1950 | M59: 1999 | N59: =+L59+(M59-L59)/2 -> 1974.5 | O59: =+M59-L59+1 -> 50 | P59: =+LN(O58:O59) -> 3.912023 | Q59: 20 | R59: 4 | S59: ECM (OLS) | T59: =IF(S59="OLS",0,IF(S59="FE",0,IF(S59="Probit model",0,IF(S59="3SLS",1,IF(S59="Logit",0,IF(S59="2SLS",1,IF(S59="SUR method",1,IF(S59="Modified LS",0,IF(S59="Zenner estimates",1,IF(S59="MLE",0,IF(S59="GLS",0,0))))))))))) -> 0 | U59: 1 | V59: 1 | W59: 1 | X59: 0 | Y59: 1 | Z59: 0 | AA59: 0 | AB59: Netherlands | AC59: =IF(AB59="USA",1,IF(AB59="UK",2,IF(AB59="Canada",3,IF(AB59="Germany",4,IF(AB59="Netherlands",5,IF(AB59="India",20,IF(AB59="Indonesia",7,IF(AB59="Korea",8,IF(AB59="Philippines",9,IF(AB59="Taiwan",10,IF(AB59="Greece",11,IF(AB59="Iran",12,IF(AB59="Israel",13,IF(AB59="Kuwait",14,IF(AB59="Lebanon",15,IF(AB59="Saudi Arabia",16,IF(AB59="Turkey",17,IF(AB59="Ethiopia",18,IF(AB59="Kenya",19,IF(AB59="Nigeria",20,IF(AB59="Multinational",6,""))))))))))))))))))))) -> 5 | AD59: =IF(AB59="USA",1,0) -> 0 | AE59: 0 | AF59: 7.601902 | AG59: 3.044523 | AH59: =+F59/G59 -> -1.740458 | AI59: =AH59/SQRT(AH59^2+J59) -> -0.26229692 | AJ59: =+AI59/AH59 -> 0.15070568 | AK59: =1/AJ59^2 -> 44.029194 | AL59: =1/AJ59 -> 6.6354498 | AM59: 0 | AN59: 1 | AO59: 0 | AP59: =1/SQRT(J59) -> 0.15617376 | AQ59: 1 | AR59: 0 | AS59: 1 | AT59: 0 | AU59: 0 | AV59: 0 | AW59: =1/K59 -> 0.05 | AX59: =1/(K59*K59) -> 0.0025
A60: Canton & de Jong (2002) | B60: 2002 | C60: =+IF(A60=A59,C59,C59+1) -> 9 | D60: enrollment | E60: tuition | F60: -0.318 | G60: 0.154 | H60: 7 | I60: 47 | J60: =+I60-H60 -> 40 | K60: 20 | L60: 1950 | M60: 1999 | N60: =+L60+(M60-L60)/2 -> 1974.5 | O60: =+M60-L60+1 -> 50 | P60: =+LN(O59:O60) -> 3.912023 | Q60: 20 | R60: 4 | S60: ECM (OLS) | T60: =IF(S60="OLS",0,IF(S60="FE",0,IF(S60="Probit model",0,IF(S60="3SLS",1,IF(S60="Logit",0,IF(S60="2SLS",1,IF(S60="SUR method",1,IF(S60="Modified LS",0,IF(S60="Zenner estimates",1,IF(S60="MLE",0,IF(S60="GLS",0,0))))))))))) -> 0 | U60: 1 | V60: 1 | W60: 1 | X60: 0 | Y60: 1 | Z60: 0 | AA60: 0 | AB60: Netherlands | AC60: =IF(AB60="USA",1,IF(AB60="UK",2,IF(AB60="Canada",3,IF(AB60="Germany",4,IF(AB60="Netherlands",5,IF(AB60="India",20,IF(AB60="Indonesia",7,IF(AB60="Korea",8,IF(AB60="Philippines",9,IF(AB60="Taiwan",10,IF(AB60="Greece",11,IF(AB60="Iran",12,IF(AB60="Israel",13,IF(AB60="Kuwait",14,IF(AB60="Lebanon",15,IF(AB60="Saudi Arabia",16,IF(AB60="Turkey",17,IF(AB60="Ethiopia",18,IF(AB60="Kenya",19,IF(AB60="Nigeria",20,IF(AB60="Multinational",6,""))))))))))))))))))))) -> 5 | AD60: =IF(AB60="USA",1,0) -> 0 | AE60: 0 | AF60: 7.601902 | AG60: 3.044523 | AH60: =+F60/G60 -> -2.0649351 | AI60: =AH60/SQRT(AH60^2+J60) -> -0.3103711 | AJ60: =+AI60/AH60 -> 0.1503055 | AK60: =1/AJ60^2 -> 44.263957 | AL60: =1/AJ60 -> 6.6531163 | AM60: 0 | AN60: 1 | AO60: 0 | AP60: =1/SQRT(J60) -> 0.15811388 | AQ60: 1 | AR60: 0 | AS60: 1 | AT60: 0 | AU60: 0 | AV60: 0 | AW60: =1/K60 -> 0.05 | AX60: =1/(K60*K60) -> 0.0025
A61: Canton & de Jong (2002) | B61: 2002 | C61: =+IF(A61=A60,C60,C60+1) -> 9 | D61: enrollment | E61: tuition | F61: -0.044 | G61: 0.13 | H61: 7 | I61: 47 | J61: =+I61-H61 -> 40 | K61: 20 | L61: 1950 | M61: 1999 | N61: =+L61+(M61-L61)/2 -> 1974.5 | O61: =+M61-L61+1 -> 50 | P61: =+LN(O60:O61) -> 3.912023 | Q61: 20 | R61: 4 | S61: ECM (OLS) | T61: =IF(S61="OLS",0,IF(S61="FE",0,IF(S61="Probit model",0,IF(S61="3SLS",1,IF(S61="Logit",0,IF(S61="2SLS",1,IF(S61="SUR method",1,IF(S61="Modified LS",0,IF(S61="Zenner estimates",1,IF(S61="MLE",0,IF(S61="GLS",0,0))))))))))) -> 0 | U61: 1 | V61: 1 | W61: 1 | X61: 0 | Y61: 1 | Z61: 0 | AA61: 0 | AB61: Netherlands | AC61: =IF(AB61="USA",1,IF(AB61="UK",2,IF(AB61="Canada",3,IF(AB61="Germany",4,IF(AB61="Netherlands",5,IF(AB61="India",20,IF(AB61="Indonesia",7,IF(AB61="Korea",8,IF(AB61="Philippines",9,IF(AB61="Taiwan",10,IF(AB61="Greece",11,IF(AB61="Iran",12,IF(AB61="Israel",13,IF(AB61="Kuwait",14,IF(AB61="Lebanon",15,IF(AB61="Saudi Arabia",16,IF(AB61="Turkey",17,IF(AB61="Ethiopia",18,IF(AB61="Kenya",19,IF(AB61="Nigeria",20,IF(AB61="Multinational",6,""))))))))))))))))))))) -> 5 | AD61: =IF(AB61="USA",1,0) -> 0 | AE61: 0 | AF61: 7.601902 | AG61: 3.044523 | AH61: =+F61/G61 -> -0.33846154 | AI61: =AH61/SQRT(AH61^2+J61) -> -0.053439001 | AJ61: =+AI61/AH61 -> 0.15788796 | AK61: =1/AJ61^2 -> 40.114556 | AL61: =1/AJ61 -> 6.3336053 | AM61: 0 | AN61: 1 | AO61: 0 | AP61: =1/SQRT(J61) -> 0.15811388 | AQ61: 1 | AR61: 0 | AS61: 1 | AT61: 0 | AU61: 0 | AV61: 0 | AW61: =1/K61 -> 0.05 | AX61: =1/(K61*K61) -> 0.0025
A62: Canton & de Jong (2002) | B62: 2002 | C62: =+IF(A62=A61,C61,C61+1) -> 9 | D62: enrollment | E62: tuition | F62: -0.01 | G62: 0.136 | H62: 6 | I62: 48 | J62: =+I62-H62 -> 42 | K62: 20 | L62: 1950 | M62: 1999 | N62: =+L62+(M62-L62)/2 -> 1974.5 | O62: =+M62-L62+1 -> 50 | P62: =+LN(O61:O62) -> 3.912023 | Q62: 20 | R62: 4 | S62: ECM (OLS) | T62: =IF(S62="OLS",0,IF(S62="FE",0,IF(S62="Probit model",0,IF(S62="3SLS",1,IF(S62="Logit",0,IF(S62="2SLS",1,IF(S62="SUR method",1,IF(S62="Modified LS",0,IF(S62="Zenner estimates",1,IF(S62="MLE",0,IF(S62="GLS",0,0))))))))))) -> 0 | U62: 1 | V62: 1 | W62: 0 | X62: 0 | Y62: 1 | Z62: 0 | AA62: 0 | AB62: Netherlands | AC62: =IF(AB62="USA",1,IF(AB62="UK",2,IF(AB62="Canada",3,IF(AB62="Germany",4,IF(AB62="Netherlands",5,IF(AB62="India",20,IF(AB62="Indonesia",7,IF(AB62="Korea",8,IF(AB62="Philippines",9,IF(AB62="Taiwan",10,IF(AB62="Greece",11,IF(AB62="Iran",12,IF(AB62="Israel",13,IF(AB62="Kuwait",14,IF(AB62="Lebanon",15,IF(AB62="Saudi Arabia",16,IF(AB62="Turkey",17,IF(AB62="Ethiopia",18,IF(AB62="Kenya",19,IF(AB62="Nigeria",20,IF(AB62="Multinational",6,""))))))))))))))))))))) -> 5 | AD62: =IF(AB62="USA",1,0) -> 0 | AE62: 0 | AF62: 7.601902 | AG62: 3.044523 | AH62: =+F62/G62 -> -0.073529412 | AI62: =AH62/SQRT(AH62^2+J62) -> -0.011345104 | AJ62: =+AI62/AH62 -> 0.15429342 | AK62: =1/AJ62^2 -> 42.005407 | AL62: =1/AJ62 -> 6.4811578 | AM62: 0 | AN62: 1 | AO62: 0 | AP62: =1/SQRT(J62) -> 0.15430335 | AQ62: 1 | AR62: 0 | AS62: 0 | AT62: 1 | AU62: 0 | AV62: 0 | AW62: =1/K62 -> 0.05 | AX62: =1/(K62*K62) -> 0.0025
A63: Canton & de Jong (2002) | B63: 2002 | C63: =+IF(A63=A62,C62,C62+1) -> 9 | D63: enrollment | E63: tuition | F63: -0.076 | G63: 0.159 | H63: 6 | I63: 47 | J63: =+I63-H63 -> 41 | K63: 20 | L63: 1950 | M63: 1999 | N63: =+L63+(M63-L63)/2 -> 1974.5 | O63: =+M63-L63+1 -> 50 | P63: =+LN(O62:O63) -> 3.912023 | Q63: 20 | R63: 4 | S63: ECM (OLS) | T63: =IF(S63="OLS",0,IF(S63="FE",0,IF(S63="Probit model",0,IF(S63="3SLS",1,IF(S63="Logit",0,IF(S63="2SLS",1,IF(S63="SUR method",1,IF(S63="Modified LS",0,IF(S63="Zenner estimates",1,IF(S63="MLE",0,IF(S63="GLS",0,0))))))))))) -> 0 | U63: 1 | V63: 1 | W63: 0 | X63: 0 | Y63: 1 | Z63: 0 | AA63: 0 | AB63: Netherlands | AC63: =IF(AB63="USA",1,IF(AB63="UK",2,IF(AB63="Canada",3,IF(AB63="Germany",4,IF(AB63="Netherlands",5,IF(AB63="India",20,IF(AB63="Indonesia",7,IF(AB63="Korea",8,IF(AB63="Philippines",9,IF(AB63="Taiwan",10,IF(AB63="Greece",11,IF(AB63="Iran",12,IF(AB63="Israel",13,IF(AB63="Kuwait",14,IF(AB63="Lebanon",15,IF(AB63="Saudi Arabia",16,IF(AB63="Turkey",17,IF(AB63="Ethiopia",18,IF(AB63="Kenya",19,IF(AB63="Nigeria",20,IF(AB63="Multinational",6,""))))))))))))))))))))) -> 5 | AD63: =IF(AB63="USA",1,0) -> 0 | AE63: 0 | AF63: 7.601902 | AG63: 3.044523 | AH63: =+F63/G63 -> -0.47798742 | AI63: =AH63/SQRT(AH63^2+J63) -> -0.074441968 | AJ63: =+AI63/AH63 -> 0.15574043 | AK63: =1/AJ63^2 -> 41.228472 | AL63: =1/AJ63 -> 6.4209401 | AM63: 0 | AN63: 1 | AO63: 0 | AP63: =1/SQRT(J63) -> 0.15617376 | AQ63: 1 | AR63: 0 | AS63: 0 | AT63: 1 | AU63: 0 | AV63: 0 | AW63: =1/K63 -> 0.05 | AX63: =1/(K63*K63) -> 0.0025
A64: Canton & de Jong (2002) | B64: 2002 | C64: =+IF(A64=A63,C63,C63+1) -> 9 | D64: enrollment | E64: tuition | F64: -0.149 | G64: 0.142 | H64: 7 | I64: 48 | J64: =+I64-H64 -> 41 | K64: 20 | L64: 1950 | M64: 1999 | N64: =+L64+(M64-L64)/2 -> 1974.5 | O64: =+M64-L64+1 -> 50 | P64: =+LN(O63:O64) -> 3.912023 | Q64: 20 | R64: 4 | S64: ECM (OLS) | T64: =IF(S64="OLS",0,IF(S64="FE",0,IF(S64="Probit model",0,IF(S64="3SLS",1,IF(S64="Logit",0,IF(S64="2SLS",1,IF(S64="SUR method",1,IF(S64="Modified LS",0,IF(S64="Zenner estimates",1,IF(S64="MLE",0,IF(S64="GLS",0,0))))))))))) -> 0 | U64: 1 | V64: 1 | W64: 1 | X64: 0 | Y64: 1 | Z64: 0 | AA64: 0 | AB64: Netherlands | AC64: =IF(AB64="USA",1,IF(AB64="UK",2,IF(AB64="Canada",3,IF(AB64="Germany",4,IF(AB64="Netherlands",5,IF(AB64="India",20,IF(AB64="Indonesia",7,IF(AB64="Korea",8,IF(AB64="Philippines",9,IF(AB64="Taiwan",10,IF(AB64="Greece",11,IF(AB64="Iran",12,IF(AB64="Israel",13,IF(AB64="Kuwait",14,IF(AB64="Lebanon",15,IF(AB64="Saudi Arabia",16,IF(AB64="Turkey",17,IF(AB64="Ethiopia",18,IF(AB64="Kenya",19,IF(AB64="Nigeria",20,IF(AB64="Multinational",6,""))))))))))))))))))))) -> 5 | AD64: =IF(AB64="USA",1,0) -> 0 | AE64: 0 | AF64: 7.601902 | AG64: 3.044523 | AH64: =+F64/G64 -> -1.0492958 | AI64: =AH64/SQRT(AH64^2+J64) -> -0.16171548 | AJ64: =+AI64/AH64 -> 0.15411811 | AK64: =1/AJ64^2 -> 42.101022 | AL64: =1/AJ64 -> 6.48853 | AM64: 0 | AN64: 1 | AO64: 0 | AP64: =1/SQRT(J64) -> 0.15617376 | AQ64: 1 | AR64: 0 | AS64: 0 | AT64: 1 | AU64: 0 | AV64: 0 | AW64: =1/K64 -> 0.05 | AX64: =1/(K64*K64) -> 0.0025
A65: Canton & de Jong (2002) | B65: 2002 | C65: =+IF(A65=A64,C64,C64+1) -> 9 | D65: enrollment | E65: tuition | F65: -0.185 | G65: 0.143 | H65: 7 | I65: 47 | J65: =+I65-H65 -> 40 | K65: 20 | L65: 1950 | M65: 1999 | N65: =+L65+(M65-L65)/2 -> 1974.5 | O65: =+M65-L65+1 -> 50 | P65: =+LN(O64:O65) -> 3.912023 | Q65: 20 | R65: 4 | S65: ECM (OLS) | T65: =IF(S65="OLS",0,IF(S65="FE",0,IF(S65="Probit model",0,IF(S65="3SLS",1,IF(S65="Logit",0,IF(S65="2SLS",1,IF(S65="SUR method",1,IF(S65="Modified LS",0,IF(S65="Zenner estimates",1,IF(S65="MLE",0,IF(S65="GLS",0,0))))))))))) -> 0 | U65: 1 | V65: 1 | W65: 1 | X65: 0 | Y65: 1 | Z65: 0 | AA65: 0 | AB65: Netherlands | AC65: =IF(AB65="USA",1,IF(AB65="UK",2,IF(AB65="Canada",3,IF(AB65="Germany",4,IF(AB65="Netherlands",5,IF(AB65="India",20,IF(AB65="Indonesia",7,IF(AB65="Korea",8,IF(AB65="Philippines",9,IF(AB65="Taiwan",10,IF(AB65="Greece",11,IF(AB65="Iran",12,IF(AB65="Israel",13,IF(AB65="Kuwait",14,IF(AB65="Lebanon",15,IF(AB65="Saudi Arabia",16,IF(AB65="Turkey",17,IF(AB65="Ethiopia",18,IF(AB65="Kenya",19,IF(AB65="Nigeria",20,IF(AB65="Multinational",6,""))))))))))))))))))))) -> 5 | AD65: =IF(AB65="USA",1,0) -> 0 | AE65: 0 | AF65: 7.601902 | AG65: 3.044523 | AH65: =+F65/G65 -> -1.2937063 | AI65: =AH65/SQRT(AH65^2+J65) -> -0.20040326 | AJ65: =+AI65/AH65 -> 0.1549063 | AK65: =1/AJ65^2 -> 41.673676 | AL65: =1/AJ65 -> 6.4555152 | AM65: 0 | AN65: 1 | AO65: 0 | AP65: =1/SQRT(J65) -> 0.15811388 | AQ65: 1 | AR65: 0 | AS65: 0 | AT65: 1 | AU65: 0 | AV65: 0 | AW65: =1/K65 -> 0.05 | AX65: =1/(K65*K65) -> 0.0025
A66: Canton & de Jong (2002) | B66: 2002 | C66: =+IF(A66=A65,C65,C65+1) -> 9 | D66: enrollment | E66: tuition | F66: 0.026 | G66: 0.121 | H66: 7 | I66: 47 | J66: =+I66-H66 -> 40 | K66: 20 | L66: 1950 | M66: 1999 | N66: =+L66+(M66-L66)/2 -> 1974.5 | O66: =+M66-L66+1 -> 50 | P66: =+LN(O65:O66) -> 3.912023 | Q66: 20 | R66: 4 | S66: ECM (OLS) | T66: =IF(S66="OLS",0,IF(S66="FE",0,IF(S66="Probit model",0,IF(S66="3SLS",1,IF(S66="Logit",0,IF(S66="2SLS",1,IF(S66="SUR method",1,IF(S66="Modified LS",0,IF(S66="Zenner estimates",1,IF(S66="MLE",0,IF(S66="GLS",0,0))))))))))) -> 0 | U66: 1 | V66: 1 | W66: 1 | X66: 0 | Y66: 1 | Z66: 0 | AA66: 0 | AB66: Netherlands | AC66: =IF(AB66="USA",1,IF(AB66="UK",2,IF(AB66="Canada",3,IF(AB66="Germany",4,IF(AB66="Netherlands",5,IF(AB66="India",20,IF(AB66="Indonesia",7,IF(AB66="Korea",8,IF(AB66="Philippines",9,IF(AB66="Taiwan",10,IF(AB66="Greece",11,IF(AB66="Iran",12,IF(AB66="Israel",13,IF(AB66="Kuwait",14,IF(AB66="Lebanon",15,IF(AB66="Saudi Arabia",16,IF(AB66="Turkey",17,IF(AB66="Ethiopia",18,IF(AB66="Kenya",19,IF(AB66="Nigeria",20,IF(AB66="Multinational",6,""))))))))))))))))))))) -> 5 | AD66: =IF(AB66="USA",1,0) -> 0 | AE66: 0 | AF66: 7.601902 | AG66: 3.044523 | AH66: =+F66/G66 -> 0.21487603 | AI66: =AH66/SQRT(AH66^2+J66) -> 0.033955292 | AJ66: =+AI66/AH66 -> 0.15802271 | AK66: =1/AJ66^2 -> 40.046172 | AL66: =1/AJ66 -> 6.3282045 | AM66: 0 | AN66: 1 | AO66: 0 | AP66: =1/SQRT(J66) -> 0.15811388 | AQ66: 1 | AR66: 0 | AS66: 0 | AT66: 1 | AU66: 0 | AV66: 0 | AW66: =1/K66 -> 0.05 | AX66: =1/(K66*K66) -> 0.0025
A67: Canton & de Jong (2002) | B67: 2002 | C67: =+IF(A67=A66,C66,C66+1) -> 9 | D67: enrollment | E67: tuition | F67: -0.102 | G67: 0.167 | H67: 6 | I67: 48 | J67: =+I67-H67 -> 42 | K67: 20 | L67: 1950 | M67: 1999 | N67: =+L67+(M67-L67)/2 -> 1974.5 | O67: =+M67-L67+1 -> 50 | P67: =+LN(O66:O67) -> 3.912023 | Q67: 20 | R67: 4 | S67: ECM (OLS) | T67: =IF(S67="OLS",0,IF(S67="FE",0,IF(S67="Probit model",0,IF(S67="3SLS",1,IF(S67="Logit",0,IF(S67="2SLS",1,IF(S67="SUR method",1,IF(S67="Modified LS",0,IF(S67="Zenner estimates",1,IF(S67="MLE",0,IF(S67="GLS",0,0))))))))))) -> 0 | U67: 1 | V67: 1 | W67: 0 | X67: 0 | Y67: 1 | Z67: 0 | AA67: 0 | AB67: Netherlands | AC67: =IF(AB67="USA",1,IF(AB67="UK",2,IF(AB67="Canada",3,IF(AB67="Germany",4,IF(AB67="Netherlands",5,IF(AB67="India",20,IF(AB67="Indonesia",7,IF(AB67="Korea",8,IF(AB67="Philippines",9,IF(AB67="Taiwan",10,IF(AB67="Greece",11,IF(AB67="Iran",12,IF(AB67="Israel",13,IF(AB67="Kuwait",14,IF(AB67="Lebanon",15,IF(AB67="Saudi Arabia",16,IF(AB67="Turkey",17,IF(AB67="Ethiopia",18,IF(AB67="Kenya",19,IF(AB67="Nigeria",20,IF(AB67="Multinational",6,""))))))))))))))))))))) -> 5 | AD67: =IF(AB67="USA",1,0) -> 0 | AE67: 0 | AF67: 7.601902 | AG67: 3.044523 | AH67: =+F67/G67 -> -0.61077844 | AI67: =AH67/SQRT(AH67^2+J67) -> -0.093829378 | AJ67: =+AI67/AH67 -> 0.15362261 | AK67: =1/AJ67^2 -> 42.37305 | AL67: =1/AJ67 -> 6.5094585 | AM67: 0 | AN67: 1 | AO67: 0 | AP67: =1/SQRT(J67) -> 0.15430335 | AQ67: 1 | AR67: 0 | AS67: 0 | AT67: 0 | AU67: 0 | AV67: 0 | AW67: =1/K67 -> 0.05 | AX67: =1/(K67*K67) -> 0.0025
A68: Canton & de Jong (2002) | B68: 2002 | C68: =+IF(A68=A67,C67,C67+1) -> 9 | D68: enrollment | E68: tuition | F68: -0.294 | G68: 0.247 | H68: 6 | I68: 47 | J68: =+I68-H68 -> 41 | K68: 20 | L68: 1950 | M68: 1999 | N68: =+L68+(M68-L68)/2 -> 1974.5 | O68: =+M68-L68+1 -> 50 | P68: =+LN(O67:O68) -> 3.912023 | Q68: 20 | R68: 4 | S68: ECM (OLS) | T68: =IF(S68="OLS",0,IF(S68="FE",0,IF(S68="Probit model",0,IF(S68="3SLS",1,IF(S68="Logit",0,IF(S68="2SLS",1,IF(S68="SUR method",1,IF(S68="Modified LS",0,IF(S68="Zenner estimates",1,IF(S68="MLE",0,IF(S68="GLS",0,0))))))))))) -> 0 | U68: 1 | V68: 1 | W68: 0 | X68: 0 | Y68: 1 | Z68: 0 | AA68: 0 | AB68: Netherlands | AC68: =IF(AB68="USA",1,IF(AB68="UK",2,IF(AB68="Canada",3,IF(AB68="Germany",4,IF(AB68="Netherlands",5,IF(AB68="India",20,IF(AB68="Indonesia",7,IF(AB68="Korea",8,IF(AB68="Philippines",9,IF(AB68="Taiwan",10,IF(AB68="Greece",11,IF(AB68="Iran",12,IF(AB68="Israel",13,IF(AB68="Kuwait",14,IF(AB68="Lebanon",15,IF(AB68="Saudi Arabia",16,IF(AB68="Turkey",17,IF(AB68="Ethiopia",18,IF(AB68="Kenya",19,IF(AB68="Nigeria",20,IF(AB68="Multinational",6,""))))))))))))))))))))) -> 5 | AD68: =IF(AB68="USA",1,0) -> 0 | AE68: 0 | AF68: 7.601902 | AG68: 3.044523 | AH68: =+F68/G68 -> -1.1902834 | AI68: =AH68/SQRT(AH68^2+J68) -> -0.18276017 | AJ68: =+AI68/AH68 -> 0.15354341 | AK68: =1/AJ68^2 -> 42.416775 | AL68: =1/AJ68 -> 6.5128162 | AM68: 0 | AN68: 1 | AO68: 0 | AP68: =1/SQRT(J68) -> 0.15617376 | AQ68: 1 | AR68: 0 | AS68: 0 | AT68: 0 | AU68: 0 | AV68: 0 | AW68: =1/K68 -> 0.05 | AX68: =1/(K68*K68) -> 0.0025
... A71: Canton & de Jong (2002) | B71: 2002 | C71: =+IF(A71=A70,C70,C70+1) -> 9 | D71: enrollment | E71: tuition | F71: -0.016 | G71: 0.128 | H71: 7 | I71: 47 | J71: =+I71-H71 -> 40 | K71: 20 | L71: 1950 | M71: 1999 | N71: =+L71+(M71-L71)/2 -> 1974.5 | O71: =+M71-L71+1 -> 50 | P71: =+LN(O70:O71) -> 3.912023 | Q71: 20 | R71: 4 | S71: ECM (OLS) | T71: =IF(S71="OLS",0,IF(S71="FE",0,IF(S71="Probit model",0,IF(S71="3SLS",1,IF(S71="Logit",0,IF(S71="2SLS",1,IF(S71="SUR method",1,IF(S71="Modified LS",0,IF(S71="Zenner estimates",1,IF(S71="MLE",0,IF(S71="GLS",0,0))))))))))) -> 0 | U71: 1 | V71: 1 | W71: 1 | X71: 0 | Y71: 1 | Z71: 0 | AA71: 0 | AB71: Netherlands | AC71: =IF(AB71="USA",1,IF(AB71="UK",2,IF(AB71="Canada",3,IF(AB71="Germany",4,IF(AB71="Netherlands",5,IF(AB71="India",20,IF(AB71="Indonesia",7,IF(AB71="Korea",8,IF(AB71="Philippines",9,IF(AB71="Taiwan",10,IF(AB71="Greece",11,IF(AB71="Iran",12,IF(AB71="Israel",13,IF(AB71="Kuwait",14,IF(AB71="Lebanon",15,IF(AB71="Saudi Arabia",16,IF(AB71="Turkey",17,IF(AB71="Ethiopia",18,IF(AB71="Kenya",19,IF(AB71="Nigeria",20,IF(AB71="Multinational",6,""))))))))))))))))))))) -> 5 | AD71: =IF(AB71="USA",1,0) -> 0 | AE71: 0 | AF71: 7.601902 | AG71: 3.044523 | AH71: =+F71/G71 -> -0.125 | AI71: =AH71/SQRT(AH71^2+J71) -> -0.019760376 | AJ71: =+AI71/AH71 -> 0.15808301 | AK71: =1/AJ71^2 -> 40.015625 | AL71: =1/AJ71 -> 6.3257905 | AM71: 0 | AN71: 1 | AO71: 0 | AP71: =1/SQRT(J71) -> 0.15811388 | AQ71: 1 | AR71: 0 | AS71: 0 | AT71: 0 | AU71: 0 | AV71: 0 | AW71: =1/K71 -> 0.05 | AX71: =1/(K71*K71) -> 0.0025
A72: Canton & de Jong (2002) | B72: 2002 | C72: =+IF(A72=A71,C71,C71+1) -> 9 | D72: enrollment | E72: tuition | F72: -0.078 | G72: 0.298 | H72: 6 | I72: 384 | J72: =+I72-H72 -> 378 | K72: 20 | L72: 1950 | M72: 1999 | N72: =+L72+(M72-L72)/2 -> 1974.5 | O72: =+M72-L72+1 -> 50 | P72: =+LN(O71:O72) -> 3.912023 | Q72: 20 | R72: 4 | S72: ECM (SUR) | T72: 1 | U72: 1 | V72: 1 | W72: 0 | X72: 0 | Y72: 1 | Z72: 0 | AA72: 0 | AB72: Netherlands | AC72: =IF(AB72="USA",1,IF(AB72="UK",2,IF(AB72="Canada",3,IF(AB72="Germany",4,IF(AB72="Netherlands",5,IF(AB72="India",20,IF(AB72="Indonesia",7,IF(AB72="Korea",8,IF(AB72="Philippines",9,IF(AB72="Taiwan",10,IF(AB72="Greece",11,IF(AB72="Iran",12,IF(AB72="Israel",13,IF(AB72="Kuwait",14,IF(AB72="Lebanon",15,IF(AB72="Saudi Arabia",16,IF(AB72="Turkey",17,IF(AB72="Ethiopia",18,IF(AB72="Kenya",19,IF(AB72="Nigeria",20,IF(AB72="Multinational",6,""))))))))))))))))))))) -> 5 | AD72: =IF(AB72="USA",1,0) -> 0 | AE72: 0 | AF72: 7.601902 | AG72: 3.044523 | AH72: =+F72/G72 -> -0.26174497 | AI72: =AH72/SQRT(AH72^2+J72) -> -0.013461489 | AJ72: =+AI72/AH72 -> 0.05142979 | AK72: =1/AJ72^2 -> 378.06851 | AL72: =1/AJ72 -> 19.443984 | AM72: 0 | AN72: 1 | AO72: 0 | AP72: =1/SQRT(J72) -> 0.05143445 | AQ72: 0 | AR72: 0 | AS72: 0 | AT72: 0 | AU72: 0 | AV72: 0 | AW72: =1/K72 -> 0.05 | AX72: =1/(K72*K72) -> 0.0025
A73: Canton & de Jong (2002) | B73: 2002 | C73: =+IF(A73=A72,C72,C72+1) -> 9 | D73: enrollment | E73: tuition | F73: 0.06 | G73: 0.154 | H73: 6 | I73: 384 | J73: =+I73-H73 -> 378 | K73: 20 | L73: 1950 | M73: 1999 | N73: =+L73+(M73-L73)/2 -> 1974.5 | O73: =+M73-L73+1 -> 50 | P73: =+LN(O72:O73) -> 3.912023 | Q73: 20 | R73: 4 | S73: ECM (SUR) | T73: 1 | U73: 1 | V73: 1 | W73: 0 | X73: 0 | Y73: 1 | Z73: 0 | AA73: 0 | AB73: Netherlands | AC73: =IF(AB73="USA",1,IF(AB73="UK",2,IF(AB73="Canada",3,IF(AB73="Germany",4,IF(AB73="Netherlands",5,IF(AB73="India",20,IF(AB73="Indonesia",7,IF(AB73="Korea",8,IF(AB73="Philippines",9,IF(AB73="Taiwan",10,IF(AB73="Greece",11,IF(AB73="Iran",12,IF(AB73="Israel",13,IF(AB73="Kuwait",14,IF(AB73="Lebanon",15,IF(AB73="Saudi Arabia",16,IF(AB73="Turkey",17,IF(AB73="Ethiopia",18,IF(AB73="Kenya",19,IF(AB73="Nigeria",20,IF(AB73="Multinational",6,""))))))))))))))))))))) -> 5 | AD73: =IF(AB73="USA",1,0) -> 0 | AE73: 0 | AF73: 7.601902 | AG73: 3.044523 | AH73: =+F73/G73 -> 0.38961039 | AI73: =AH73/SQRT(AH73^2+J73) -> 0.020035374 | AJ73: =+AI73/AH73 -> 0.051424126 | AK73: =1/AJ73^2 -> 378.1518 | AL73: =1/AJ73 -> 19.446125 | AM73: 0 | AN73: 1 | AO73: 0 | AP73: =1/SQRT(J73) -> 0.05143445 | AQ73: 0 | AR73: 0 | AS73: 0 | AT73: 0 | AU73: 0 | AV73: 0 | AW73: =1/K73 -> 0.05 | AX73: =1/(K73*K73) -> 0.0025
A74: Canton & de Jong (2002) | B74: 2002 | C74: =+IF(A74=A73,C73,C73+1) -> 9 | D74: enrollment | E74: tuition | F74: 0.093 | G74: 0.224 | H74: 6 | I74: 384 | J74: =+I74-H74 -> 378 | K74: 20 | L74: 1950 | M74: 1999 | N74: =+L74+(M74-L74)/2 -> 1974.5 | O74: =+M74-L74+1 -> 50 | P74: =+LN(O73:O74) -> 3.912023 | Q74: 20 | R74: 4 | S74: ECM (SUR) | T74: 1 | U74: 1 | V74: 1 | W74: 0 | X74: 0 | Y74: 1 | Z74: 0 | AA74: 0 | AB74: Netherlands | AC74: =IF(AB74="USA",1,IF(AB74="UK",2,IF(AB74="Canada",3,IF(AB74="Germany",4,IF(AB74="Netherlands",5,IF(AB74="India",20,IF(AB74="Indonesia",7,IF(AB74="Korea",8,IF(AB74="Philippines",9,IF(AB74="Taiwan",10,IF(AB74="Greece",11,IF(AB74="Iran",12,IF(AB74="Israel",13,IF(AB74="Kuwait",14,IF(AB74="Lebanon",15,IF(AB74="Saudi Arabia",16,IF(AB74="Turkey",17,IF(AB74="Ethiopia",18,IF(AB74="Kenya",19,IF(AB74="Nigeria",20,IF(AB74="Multinational",6,""))))))))))))))))))))) -> 5 | AD74: =IF(AB74="USA",1,0) -> 0 | AE74: 0 | AF74: 7.601902 | AG74: 3.044523 | AH74: =+F74/G74 -> 0.41517857 | AI74: =AH74/SQRT(AH74^2+J74) -> 0.021349614 | AJ74: =+AI74/AH74 -> 0.051422727 | AK74: =1/AJ74^2 -> 378.17237 | AL74: =1/AJ74 -> 19.446655 | AM74: 0 | AN74: 1 | AO74: 0 | AP74: =1/SQRT(J74) -> 0.05143445 | AQ74: 0 | AR74: 0 | AS74: 0 | AT74: 0 | AU74: 0 | AV74: 0 | AW74: =1/K74 -> 0.05 | AX74: =1/(K74*K74) -> 0.0025
A75: Chen (2016) | B75: 2016 | C75: =+IF(A75=A74,C74,C74+1) -> 10 | D75: enrollment | E75: tuition | F75: -0.3532 | G75: 0.04772973 | H75: 2 | I75: 13 | J75: =+I75-H75 -> 11 | K75: 4 | L75: 2001 | M75: 2013 | N75: =+L75+(M75-L75)/2 -> 2007 | O75: =+M75-L75+1 -> 13 | P75: =+LN(O74:O75) -> 2.5649494 | Q75: 0 | R75: 0 | S75: OLS | T75: =IF(S75="OLS",0,IF(S75="FE",0,IF(S75="Probit model",0,IF(S75="3SLS",1,IF(S75="Logit",0,IF(S75="2SLS",1,IF(S75="SUR method",1,IF(S75="Modified LS",0,IF(S75="Zenner estimates",1,IF(S75="MLE",0,IF(S75="GLS",0,0))))))))))) -> 0 | U75: 0 | V75: 0 | W75: 0 | X75: 0 | Y75: 1 | Z75: 0 | AA75: 0 | AB75: USA | AC75: =IF(AB75="USA",1,IF(AB75="UK",2,IF(AB75="Canada",3,IF(AB75="Germany",4,IF(AB75="Netherlands",5,IF(AB75="India",20,IF(AB75="Indonesia",7,IF(AB75="Korea",8,IF(AB75="Philippines",9,IF(AB75="Taiwan",10,IF(AB75="Greece",11,IF(AB75="Iran",12,IF(AB75="Israel",13,IF(AB75="Kuwait",14,IF(AB75="Lebanon",15,IF(AB75="Saudi Arabia",16,IF(AB75="Turkey",17,IF(AB75="Ethiopia",18,IF(AB75="Kenya",19,IF(AB75="Nigeria",20,IF(AB75="Multinational",6,""))))))))))))))))))))) -> 1 | AD75: =IF(AB75="USA",1,0) -> 1 | AE75: 1 | AF75: 7.608871 | AG75: 0 | AH75: =+F75/G75 -> -7.4 | AI75: =AH75/SQRT(AH75^2+J75) -> -0.9125377 | AJ75: =+AI75/AH75 -> 0.12331591 | AK75: =1/AJ75^2 -> 65.76 | AL75: =1/AJ75 -> 8.109254 | AM75: 1 | AN75: 0 | AO75: 0 | AP75: =1/SQRT(J75) -> 0.30151134 | AQ75: 1 | AR75: 0 | AS75: 0 | AT75: 0 | AU75: 0 | AV75: 1 | AW75: =1/K75 -> 0.25 | AX75: =1/(K75*K75) -> 0.0625
A76: Chen (2016) | B76: 2016 | C76: =+IF(A76=A75,C75,C75+1) -> 10 | D76: enrollment | E76: tuition | F76: -0.9369 | G76: 0.15308824 | H76: 2 | I76: 13 | J76: =+I76-H76 -> 11 | K76: 4 | L76: 2001 | M76: 2013 | N76: =+L76+(M76-L76)/2 -> 2007 | O76: =+M76-L76+1 -> 13 | P76: =+LN(O75:O76) -> 2.5649494 | Q76: 0 | R76: 0 | S76: OLS | T76: =IF(S76="OLS",0,IF(S76="FE",0,IF(S76="Probit model",0,IF(S76="3SLS",1,IF(S76="Logit",0,IF(S76="2SLS",1,IF(S76="SUR method",1,IF(S76="Modified LS",0,IF(S76="Zenner estimates",1,IF(S76="MLE",0,IF(S76="GLS",0,0))))))))))) -> 0 | U76: 0 | V76: 0 | W76: 0 | X76: 0 | Y76: 1 | Z76: 0 | AA76: 0 | AB76: USA | AC76: =IF(AB76="USA",1,IF(AB76="UK",2,IF(AB76="Canada",3,IF(AB76="Germany",4,IF(AB76="Netherlands",5,IF(AB76="India",20,IF(AB76="Indonesia",7,IF(AB76="Korea",8,IF(AB76="Philippines",9,IF(AB76="Taiwan",10,IF(AB76="Greece",11,IF(AB76="Iran",12,IF(AB76="Israel",13,IF(AB76="Kuwait",14,IF(AB76="Lebanon",15,IF(AB76="Saudi Arabia",16,IF(AB76="Turkey",17,IF(AB76="Ethiopia",18,IF(AB76="Kenya",19,IF(AB76="Nigeria",20,IF(AB76="Multinational",6,""))))))))))))))))))))) -> 1 | AD76: =IF(AB76="USA",1,0) -> 1 | AE76: 1 | AF76: 7.608871 | AG76: 0 | AH76: =+F76/G76 -> -6.12 | AI76: =AH76/SQRT(AH76^2+J76) -> -0.8791942 | AJ76: =+AI76/AH76 -> 0.14365918 | AK76: =1/AJ76^2 -> 48.4544 | AL76: =1/AJ76 -> 6.9609195 | AM76: 1 | AN76: 0 | AO76: 0 | AP76: =1/SQRT(J76) -> 0.30151134 | AQ76: 1 | AR76: 0 | AS76: 0 | AT76: 0 | AU76: 0 | AV76: 1 | AW76: =1/K76 -> 0.25 | AX76: =1/(K76*K76) -> 0.0625
A77: Chen (2016) | B77: 2016 | C77: =+IF(A77=A76,C76,C76+1) -> 10 | D77: enrollment | E77: tuition | F77: -1.0999 | G77: 0.20181651 | H77: 2 | I77: 13 | J77: =+I77-H77 -> 11 | K77: 4 | L77: 2001 | M77: 2013 | N77: =+L77+(M77-L77)/2 -> 2007 | O77: =+M77-L77+1 -> 13 | P77: =+LN(O76:O77) -> 2.5649494 | Q77: 0 | R77: 0 | S77: OLS | T77: =IF(S77="OLS",0,IF(S77="FE",0,IF(S77="Probit model",0,IF(S77="3SLS",1,IF(S77="Logit",0,IF(S77="2SLS",1,IF(S77="SUR method",1,IF(S77="Modified LS",0,IF(S77="Zenner estimates",1,IF(S77="MLE",0,IF(S77="GLS",0,0))))))))))) -> 0 | U77: 0 | V77: 0 | W77: 0 | X77: 0 | Y77: 1 | Z77: 0 | AA77: 0 | AB77: USA | AC77: =IF(AB77="USA",1,IF(AB77="UK",2,IF(AB77="Canada",3,IF(AB77="Germany",4,IF(AB77="Netherlands",5,IF(AB77="India",20,IF(AB77="Indonesia",7,IF(AB77="Korea",8,IF(AB77="Philippines",9,IF(AB77="Taiwan",10,IF(AB77="Greece",11,IF(AB77="Iran",12,IF(AB77="Israel",13,IF(AB77="Kuwait",14,IF(AB77="Lebanon",15,IF(AB77="Saudi Arabia",16,IF(AB77="Turkey",17,IF(AB77="Ethiopia",18,IF(AB77="Kenya",19,IF(AB77="Nigeria",20,IF(AB77="Multinational",6,""))))))))))))))))))))) -> 1 | AD77: =IF(AB77="USA",1,0) -> 1 | AE77: 1 | AF77: 7.608871 | AG77: 0 | AH77: =+F77/G77 -> -5.45 | AI77: =AH77/SQRT(AH77^2+J77) -> -0.85425191 | AJ77: =+AI77/AH77 -> 0.15674347 | AK77: =1/AJ77^2 -> 40.7025 | AL77: =1/AJ77 -> 6.3798511 | AM77: 1 | AN77: 0 | AO77: 0 | AP77: =1/SQRT(J77) -> 0.30151134 | AQ77: 1 | AR77: 0 | AS77: 0 | AT77: 0 | AU77: 0 | AV77: 1 | AW77: =1/K77 -> 0.25 | AX77: =1/(K77*K77) -> 0.0625
A78: Chen (2016) | B78: 2016 | C78: =+IF(A78=A77,C77,C77+1) -> 10 | D78: enrollment | E78: tuition | F78: -1.1017 | G78: 0.16616893 | H78: 2 | I78: 13 | J78: =+I78-H78 -> 11 | K78: 4 | L78: 2001 | M78: 2013 | N78: =+L78+(M78-L78)/2 -> 2007 | O78: =+M78-L78+1 -> 13 | P78: =+LN(O77:O78) -> 2.5649494 | Q78: 0 | R78: 0 | S78: OLS | T78: =IF(S78="OLS",0,IF(S78="FE",0,IF(S78="Probit model",0,IF(S78="3SLS",1,IF(S78="Logit",0,IF(S78="2SLS",1,IF(S78="SUR method",1,IF(S78="Modified LS",0,IF(S78="Zenner estimates",1,IF(S78="MLE",0,IF(S78="GLS",0,0))))))))))) -> 0 | U78: 0 | V78: 0 | W78: 0 | X78: 0 | Y78: 1 | Z78: 0 | AA78: 0 | AB78: USA | AC78: =IF(AB78="USA",1,IF(AB78="UK",2,IF(AB78="Canada",3,IF(AB78="Germany",4,IF(AB78="Netherlands",5,IF(AB78="India",20,IF(AB78="Indonesia",7,IF(AB78="Korea",8,IF(AB78="Philippines",9,IF(AB78="Taiwan",10,IF(AB78="Greece",11,IF(AB78="Iran",12,IF(AB78="Israel",13,IF(AB78="Kuwait",14,IF(AB78="Lebanon",15,IF(AB78="Saudi Arabia",16,IF(AB78="Turkey",17,IF(AB78="Ethiopia",18,IF(AB78="Kenya",19,IF(AB78="Nigeria",20,IF(AB78="Multinational",6,""))))))))))))))))))))) -> 1 | AD78: =IF(AB78="USA",1,0) -> 1 | AE78: 1 | AF78: 7.608871 | AG78: 0 | AH78: =+F78/G78 -> -6.63 | AI78: =AH78/SQRT(AH78^2+J78) -> -0.8943395 | AJ78: =+AI78/AH78 -> 0.13489284 | AK78: =1/AJ78^2 -> 54.9569 | AL78: =1/AJ78 -> 7.4132921 | AM78: 1 | AN78: 0 | AO78: 0 | AP78: =1/SQRT(J78) -> 0.30151134 | AQ78: 1 | AR78: 0 | AS78: 0 | AT78: 0 | AU78: 0 | AV78: 1 | AW78: =1/K78 -> 0.25 | AX78: =1/(K78*K78) -> 0.0625
A79: Cheslock (2001) | B79: 2001 | C79: =+IF(A79=A78,C78,C78+1) -> 11 | D79: enrollment | E79: tuition | F79: -0.0396 | G79: 0.0094 | H79: 13 | I79: 3036 | J79: =+I79-H79 -> 3023 | K79: 16 | L79: 1984 | M79: 1997 | N79: =+L79+(M79-L79)/2 -> 1990.5 | O79: =+M79-L79+1 -> 14 | P79: =+LN(O78:O79) -> 2.6390573 | Q79: 2 | R79: 0 | S79: OLS | T79: =IF(S79="OLS",0,IF(S79="FE",0,IF(S79="Probit model",0,IF(S79="3SLS",1,IF(S79="Logit",0,IF(S79="2SLS",1,IF(S79="SUR method",1,IF(S79="Modified LS",0,IF(S79="Zenner estimates",1,IF(S79="MLE",0,IF(S79="GLS",0,0))))))))))) -> 0 | U79: 0 | V79: 0 | W79: 0 | X79: 0 | Y79: 0 | Z79: 1 | AA79: 0 | AB79: USA | AC79: =IF(AB79="USA",1,IF(AB79="UK",2,IF(AB79="Canada",3,IF(AB79="Germany",4,IF(AB79="Netherlands",5,IF(AB79="India",20,IF(AB79="Indonesia",7,IF(AB79="Korea",8,IF(AB79="Philippines",9,IF(AB79="Taiwan",10,IF(AB79="Greece",11,IF(AB79="Iran",12,IF(AB79="Israel",13,IF(AB79="Kuwait",14,IF(AB79="Lebanon",15,IF(AB79="Saudi Arabia",16,IF(AB79="Turkey",17,IF(AB79="Ethiopia",18,IF(AB79="Kenya",19,IF(AB79="Nigeria",20,IF(AB79="Multinational",6,""))))))))))))))))))))) -> 1 | AD79: =IF(AB79="USA",1,0) -> 1 | AE79: 0 | AF79: 7.601402 | AG79: 1.098612 | AH79: =+F79/G79 -> -4.212766 | AI79: =AH79/SQRT(AH79^2+J79) -> -0.076397151 | AJ79: =+AI79/AH79 -> 0.018134677 | AK79: =1/AJ79^2 -> 3040.7474 | AL79: =1/AJ79 -> 55.142972 | AM79: 1 | AN79: 0 | AO79: 0 | AP79: =1/SQRT(J79) -> 0.018187832 | AQ79: 1 | AR79: 0 | AS79: 0 | AT79: 0 | AU79: 1 | AV79: 0 | AW79: =1/K79 -> 0.0625 | AX79: =1/(K79*K79) -> 0.00390625
A80: Cheslock (2001) | B80: 2001 | C80: =+IF(A80=A79,C79,C79+1) -> 11 | D80: enrollment | E80: tuition | F80: -0.0967 | G80: 0.0349 | H80: 13 | I80: 2341 | J80: =+I80-H80 -> 2328 | K80: 16 | L80: 1984 | M80: 1997 | N80: =+L80+(M80-L80)/2 -> 1990.5 | O80: =+M80-L80+1 -> 14 | P80: =+LN(O79:O80) -> 2.6390573 | Q80: 2 | R80: 0 | S80: OLS | T80: =IF(S80="OLS",0,IF(S80="FE",0,IF(S80="Probit model",0,IF(S80="3SLS",1,IF(S80="Logit",0,IF(S80="2SLS",1,IF(S80="SUR method",1,IF(S80="Modified LS",0,IF(S80="Zenner estimates",1,IF(S80="MLE",0,IF(S80="GLS",0,0))))))))))) -> 0 | U80: 0 | V80: 0 | W80: 0 | X80: 0 | Y80: 0 | Z80: 1 | AA80: 0 | AB80: USA | AC80: =IF(AB80="USA",1,IF(AB80="UK",2,IF(AB80="Canada",3,IF(AB80="Germany",4,IF(AB80="Netherlands",5,IF(AB80="India",20,IF(AB80="Indonesia",7,IF(AB80="Korea",8,IF(AB80="Philippines",9,IF(AB80="Taiwan",10,IF(AB80="Greece",11,IF(AB80="Iran",12,IF(AB80="Israel",13,IF(AB80="Kuwait",14,IF(AB80="Lebanon",15,IF(AB80="Saudi Arabia",16,IF(AB80="Turkey",17,IF(AB80="Ethiopia",18,IF(AB80="Kenya",19,IF(AB80="Nigeria",20,IF(AB80="Multinational",6,""))))))))))))))))))))) -> 1 | AD80: =IF(AB80="USA",1,0) -> 1 | AE80: 0 | AF80: 7.601402 | AG80: 1.098612 | AH80: =+F80/G80 -> -2.7707736 | AI80: =AH80/SQRT(AH80^2+J80) -> -0.057331676 | AJ80: =+AI80/AH80 -> 0.020691577 | AK80: =1/AJ80^2 -> 2335.6772 | AL80: =1/AJ80 -> 48.328844 | AM80: 1 | AN80: 0 | AO80: 0 | AP80: =1/SQRT(J80) -> 0.020725667 | AQ80: 1 | AR80: 0 | AS80: 0 | AT80: 0 | AU80: 0 | AV80: 1 | AW80: =1/K80 -> 0.0625 | AX80: =1/(K80*K80) -> 0.00390625
A81: Cheslock (2001) | B81: 2001 | C81: =+IF(A81=A80,C80,C80+1) -> 11 | D81: enrollment | E81: tuition | F81: 0.0276 | G81: 0.0349 | H81: 11 | I81: 287 | J81: =+I81-H81 -> 276 | K81: 16 | L81: 1984 | M81: 1997 | N81: =+L81+(M81-L81)/2 -> 1990.5 | O81: =+M81-L81+1 -> 14 | P81: =+LN(O80:O81) -> 2.6390573 | Q81: 2 | R81: 0 | S81: OLS | T81: =IF(S81="OLS",0,IF(S81="FE",0,IF(S81="Probit model",0,IF(S81="3SLS",1,IF(S81="Logit",0,IF(S81="2SLS",1,IF(S81="SUR method",1,IF(S81="Modified LS",0,IF(S81="Zenner estimates",1,IF(S81="MLE",0,IF(S81="GLS",0,0))))))))))) -> 0 | U81: 0 | V81: 0 | W81: 0 | X81: 0 | Y81: 0 | Z81: 1 | AA81: 0 | AB81: USA | AC81: =IF(AB81="USA",1,IF(AB81="UK",2,IF(AB81="Canada",3,IF(AB81="Germany",4,IF(AB81="Netherlands",5,IF(AB81="India",20,IF(AB81="Indonesia",7,IF(AB81="Korea",8,IF(AB81="Philippines",9,IF(AB81="Taiwan",10,IF(AB81="Greece",11,IF(AB81="Iran",12,IF(AB81="Israel",13,IF(AB81="Kuwait",14,IF(AB81="Lebanon",15,IF(AB81="Saudi Arabia",16,IF(AB81="Turkey",17,IF(AB81="Ethiopia",18,IF(AB81="Kenya",19,IF(AB81="Nigeria",20,IF(AB81="Multinational",6,""))))))))))))))))))))) -> 1 | AD81: =IF(AB81="USA",1,0) -> 1 | AE81: 0 | AF81: 7.601402 | AG81: 1.098612 | AH81: =+F81/G81 -> 0.79083095 | AI81: =AH81/SQRT(AH81^2+J81) -> 0.047548587 | AJ81: =+AI81/AH81 -> 0.060124844 | AK81: =1/AJ81^2 -> 276.62541 | AL81: =1/AJ81 -> 16.63206 | AM81: 1 | AN81: 0 | AO81: 0 | AP81: =1/SQRT(J81) -> 0.060192927 | AQ81: 1 | AR81: 0 | AS81: 0 | AT81: 0 | AU81: 1 | AV81: 0 | AW81: =1/K81 -> 0.0625 | AX81: =1/(K81*K81) -> 0.00390625
A82: Cheslock (2001) | B82: 2001 | C82: =+IF(A82=A81,C81,C81+1) -> 11 | D82: enrollment | E82: tuition | F82: -0.0396 | G82: 0.0176 | H82: 11 | I82: 1241 | J82: =+I82-H82 -> 1230 | K82: 16 | L82: 1984 | M82: 1997 | N82: =+L82+(M82-L82)/2 -> 1990.5 | O82: =+M82-L82+1 -> 14 | P82: =+LN(O81:O82) -> 2.6390573 | Q82: 2 | R82: 0 | S82: OLS | T82: =IF(S82="OLS",0,IF(S82="FE",0,IF(S82="Probit model",0,IF(S82="3SLS",1,IF(S82="Logit",0,IF(S82="2SLS",1,IF(S82="SUR method",1,IF(S82="Modified LS",0,IF(S82="Zenner estimates",1,IF(S82="MLE",0,IF(S82="GLS",0,0))))))))))) -> 0 | U82: 0 | V82: 0 | W82: 0 | X82: 0 | Y82: 0 | Z82: 1 | AA82: 0 | AB82: USA | AC82: =IF(AB82="USA",1,IF(AB82="UK",2,IF(AB82="Canada",3,IF(AB82="Germany",4,IF(AB82="Netherlands",5,IF(AB82="India",20,IF(AB82="Indonesia",7,IF(AB82="Korea",8,IF(AB82="Philippines",9,IF(AB82="Taiwan",10,IF(AB82="Greece",11,IF(AB82="Iran",12,IF(AB82="Israel",13,IF(AB82="Kuwait",14,IF(AB82="Lebanon",15,IF(AB82="Saudi Arabia",16,IF(AB82="Turkey",17,IF(AB82="Ethiopia",18,IF(AB82="Kenya",19,IF(AB82="Nigeria",20,IF(AB82="Multinational",6,""))))))))))))))))))))) -> 1 | AD82: =IF(AB82="USA",1,0) -> 1 | AE82: 0 | AF82: 7.601402 | AG82: 1.098612 | AH82: =+F82/G82 -> -2.25 | AI82: =AH82/SQRT(AH82^2+J82) -> -0.064023299 | AJ82: =+AI82/AH82 -> 0.0284548 | AK82: =1/AJ82^2 -> 1235.0625 | AL82: =1/AJ82 -> 35.143456 | AM82: 1 | AN82: 0 | AO82: 0 | AP82: =1/SQRT(J82) -> 0.028513297 | AQ82: 1 | AR82: 0 | AS82: 0 | AT82: 0 | AU82: 1 | AV82: 0 | AW82: =1/K82 -> 0.0625 | AX82: =1/(K82*K82) -> 0.00390625
...

Sheet bma_nobs
